2024-02-28 19:09:48 - anonbot - INFO - Initializing AnonBot
2024-02-28 19:23:37 - anonbot - INFO - Initializing AnonBot
2024-02-28 19:24:09 - anonbot - INFO - Initializing AnonBot
2024-02-28 19:24:25 - anonbot - INFO - Initializing AnonBot
2024-02-28 19:24:55 - anonbot - INFO - Initializing AnonBot
2024-02-28 19:28:37 - anonbot - INFO - Initializing AnonBot
2024-02-28 19:32:09 - anonbot - INFO - Initializing AnonBot
2024-02-28 19:36:39 - anonbot - INFO - Initializing AnonBot
2024-02-28 21:36:41 - anonbot - INFO - Initializing AnonBot
2024-02-28 21:36:51 - anonbot - INFO - Initializing AnonBot
2024-02-28 21:37:24 - anonbot - INFO - Initializing AnonBot
2024-02-28 21:40:09 - anonbot - INFO - Initializing AnonBot
2024-02-28 21:42:01 - anonbot - INFO - Initializing AnonBot
2024-02-28 21:42:18 - anonbot - INFO - Initializing AnonBot
2024-02-28 21:42:56 - anonbot - INFO - Initializing AnonBot
2024-02-28 21:43:38 - anonbot - INFO - Initializing AnonBot
2024-02-28 21:43:38 - anonbot.internal.driver.abstract - DEBUG - Driver(type='general+websocket+flask+httpx', adapters=1, bots=0) 成功注册 adapter Satori
2024-02-28 21:43:38 - anonbot.internal.driver.abstract - DEBUG - Adapters Loaded: Satori
2024-02-28 21:45:13 - anonbot - INFO - Initializing AnonBot
2024-02-28 21:45:13 - anonbot.internal.driver.abstract - DEBUG - Driver(type='general+websocket+flask+httpx', adapters=1, bots=0) 成功注册 adapter Satori
2024-02-28 21:45:13 - anonbot.internal.driver.abstract - DEBUG - Adapters Loaded: Satori
2024-02-28 21:45:13 - anonbot.driver.general - INFO - 应用启动成功
2024-02-28 21:51:40 - anonbot - INFO - Initializing AnonBot
2024-02-28 21:51:40 - anonbot.internal.driver.abstract - DEBUG - Driver(type='general+websocket+flask+httpx', adapters=1, bots=0) 成功注册 adapter Satori
2024-02-28 21:51:40 - anonbot.internal.driver.abstract - DEBUG - Adapters Loaded: Satori
2024-02-28 21:51:40 - anonbot.driver.general - INFO - 应用启动成功
2024-02-28 21:56:24 - anonbot - INFO - Initializing AnonBot
2024-02-28 21:56:24 - anonbot.internal.driver.abstract - DEBUG - Driver(type='general+websocket+flask+httpx', adapters=1, bots=0) 成功注册 adapter Satori
2024-02-28 21:56:24 - anonbot.internal.driver.abstract - DEBUG - Adapters Loaded: Satori
2024-02-28 21:56:24 - anonbot.driver.general - INFO - 应用启动成功
2024-02-28 21:56:48 - anonbot - INFO - Initializing AnonBot
2024-02-28 21:56:48 - anonbot.internal.driver.abstract - DEBUG - Driver(type='general+websocket+flask+httpx', adapters=1, bots=0) 成功注册 adapter Satori
2024-02-28 21:56:48 - anonbot.internal.driver.abstract - DEBUG - Adapters Loaded: Satori
2024-02-28 21:56:48 - anonbot.driver.general - INFO - 应用启动成功
2024-02-28 21:59:58 - anonbot - INFO - Initializing AnonBot
2024-02-28 21:59:58 - anonbot.internal.driver.abstract - DEBUG - Driver(type='general+websocket+flask+httpx', adapters=1, bots=0) 成功注册 adapter Satori
2024-02-28 21:59:58 - anonbot.internal.driver.abstract - DEBUG - Adapters Loaded: Satori
2024-02-28 21:59:58 - anonbot.driver.general - INFO - 应用启动成功
2024-02-28 22:00:34 - anonbot - INFO - Initializing AnonBot
2024-02-28 22:00:35 - anonbot.internal.driver.abstract - DEBUG - Driver(type='general+websocket+flask+httpx', adapters=1, bots=0) 成功注册 adapter Satori
2024-02-28 22:00:35 - anonbot.internal.driver.abstract - DEBUG - Adapters Loaded: Satori
2024-02-28 22:00:35 - anonbot.driver.general - INFO - 应用启动成功
2024-02-28 22:00:52 - anonbot - INFO - Initializing AnonBot
2024-02-28 22:00:53 - anonbot.internal.driver.abstract - DEBUG - Driver(type='general+websocket+flask+httpx', adapters=1, bots=0) 成功注册 adapter Satori
2024-02-28 22:00:53 - anonbot.internal.driver.abstract - DEBUG - Adapters Loaded: Satori
2024-02-28 22:00:53 - anonbot.driver.general - INFO - 应用启动成功
2024-02-28 22:01:24 - anonbot - INFO - Initializing AnonBot
2024-02-28 22:01:25 - anonbot.internal.driver.abstract - DEBUG - Driver(type='general+websocket+flask+httpx', adapters=1, bots=0) 成功注册 adapter Satori
2024-02-28 22:01:25 - anonbot.internal.driver.abstract - DEBUG - Adapters Loaded: Satori
2024-02-28 22:01:25 - anonbot.driver.general - INFO - 应用启动成功
2024-02-28 22:02:05 - anonbot - INFO - Initializing AnonBot
2024-02-28 22:02:06 - anonbot.internal.driver.abstract - DEBUG - Driver(type='general+websocket+flask+httpx', adapters=1, bots=0) 成功注册 adapter Satori
2024-02-28 22:02:06 - anonbot.internal.driver.abstract - DEBUG - Adapters Loaded: Satori
2024-02-28 22:02:06 - anonbot.driver.general - INFO - 应用启动成功
2024-02-28 22:05:52 - anonbot - INFO - Initializing AnonBot
2024-02-28 22:05:52 - anonbot.internal.driver.abstract - DEBUG - Driver(type='general+websocket+flask+httpx', adapters=1, bots=0) 成功注册 adapter Satori
2024-02-28 22:05:52 - anonbot.internal.driver.abstract - DEBUG - Adapters Loaded: Satori
2024-02-28 22:05:52 - anonbot.driver.general - INFO - 应用启动成功
2024-02-28 22:06:59 - anonbot - INFO - Initializing AnonBot
2024-02-28 22:07:00 - anonbot.internal.driver.abstract - DEBUG - Driver(type='general+websocket+flask+httpx', adapters=1, bots=0) 成功注册 adapter Satori
2024-02-28 22:07:00 - anonbot.internal.driver.abstract - DEBUG - Adapters Loaded: Satori
2024-02-28 22:07:00 - anonbot.driver.general - INFO - 应用启动成功
2024-02-28 22:07:37 - anonbot - INFO - Initializing AnonBot
2024-02-28 22:07:37 - anonbot.internal.driver.abstract - DEBUG - Driver(type='general+websocket+flask+httpx', adapters=1, bots=0) 成功注册 adapter Satori
2024-02-28 22:07:37 - anonbot.internal.driver.abstract - DEBUG - Adapters Loaded: Satori
2024-02-28 22:07:37 - anonbot.driver.general - INFO - 应用启动成功
2024-02-28 22:08:01 - anonbot - INFO - Initializing AnonBot
2024-02-28 22:08:01 - anonbot.internal.driver.abstract - DEBUG - Driver(type='general+websocket+flask+httpx', adapters=1, bots=0) 成功注册 adapter Satori
2024-02-28 22:08:02 - anonbot.internal.driver.abstract - DEBUG - Adapters Loaded: Satori
2024-02-28 22:08:02 - anonbot.driver.general - INFO - 应用启动成功
2024-02-28 22:08:25 - anonbot - INFO - Initializing AnonBot
2024-02-28 22:08:26 - anonbot.internal.driver.abstract - DEBUG - Driver(type='general+websocket+flask+httpx', adapters=1, bots=0) 成功注册 adapter Satori
2024-02-28 22:08:26 - anonbot.internal.driver.abstract - DEBUG - Adapters Loaded: Satori
2024-02-28 22:08:26 - anonbot.driver.general - INFO - 应用启动成功
2024-02-28 22:09:04 - anonbot - INFO - Initializing AnonBot
2024-02-28 22:09:04 - anonbot.internal.driver.abstract - DEBUG - Driver(type='general+websocket+flask+httpx', adapters=1, bots=0) 成功注册 adapter Satori
2024-02-28 22:09:04 - anonbot.internal.driver.abstract - DEBUG - Adapters Loaded: Satori
2024-02-28 22:09:04 - anonbot.driver.general - INFO - 应用启动成功
2024-02-28 22:10:42 - anonbot - INFO - Initializing AnonBot
2024-02-28 22:10:42 - anonbot.internal.driver.abstract - DEBUG - Driver(type='general+websocket+flask+httpx', adapters=1, bots=0) 成功注册 adapter Satori
2024-02-28 22:10:42 - anonbot.internal.driver.abstract - DEBUG - Adapters Loaded: Satori
2024-02-28 22:10:42 - anonbot.driver.general - INFO - 应用启动成功
2024-02-28 22:11:26 - anonbot - INFO - Initializing AnonBot
2024-02-28 22:11:27 - anonbot.internal.driver.abstract - DEBUG - Driver(type='general+websocket+flask+httpx', adapters=1, bots=0) 成功注册 adapter Satori
2024-02-28 22:11:27 - anonbot.internal.driver.abstract - DEBUG - Adapters Loaded: Satori
2024-02-28 22:11:27 - anonbot.driver.general - INFO - 应用启动成功
2024-02-28 22:11:50 - anonbot - INFO - Initializing AnonBot
2024-02-28 22:11:50 - anonbot.internal.driver.abstract - DEBUG - Driver(type='general+websocket+flask+httpx', adapters=1, bots=0) 成功注册 adapter Satori
2024-02-28 22:11:50 - anonbot.internal.driver.abstract - DEBUG - Adapters Loaded: Satori
2024-02-28 22:11:50 - anonbot.driver.general - INFO - 应用启动成功
2024-02-28 22:12:12 - anonbot - INFO - Initializing AnonBot
2024-02-28 22:12:13 - anonbot.internal.driver.abstract - DEBUG - Driver(type='general+websocket+flask+httpx', adapters=1, bots=0) 成功注册 adapter Satori
2024-02-28 22:12:13 - anonbot.internal.driver.abstract - DEBUG - Adapters Loaded: Satori
2024-02-28 22:12:13 - anonbot.driver.general - INFO - 应用启动成功
2024-02-28 22:12:38 - anonbot - INFO - Initializing AnonBot
2024-02-28 22:12:38 - anonbot.internal.driver.abstract - DEBUG - Driver(type='general+websocket+flask+httpx', adapters=1, bots=0) 成功注册 adapter Satori
2024-02-28 22:12:38 - anonbot.internal.driver.abstract - DEBUG - Adapters Loaded: Satori
2024-02-28 22:12:38 - anonbot.driver.general - INFO - 应用启动成功
2024-02-28 22:13:32 - anonbot - INFO - Initializing AnonBot
2024-02-28 22:13:32 - anonbot.internal.driver.abstract - DEBUG - Driver(type='general+websocket+flask+httpx', adapters=1, bots=0) 成功注册 adapter Satori
2024-02-28 22:13:32 - anonbot.internal.driver.abstract - DEBUG - Adapters Loaded: Satori
2024-02-28 22:13:32 - anonbot.driver.general - INFO - 应用启动成功
2024-02-28 22:14:14 - anonbot - INFO - Initializing AnonBot
2024-02-28 22:14:15 - anonbot.internal.driver.abstract - DEBUG - Driver(type='general+websocket+flask+httpx', adapters=1, bots=0) 成功注册 adapter Satori
2024-02-28 22:14:15 - anonbot.internal.driver.abstract - DEBUG - Adapters Loaded: Satori
2024-02-28 22:14:15 - anonbot.driver.general - INFO - 应用启动成功
2024-02-28 22:15:27 - anonbot - INFO - Initializing AnonBot
2024-02-28 22:15:27 - anonbot.internal.driver.abstract - DEBUG - Driver(type='general+websocket+flask+httpx', adapters=1, bots=0) 成功注册 adapter Satori
2024-02-28 22:15:27 - anonbot.internal.driver.abstract - DEBUG - Adapters Loaded: Satori
2024-02-28 22:15:27 - anonbot.driver.general - INFO - 应用启动成功
2024-02-28 22:19:11 - anonbot - INFO - Initializing AnonBot
2024-02-28 22:19:11 - anonbot.internal.driver.abstract - DEBUG - Driver(type='general+websocket+flask+httpx', adapters=1, bots=0) 成功注册 adapter Satori
2024-02-28 22:19:11 - anonbot.internal.driver.abstract - DEBUG - Adapters Loaded: Satori
2024-02-28 22:19:11 - anonbot.driver.general - INFO - 应用启动成功
2024-02-28 22:20:38 - anonbot - INFO - Initializing AnonBot
2024-02-28 22:20:39 - anonbot.internal.driver.abstract - DEBUG - Driver(type='general+websocket+flask+httpx', adapters=1, bots=0) 成功注册 adapter Satori
2024-02-28 22:20:39 - anonbot.internal.driver.abstract - DEBUG - Adapters Loaded: Satori
2024-02-28 22:20:39 - anonbot.driver.general - INFO - 应用启动成功
2024-02-28 22:22:01 - anonbot - INFO - Initializing AnonBot
2024-02-28 22:22:01 - anonbot.driver.general - INFO - 应用启动成功
2024-02-28 22:23:36 - anonbot - INFO - Initializing AnonBot
2024-02-28 22:23:36 - anonbot.internal.driver.abstract - DEBUG - Driver(type='general+websocket+flask+httpx', adapters=1, bots=0) 成功注册 adapter Satori
2024-02-28 22:23:36 - anonbot.internal.driver.abstract - DEBUG - Adapters Loaded: Satori
2024-02-28 22:23:36 - anonbot.driver.general - INFO - 应用启动成功
2024-02-28 22:24:39 - anonbot - INFO - Initializing AnonBot
2024-02-28 22:24:39 - anonbot.internal.driver.abstract - DEBUG - Driver(type='general+websocket+flask+httpx', adapters=1, bots=0) 成功注册 adapter Satori
2024-02-28 22:24:39 - anonbot.internal.driver.abstract - DEBUG - Adapters Loaded: Satori
2024-02-28 22:24:39 - anonbot.driver.general - INFO - 应用启动成功
2024-02-28 22:25:24 - anonbot - INFO - Initializing AnonBot
2024-02-28 22:25:24 - anonbot.internal.driver.abstract - DEBUG - Driver(type='general+websocket+flask+httpx', adapters=1, bots=0) 成功注册 adapter Satori
2024-02-28 22:25:24 - anonbot.internal.driver.abstract - DEBUG - Adapters Loaded: Satori
2024-02-28 22:25:24 - anonbot.driver.general - INFO - 应用启动成功
2024-02-28 22:28:58 - anonbot - INFO - Initializing AnonBot
2024-02-28 22:28:58 - anonbot.internal.driver.abstract - DEBUG - Driver(type='general+websocket+flask+httpx', adapters=1, bots=0) 成功注册 adapter Satori
2024-02-28 22:28:58 - anonbot.internal.driver.abstract - DEBUG - Adapters Loaded: Satori
2024-02-28 22:28:58 - anonbot.driver.general - INFO - 应用启动成功
2024-02-28 22:32:12 - anonbot - INFO - Initializing AnonBot
2024-02-28 22:33:30 - anonbot - INFO - Initializing AnonBot
2024-02-28 22:33:31 - anonbot.internal.driver.abstract - DEBUG - Driver(type='general+websocket+flask+httpx', adapters=1, bots=0) 成功注册 adapter Satori
2024-02-28 22:33:31 - anonbot.internal.driver.abstract - DEBUG - Adapters Loaded: Satori
2024-02-28 22:33:31 - anonbot.driver.general - INFO - 应用启动成功
2024-02-28 22:33:33 - anonbot.adapter.satori.adapter - ERROR - Error while connecting to WebSocket ws://127.0.0.1:8192/v1/events
Traceback (most recent call last):
  File "f:\VS Code File\anonbot\anonbot\adapter\satori\adapter.py", line 140, in ws
    with self.websocket(request) as ws:
  File "C:\Users\qwert\AppData\Local\Programs\Python\Python311\Lib\contextlib.py", line 137, in __enter__
    return next(self.gen)
           ^^^^^^^^^^^^^^
  File "f:\VS Code File\anonbot\anonbot\internal\adapter\adapter.py", line 82, in websocket
    with self.driver.websocket(setup) as websocket:
  File "C:\Users\qwert\AppData\Local\Programs\Python\Python311\Lib\contextlib.py", line 137, in __enter__
    return next(self.gen)
           ^^^^^^^^^^^^^^
  File "f:\VS Code File\anonbot\anonbot\driver\websocket.py", line 47, in websocket
    ws = create_connection(
         ^^^^^^^^^^^^^^^^^^
  File "C:\Users\qwert\AppData\Local\Programs\Python\Python311\Lib\site-packages\websocket\_core.py", line 610, in create_connection
    websock.connect(url, **options)
  File "C:\Users\qwert\AppData\Local\Programs\Python\Python311\Lib\site-packages\websocket\_core.py", line 251, in connect
    self.sock, addrs = connect(url, self.sock_opt, proxy_info(**options),
                       ^^^^^^^^^^^^^^^^^^^^^^^^^^^^^^^^^^^^^^^^^^^^^^^^^^
  File "C:\Users\qwert\AppData\Local\Programs\Python\Python311\Lib\site-packages\websocket\_http.py", line 129, in connect
    sock = _open_socket(addrinfo_list, options.sockopt, options.timeout)
           ^^^^^^^^^^^^^^^^^^^^^^^^^^^^^^^^^^^^^^^^^^^^^^^^^^^^^^^^^^^^^
  File "C:\Users\qwert\AppData\Local\Programs\Python\Python311\Lib\site-packages\websocket\_http.py", line 204, in _open_socket
    raise err
  File "C:\Users\qwert\AppData\Local\Programs\Python\Python311\Lib\site-packages\websocket\_http.py", line 184, in _open_socket
    sock.connect(address)
ConnectionRefusedError: [WinError 10061] 由于目标计算机积极拒绝，无法连接。

2024-02-28 22:33:38 - anonbot.adapter.satori.adapter - ERROR - Error while connecting to WebSocket ws://127.0.0.1:8192/v1/events
Traceback (most recent call last):
  File "f:\VS Code File\anonbot\anonbot\adapter\satori\adapter.py", line 140, in ws
    with self.websocket(request) as ws:
  File "C:\Users\qwert\AppData\Local\Programs\Python\Python311\Lib\contextlib.py", line 137, in __enter__
    return next(self.gen)
           ^^^^^^^^^^^^^^
  File "f:\VS Code File\anonbot\anonbot\internal\adapter\adapter.py", line 82, in websocket
    with self.driver.websocket(setup) as websocket:
  File "C:\Users\qwert\AppData\Local\Programs\Python\Python311\Lib\contextlib.py", line 137, in __enter__
    return next(self.gen)
           ^^^^^^^^^^^^^^
  File "f:\VS Code File\anonbot\anonbot\driver\websocket.py", line 47, in websocket
    ws = create_connection(
         ^^^^^^^^^^^^^^^^^^
  File "C:\Users\qwert\AppData\Local\Programs\Python\Python311\Lib\site-packages\websocket\_core.py", line 610, in create_connection
    websock.connect(url, **options)
  File "C:\Users\qwert\AppData\Local\Programs\Python\Python311\Lib\site-packages\websocket\_core.py", line 251, in connect
    self.sock, addrs = connect(url, self.sock_opt, proxy_info(**options),
                       ^^^^^^^^^^^^^^^^^^^^^^^^^^^^^^^^^^^^^^^^^^^^^^^^^^
  File "C:\Users\qwert\AppData\Local\Programs\Python\Python311\Lib\site-packages\websocket\_http.py", line 129, in connect
    sock = _open_socket(addrinfo_list, options.sockopt, options.timeout)
           ^^^^^^^^^^^^^^^^^^^^^^^^^^^^^^^^^^^^^^^^^^^^^^^^^^^^^^^^^^^^^
  File "C:\Users\qwert\AppData\Local\Programs\Python\Python311\Lib\site-packages\websocket\_http.py", line 204, in _open_socket
    raise err
  File "C:\Users\qwert\AppData\Local\Programs\Python\Python311\Lib\site-packages\websocket\_http.py", line 184, in _open_socket
    sock.connect(address)
ConnectionRefusedError: [WinError 10061] 由于目标计算机积极拒绝，无法连接。

2024-02-28 22:33:43 - anonbot.adapter.satori.adapter - ERROR - Error while connecting to WebSocket ws://127.0.0.1:8192/v1/events
Traceback (most recent call last):
  File "f:\VS Code File\anonbot\anonbot\adapter\satori\adapter.py", line 140, in ws
    with self.websocket(request) as ws:
  File "C:\Users\qwert\AppData\Local\Programs\Python\Python311\Lib\contextlib.py", line 137, in __enter__
    return next(self.gen)
           ^^^^^^^^^^^^^^
  File "f:\VS Code File\anonbot\anonbot\internal\adapter\adapter.py", line 82, in websocket
    with self.driver.websocket(setup) as websocket:
  File "C:\Users\qwert\AppData\Local\Programs\Python\Python311\Lib\contextlib.py", line 137, in __enter__
    return next(self.gen)
           ^^^^^^^^^^^^^^
  File "f:\VS Code File\anonbot\anonbot\driver\websocket.py", line 47, in websocket
    ws = create_connection(
         ^^^^^^^^^^^^^^^^^^
  File "C:\Users\qwert\AppData\Local\Programs\Python\Python311\Lib\site-packages\websocket\_core.py", line 610, in create_connection
    websock.connect(url, **options)
  File "C:\Users\qwert\AppData\Local\Programs\Python\Python311\Lib\site-packages\websocket\_core.py", line 251, in connect
    self.sock, addrs = connect(url, self.sock_opt, proxy_info(**options),
                       ^^^^^^^^^^^^^^^^^^^^^^^^^^^^^^^^^^^^^^^^^^^^^^^^^^
  File "C:\Users\qwert\AppData\Local\Programs\Python\Python311\Lib\site-packages\websocket\_http.py", line 129, in connect
    sock = _open_socket(addrinfo_list, options.sockopt, options.timeout)
           ^^^^^^^^^^^^^^^^^^^^^^^^^^^^^^^^^^^^^^^^^^^^^^^^^^^^^^^^^^^^^
  File "C:\Users\qwert\AppData\Local\Programs\Python\Python311\Lib\site-packages\websocket\_http.py", line 204, in _open_socket
    raise err
  File "C:\Users\qwert\AppData\Local\Programs\Python\Python311\Lib\site-packages\websocket\_http.py", line 184, in _open_socket
    sock.connect(address)
ConnectionRefusedError: [WinError 10061] 由于目标计算机积极拒绝，无法连接。

2024-02-28 22:33:48 - anonbot.adapter.satori.adapter - ERROR - Error while connecting to WebSocket ws://127.0.0.1:8192/v1/events
Traceback (most recent call last):
  File "f:\VS Code File\anonbot\anonbot\adapter\satori\adapter.py", line 140, in ws
    with self.websocket(request) as ws:
  File "C:\Users\qwert\AppData\Local\Programs\Python\Python311\Lib\contextlib.py", line 137, in __enter__
    return next(self.gen)
           ^^^^^^^^^^^^^^
  File "f:\VS Code File\anonbot\anonbot\internal\adapter\adapter.py", line 82, in websocket
    with self.driver.websocket(setup) as websocket:
  File "C:\Users\qwert\AppData\Local\Programs\Python\Python311\Lib\contextlib.py", line 137, in __enter__
    return next(self.gen)
           ^^^^^^^^^^^^^^
  File "f:\VS Code File\anonbot\anonbot\driver\websocket.py", line 47, in websocket
    ws = create_connection(
         ^^^^^^^^^^^^^^^^^^
  File "C:\Users\qwert\AppData\Local\Programs\Python\Python311\Lib\site-packages\websocket\_core.py", line 610, in create_connection
    websock.connect(url, **options)
  File "C:\Users\qwert\AppData\Local\Programs\Python\Python311\Lib\site-packages\websocket\_core.py", line 251, in connect
    self.sock, addrs = connect(url, self.sock_opt, proxy_info(**options),
                       ^^^^^^^^^^^^^^^^^^^^^^^^^^^^^^^^^^^^^^^^^^^^^^^^^^
  File "C:\Users\qwert\AppData\Local\Programs\Python\Python311\Lib\site-packages\websocket\_http.py", line 129, in connect
    sock = _open_socket(addrinfo_list, options.sockopt, options.timeout)
           ^^^^^^^^^^^^^^^^^^^^^^^^^^^^^^^^^^^^^^^^^^^^^^^^^^^^^^^^^^^^^
  File "C:\Users\qwert\AppData\Local\Programs\Python\Python311\Lib\site-packages\websocket\_http.py", line 204, in _open_socket
    raise err
  File "C:\Users\qwert\AppData\Local\Programs\Python\Python311\Lib\site-packages\websocket\_http.py", line 184, in _open_socket
    sock.connect(address)
ConnectionRefusedError: [WinError 10061] 由于目标计算机积极拒绝，无法连接。

2024-02-28 22:33:53 - anonbot.adapter.satori.adapter - ERROR - Error while connecting to WebSocket ws://127.0.0.1:8192/v1/events
Traceback (most recent call last):
  File "f:\VS Code File\anonbot\anonbot\adapter\satori\adapter.py", line 140, in ws
    with self.websocket(request) as ws:
  File "C:\Users\qwert\AppData\Local\Programs\Python\Python311\Lib\contextlib.py", line 137, in __enter__
    return next(self.gen)
           ^^^^^^^^^^^^^^
  File "f:\VS Code File\anonbot\anonbot\internal\adapter\adapter.py", line 82, in websocket
    with self.driver.websocket(setup) as websocket:
  File "C:\Users\qwert\AppData\Local\Programs\Python\Python311\Lib\contextlib.py", line 137, in __enter__
    return next(self.gen)
           ^^^^^^^^^^^^^^
  File "f:\VS Code File\anonbot\anonbot\driver\websocket.py", line 47, in websocket
    ws = create_connection(
         ^^^^^^^^^^^^^^^^^^
  File "C:\Users\qwert\AppData\Local\Programs\Python\Python311\Lib\site-packages\websocket\_core.py", line 610, in create_connection
    websock.connect(url, **options)
  File "C:\Users\qwert\AppData\Local\Programs\Python\Python311\Lib\site-packages\websocket\_core.py", line 251, in connect
    self.sock, addrs = connect(url, self.sock_opt, proxy_info(**options),
                       ^^^^^^^^^^^^^^^^^^^^^^^^^^^^^^^^^^^^^^^^^^^^^^^^^^
  File "C:\Users\qwert\AppData\Local\Programs\Python\Python311\Lib\site-packages\websocket\_http.py", line 129, in connect
    sock = _open_socket(addrinfo_list, options.sockopt, options.timeout)
           ^^^^^^^^^^^^^^^^^^^^^^^^^^^^^^^^^^^^^^^^^^^^^^^^^^^^^^^^^^^^^
  File "C:\Users\qwert\AppData\Local\Programs\Python\Python311\Lib\site-packages\websocket\_http.py", line 204, in _open_socket
    raise err
  File "C:\Users\qwert\AppData\Local\Programs\Python\Python311\Lib\site-packages\websocket\_http.py", line 184, in _open_socket
    sock.connect(address)
ConnectionRefusedError: [WinError 10061] 由于目标计算机积极拒绝，无法连接。

2024-02-28 22:33:58 - anonbot.adapter.satori.adapter - ERROR - Error while connecting to WebSocket ws://127.0.0.1:8192/v1/events
Traceback (most recent call last):
  File "f:\VS Code File\anonbot\anonbot\adapter\satori\adapter.py", line 140, in ws
    with self.websocket(request) as ws:
  File "C:\Users\qwert\AppData\Local\Programs\Python\Python311\Lib\contextlib.py", line 137, in __enter__
    return next(self.gen)
           ^^^^^^^^^^^^^^
  File "f:\VS Code File\anonbot\anonbot\internal\adapter\adapter.py", line 82, in websocket
    with self.driver.websocket(setup) as websocket:
  File "C:\Users\qwert\AppData\Local\Programs\Python\Python311\Lib\contextlib.py", line 137, in __enter__
    return next(self.gen)
           ^^^^^^^^^^^^^^
  File "f:\VS Code File\anonbot\anonbot\driver\websocket.py", line 47, in websocket
    ws = create_connection(
         ^^^^^^^^^^^^^^^^^^
  File "C:\Users\qwert\AppData\Local\Programs\Python\Python311\Lib\site-packages\websocket\_core.py", line 610, in create_connection
    websock.connect(url, **options)
  File "C:\Users\qwert\AppData\Local\Programs\Python\Python311\Lib\site-packages\websocket\_core.py", line 251, in connect
    self.sock, addrs = connect(url, self.sock_opt, proxy_info(**options),
                       ^^^^^^^^^^^^^^^^^^^^^^^^^^^^^^^^^^^^^^^^^^^^^^^^^^
  File "C:\Users\qwert\AppData\Local\Programs\Python\Python311\Lib\site-packages\websocket\_http.py", line 129, in connect
    sock = _open_socket(addrinfo_list, options.sockopt, options.timeout)
           ^^^^^^^^^^^^^^^^^^^^^^^^^^^^^^^^^^^^^^^^^^^^^^^^^^^^^^^^^^^^^
  File "C:\Users\qwert\AppData\Local\Programs\Python\Python311\Lib\site-packages\websocket\_http.py", line 204, in _open_socket
    raise err
  File "C:\Users\qwert\AppData\Local\Programs\Python\Python311\Lib\site-packages\websocket\_http.py", line 184, in _open_socket
    sock.connect(address)
ConnectionRefusedError: [WinError 10061] 由于目标计算机积极拒绝，无法连接。

2024-02-28 22:34:03 - anonbot.adapter.satori.adapter - ERROR - Error while connecting to WebSocket ws://127.0.0.1:8192/v1/events
Traceback (most recent call last):
  File "f:\VS Code File\anonbot\anonbot\adapter\satori\adapter.py", line 140, in ws
    with self.websocket(request) as ws:
  File "C:\Users\qwert\AppData\Local\Programs\Python\Python311\Lib\contextlib.py", line 137, in __enter__
    return next(self.gen)
           ^^^^^^^^^^^^^^
  File "f:\VS Code File\anonbot\anonbot\internal\adapter\adapter.py", line 82, in websocket
    with self.driver.websocket(setup) as websocket:
  File "C:\Users\qwert\AppData\Local\Programs\Python\Python311\Lib\contextlib.py", line 137, in __enter__
    return next(self.gen)
           ^^^^^^^^^^^^^^
  File "f:\VS Code File\anonbot\anonbot\driver\websocket.py", line 47, in websocket
    ws = create_connection(
         ^^^^^^^^^^^^^^^^^^
  File "C:\Users\qwert\AppData\Local\Programs\Python\Python311\Lib\site-packages\websocket\_core.py", line 610, in create_connection
    websock.connect(url, **options)
  File "C:\Users\qwert\AppData\Local\Programs\Python\Python311\Lib\site-packages\websocket\_core.py", line 251, in connect
    self.sock, addrs = connect(url, self.sock_opt, proxy_info(**options),
                       ^^^^^^^^^^^^^^^^^^^^^^^^^^^^^^^^^^^^^^^^^^^^^^^^^^
  File "C:\Users\qwert\AppData\Local\Programs\Python\Python311\Lib\site-packages\websocket\_http.py", line 129, in connect
    sock = _open_socket(addrinfo_list, options.sockopt, options.timeout)
           ^^^^^^^^^^^^^^^^^^^^^^^^^^^^^^^^^^^^^^^^^^^^^^^^^^^^^^^^^^^^^
  File "C:\Users\qwert\AppData\Local\Programs\Python\Python311\Lib\site-packages\websocket\_http.py", line 204, in _open_socket
    raise err
  File "C:\Users\qwert\AppData\Local\Programs\Python\Python311\Lib\site-packages\websocket\_http.py", line 184, in _open_socket
    sock.connect(address)
ConnectionRefusedError: [WinError 10061] 由于目标计算机积极拒绝，无法连接。

2024-02-28 22:34:08 - anonbot.adapter.satori.adapter - ERROR - Error while connecting to WebSocket ws://127.0.0.1:8192/v1/events
Traceback (most recent call last):
  File "f:\VS Code File\anonbot\anonbot\adapter\satori\adapter.py", line 140, in ws
    with self.websocket(request) as ws:
  File "C:\Users\qwert\AppData\Local\Programs\Python\Python311\Lib\contextlib.py", line 137, in __enter__
    return next(self.gen)
           ^^^^^^^^^^^^^^
  File "f:\VS Code File\anonbot\anonbot\internal\adapter\adapter.py", line 82, in websocket
    with self.driver.websocket(setup) as websocket:
  File "C:\Users\qwert\AppData\Local\Programs\Python\Python311\Lib\contextlib.py", line 137, in __enter__
    return next(self.gen)
           ^^^^^^^^^^^^^^
  File "f:\VS Code File\anonbot\anonbot\driver\websocket.py", line 47, in websocket
    ws = create_connection(
         ^^^^^^^^^^^^^^^^^^
  File "C:\Users\qwert\AppData\Local\Programs\Python\Python311\Lib\site-packages\websocket\_core.py", line 610, in create_connection
    websock.connect(url, **options)
  File "C:\Users\qwert\AppData\Local\Programs\Python\Python311\Lib\site-packages\websocket\_core.py", line 251, in connect
    self.sock, addrs = connect(url, self.sock_opt, proxy_info(**options),
                       ^^^^^^^^^^^^^^^^^^^^^^^^^^^^^^^^^^^^^^^^^^^^^^^^^^
  File "C:\Users\qwert\AppData\Local\Programs\Python\Python311\Lib\site-packages\websocket\_http.py", line 129, in connect
    sock = _open_socket(addrinfo_list, options.sockopt, options.timeout)
           ^^^^^^^^^^^^^^^^^^^^^^^^^^^^^^^^^^^^^^^^^^^^^^^^^^^^^^^^^^^^^
  File "C:\Users\qwert\AppData\Local\Programs\Python\Python311\Lib\site-packages\websocket\_http.py", line 204, in _open_socket
    raise err
  File "C:\Users\qwert\AppData\Local\Programs\Python\Python311\Lib\site-packages\websocket\_http.py", line 184, in _open_socket
    sock.connect(address)
ConnectionRefusedError: [WinError 10061] 由于目标计算机积极拒绝，无法连接。

2024-02-28 22:34:13 - anonbot.adapter.satori.adapter - ERROR - Error while connecting to WebSocket ws://127.0.0.1:8192/v1/events
Traceback (most recent call last):
  File "f:\VS Code File\anonbot\anonbot\adapter\satori\adapter.py", line 140, in ws
    with self.websocket(request) as ws:
  File "C:\Users\qwert\AppData\Local\Programs\Python\Python311\Lib\contextlib.py", line 137, in __enter__
    return next(self.gen)
           ^^^^^^^^^^^^^^
  File "f:\VS Code File\anonbot\anonbot\internal\adapter\adapter.py", line 82, in websocket
    with self.driver.websocket(setup) as websocket:
  File "C:\Users\qwert\AppData\Local\Programs\Python\Python311\Lib\contextlib.py", line 137, in __enter__
    return next(self.gen)
           ^^^^^^^^^^^^^^
  File "f:\VS Code File\anonbot\anonbot\driver\websocket.py", line 47, in websocket
    ws = create_connection(
         ^^^^^^^^^^^^^^^^^^
  File "C:\Users\qwert\AppData\Local\Programs\Python\Python311\Lib\site-packages\websocket\_core.py", line 610, in create_connection
    websock.connect(url, **options)
  File "C:\Users\qwert\AppData\Local\Programs\Python\Python311\Lib\site-packages\websocket\_core.py", line 251, in connect
    self.sock, addrs = connect(url, self.sock_opt, proxy_info(**options),
                       ^^^^^^^^^^^^^^^^^^^^^^^^^^^^^^^^^^^^^^^^^^^^^^^^^^
  File "C:\Users\qwert\AppData\Local\Programs\Python\Python311\Lib\site-packages\websocket\_http.py", line 129, in connect
    sock = _open_socket(addrinfo_list, options.sockopt, options.timeout)
           ^^^^^^^^^^^^^^^^^^^^^^^^^^^^^^^^^^^^^^^^^^^^^^^^^^^^^^^^^^^^^
  File "C:\Users\qwert\AppData\Local\Programs\Python\Python311\Lib\site-packages\websocket\_http.py", line 204, in _open_socket
    raise err
  File "C:\Users\qwert\AppData\Local\Programs\Python\Python311\Lib\site-packages\websocket\_http.py", line 184, in _open_socket
    sock.connect(address)
ConnectionRefusedError: [WinError 10061] 由于目标计算机积极拒绝，无法连接。

2024-02-28 22:34:18 - anonbot.adapter.satori.adapter - ERROR - Error while connecting to WebSocket ws://127.0.0.1:8192/v1/events
Traceback (most recent call last):
  File "f:\VS Code File\anonbot\anonbot\adapter\satori\adapter.py", line 140, in ws
    with self.websocket(request) as ws:
  File "C:\Users\qwert\AppData\Local\Programs\Python\Python311\Lib\contextlib.py", line 137, in __enter__
    return next(self.gen)
           ^^^^^^^^^^^^^^
  File "f:\VS Code File\anonbot\anonbot\internal\adapter\adapter.py", line 82, in websocket
    with self.driver.websocket(setup) as websocket:
  File "C:\Users\qwert\AppData\Local\Programs\Python\Python311\Lib\contextlib.py", line 137, in __enter__
    return next(self.gen)
           ^^^^^^^^^^^^^^
  File "f:\VS Code File\anonbot\anonbot\driver\websocket.py", line 47, in websocket
    ws = create_connection(
         ^^^^^^^^^^^^^^^^^^
  File "C:\Users\qwert\AppData\Local\Programs\Python\Python311\Lib\site-packages\websocket\_core.py", line 610, in create_connection
    websock.connect(url, **options)
  File "C:\Users\qwert\AppData\Local\Programs\Python\Python311\Lib\site-packages\websocket\_core.py", line 251, in connect
    self.sock, addrs = connect(url, self.sock_opt, proxy_info(**options),
                       ^^^^^^^^^^^^^^^^^^^^^^^^^^^^^^^^^^^^^^^^^^^^^^^^^^
  File "C:\Users\qwert\AppData\Local\Programs\Python\Python311\Lib\site-packages\websocket\_http.py", line 129, in connect
    sock = _open_socket(addrinfo_list, options.sockopt, options.timeout)
           ^^^^^^^^^^^^^^^^^^^^^^^^^^^^^^^^^^^^^^^^^^^^^^^^^^^^^^^^^^^^^
  File "C:\Users\qwert\AppData\Local\Programs\Python\Python311\Lib\site-packages\websocket\_http.py", line 204, in _open_socket
    raise err
  File "C:\Users\qwert\AppData\Local\Programs\Python\Python311\Lib\site-packages\websocket\_http.py", line 184, in _open_socket
    sock.connect(address)
ConnectionRefusedError: [WinError 10061] 由于目标计算机积极拒绝，无法连接。

2024-02-28 22:34:24 - anonbot.adapter.satori.adapter - ERROR - Error while connecting to WebSocket ws://127.0.0.1:8192/v1/events
Traceback (most recent call last):
  File "f:\VS Code File\anonbot\anonbot\adapter\satori\adapter.py", line 140, in ws
    with self.websocket(request) as ws:
  File "C:\Users\qwert\AppData\Local\Programs\Python\Python311\Lib\contextlib.py", line 137, in __enter__
    return next(self.gen)
           ^^^^^^^^^^^^^^
  File "f:\VS Code File\anonbot\anonbot\internal\adapter\adapter.py", line 82, in websocket
    with self.driver.websocket(setup) as websocket:
  File "C:\Users\qwert\AppData\Local\Programs\Python\Python311\Lib\contextlib.py", line 137, in __enter__
    return next(self.gen)
           ^^^^^^^^^^^^^^
  File "f:\VS Code File\anonbot\anonbot\driver\websocket.py", line 47, in websocket
    ws = create_connection(
         ^^^^^^^^^^^^^^^^^^
  File "C:\Users\qwert\AppData\Local\Programs\Python\Python311\Lib\site-packages\websocket\_core.py", line 610, in create_connection
    websock.connect(url, **options)
  File "C:\Users\qwert\AppData\Local\Programs\Python\Python311\Lib\site-packages\websocket\_core.py", line 251, in connect
    self.sock, addrs = connect(url, self.sock_opt, proxy_info(**options),
                       ^^^^^^^^^^^^^^^^^^^^^^^^^^^^^^^^^^^^^^^^^^^^^^^^^^
  File "C:\Users\qwert\AppData\Local\Programs\Python\Python311\Lib\site-packages\websocket\_http.py", line 129, in connect
    sock = _open_socket(addrinfo_list, options.sockopt, options.timeout)
           ^^^^^^^^^^^^^^^^^^^^^^^^^^^^^^^^^^^^^^^^^^^^^^^^^^^^^^^^^^^^^
  File "C:\Users\qwert\AppData\Local\Programs\Python\Python311\Lib\site-packages\websocket\_http.py", line 204, in _open_socket
    raise err
  File "C:\Users\qwert\AppData\Local\Programs\Python\Python311\Lib\site-packages\websocket\_http.py", line 184, in _open_socket
    sock.connect(address)
ConnectionRefusedError: [WinError 10061] 由于目标计算机积极拒绝，无法连接。

2024-02-28 22:34:29 - anonbot.adapter.satori.adapter - ERROR - Error while connecting to WebSocket ws://127.0.0.1:8192/v1/events
Traceback (most recent call last):
  File "f:\VS Code File\anonbot\anonbot\adapter\satori\adapter.py", line 140, in ws
    with self.websocket(request) as ws:
  File "C:\Users\qwert\AppData\Local\Programs\Python\Python311\Lib\contextlib.py", line 137, in __enter__
    return next(self.gen)
           ^^^^^^^^^^^^^^
  File "f:\VS Code File\anonbot\anonbot\internal\adapter\adapter.py", line 82, in websocket
    with self.driver.websocket(setup) as websocket:
  File "C:\Users\qwert\AppData\Local\Programs\Python\Python311\Lib\contextlib.py", line 137, in __enter__
    return next(self.gen)
           ^^^^^^^^^^^^^^
  File "f:\VS Code File\anonbot\anonbot\driver\websocket.py", line 47, in websocket
    ws = create_connection(
         ^^^^^^^^^^^^^^^^^^
  File "C:\Users\qwert\AppData\Local\Programs\Python\Python311\Lib\site-packages\websocket\_core.py", line 610, in create_connection
    websock.connect(url, **options)
  File "C:\Users\qwert\AppData\Local\Programs\Python\Python311\Lib\site-packages\websocket\_core.py", line 251, in connect
    self.sock, addrs = connect(url, self.sock_opt, proxy_info(**options),
                       ^^^^^^^^^^^^^^^^^^^^^^^^^^^^^^^^^^^^^^^^^^^^^^^^^^
  File "C:\Users\qwert\AppData\Local\Programs\Python\Python311\Lib\site-packages\websocket\_http.py", line 129, in connect
    sock = _open_socket(addrinfo_list, options.sockopt, options.timeout)
           ^^^^^^^^^^^^^^^^^^^^^^^^^^^^^^^^^^^^^^^^^^^^^^^^^^^^^^^^^^^^^
  File "C:\Users\qwert\AppData\Local\Programs\Python\Python311\Lib\site-packages\websocket\_http.py", line 204, in _open_socket
    raise err
  File "C:\Users\qwert\AppData\Local\Programs\Python\Python311\Lib\site-packages\websocket\_http.py", line 184, in _open_socket
    sock.connect(address)
ConnectionRefusedError: [WinError 10061] 由于目标计算机积极拒绝，无法连接。

2024-02-28 22:34:34 - anonbot.adapter.satori.adapter - ERROR - Error while connecting to WebSocket ws://127.0.0.1:8192/v1/events
Traceback (most recent call last):
  File "f:\VS Code File\anonbot\anonbot\adapter\satori\adapter.py", line 140, in ws
    with self.websocket(request) as ws:
  File "C:\Users\qwert\AppData\Local\Programs\Python\Python311\Lib\contextlib.py", line 137, in __enter__
    return next(self.gen)
           ^^^^^^^^^^^^^^
  File "f:\VS Code File\anonbot\anonbot\internal\adapter\adapter.py", line 82, in websocket
    with self.driver.websocket(setup) as websocket:
  File "C:\Users\qwert\AppData\Local\Programs\Python\Python311\Lib\contextlib.py", line 137, in __enter__
    return next(self.gen)
           ^^^^^^^^^^^^^^
  File "f:\VS Code File\anonbot\anonbot\driver\websocket.py", line 47, in websocket
    ws = create_connection(
         ^^^^^^^^^^^^^^^^^^
  File "C:\Users\qwert\AppData\Local\Programs\Python\Python311\Lib\site-packages\websocket\_core.py", line 610, in create_connection
    websock.connect(url, **options)
  File "C:\Users\qwert\AppData\Local\Programs\Python\Python311\Lib\site-packages\websocket\_core.py", line 251, in connect
    self.sock, addrs = connect(url, self.sock_opt, proxy_info(**options),
                       ^^^^^^^^^^^^^^^^^^^^^^^^^^^^^^^^^^^^^^^^^^^^^^^^^^
  File "C:\Users\qwert\AppData\Local\Programs\Python\Python311\Lib\site-packages\websocket\_http.py", line 129, in connect
    sock = _open_socket(addrinfo_list, options.sockopt, options.timeout)
           ^^^^^^^^^^^^^^^^^^^^^^^^^^^^^^^^^^^^^^^^^^^^^^^^^^^^^^^^^^^^^
  File "C:\Users\qwert\AppData\Local\Programs\Python\Python311\Lib\site-packages\websocket\_http.py", line 204, in _open_socket
    raise err
  File "C:\Users\qwert\AppData\Local\Programs\Python\Python311\Lib\site-packages\websocket\_http.py", line 184, in _open_socket
    sock.connect(address)
ConnectionRefusedError: [WinError 10061] 由于目标计算机积极拒绝，无法连接。

2024-02-28 22:35:12 - anonbot - INFO - Initializing AnonBot
2024-02-28 22:35:12 - anonbot.internal.driver.abstract - DEBUG - Driver(type='general+websocket+flask+httpx', adapters=1, bots=0) 成功注册 adapter Satori
2024-02-28 22:35:12 - anonbot.internal.driver.abstract - DEBUG - Adapters Loaded: Satori
2024-02-28 22:35:12 - anonbot.driver.general - INFO - 应用启动成功
2024-02-28 22:35:14 - anonbot.adapter.satori.adapter - ERROR - Error while connecting to WebSocket ws://127.0.0.1:8192/v1/events
Traceback (most recent call last):
  File "f:\VS Code File\anonbot\anonbot\adapter\satori\adapter.py", line 140, in ws
    with self.websocket(request) as ws:
  File "C:\Users\qwert\AppData\Local\Programs\Python\Python311\Lib\contextlib.py", line 137, in __enter__
    return next(self.gen)
           ^^^^^^^^^^^^^^
  File "f:\VS Code File\anonbot\anonbot\internal\adapter\adapter.py", line 82, in websocket
    with self.driver.websocket(setup) as websocket:
  File "C:\Users\qwert\AppData\Local\Programs\Python\Python311\Lib\contextlib.py", line 137, in __enter__
    return next(self.gen)
           ^^^^^^^^^^^^^^
  File "f:\VS Code File\anonbot\anonbot\driver\websocket.py", line 47, in websocket
    ws = create_connection(
         ^^^^^^^^^^^^^^^^^^
  File "C:\Users\qwert\AppData\Local\Programs\Python\Python311\Lib\site-packages\websocket\_core.py", line 610, in create_connection
    websock.connect(url, **options)
  File "C:\Users\qwert\AppData\Local\Programs\Python\Python311\Lib\site-packages\websocket\_core.py", line 251, in connect
    self.sock, addrs = connect(url, self.sock_opt, proxy_info(**options),
                       ^^^^^^^^^^^^^^^^^^^^^^^^^^^^^^^^^^^^^^^^^^^^^^^^^^
  File "C:\Users\qwert\AppData\Local\Programs\Python\Python311\Lib\site-packages\websocket\_http.py", line 129, in connect
    sock = _open_socket(addrinfo_list, options.sockopt, options.timeout)
           ^^^^^^^^^^^^^^^^^^^^^^^^^^^^^^^^^^^^^^^^^^^^^^^^^^^^^^^^^^^^^
  File "C:\Users\qwert\AppData\Local\Programs\Python\Python311\Lib\site-packages\websocket\_http.py", line 204, in _open_socket
    raise err
  File "C:\Users\qwert\AppData\Local\Programs\Python\Python311\Lib\site-packages\websocket\_http.py", line 184, in _open_socket
    sock.connect(address)
ConnectionRefusedError: [WinError 10061] 由于目标计算机积极拒绝，无法连接。

2024-02-28 22:35:19 - anonbot.adapter.satori.adapter - ERROR - Error while connecting to WebSocket ws://127.0.0.1:8192/v1/events
Traceback (most recent call last):
  File "f:\VS Code File\anonbot\anonbot\adapter\satori\adapter.py", line 140, in ws
    with self.websocket(request) as ws:
  File "C:\Users\qwert\AppData\Local\Programs\Python\Python311\Lib\contextlib.py", line 137, in __enter__
    return next(self.gen)
           ^^^^^^^^^^^^^^
  File "f:\VS Code File\anonbot\anonbot\internal\adapter\adapter.py", line 82, in websocket
    with self.driver.websocket(setup) as websocket:
  File "C:\Users\qwert\AppData\Local\Programs\Python\Python311\Lib\contextlib.py", line 137, in __enter__
    return next(self.gen)
           ^^^^^^^^^^^^^^
  File "f:\VS Code File\anonbot\anonbot\driver\websocket.py", line 47, in websocket
    ws = create_connection(
         ^^^^^^^^^^^^^^^^^^
  File "C:\Users\qwert\AppData\Local\Programs\Python\Python311\Lib\site-packages\websocket\_core.py", line 610, in create_connection
    websock.connect(url, **options)
  File "C:\Users\qwert\AppData\Local\Programs\Python\Python311\Lib\site-packages\websocket\_core.py", line 251, in connect
    self.sock, addrs = connect(url, self.sock_opt, proxy_info(**options),
                       ^^^^^^^^^^^^^^^^^^^^^^^^^^^^^^^^^^^^^^^^^^^^^^^^^^
  File "C:\Users\qwert\AppData\Local\Programs\Python\Python311\Lib\site-packages\websocket\_http.py", line 129, in connect
    sock = _open_socket(addrinfo_list, options.sockopt, options.timeout)
           ^^^^^^^^^^^^^^^^^^^^^^^^^^^^^^^^^^^^^^^^^^^^^^^^^^^^^^^^^^^^^
  File "C:\Users\qwert\AppData\Local\Programs\Python\Python311\Lib\site-packages\websocket\_http.py", line 204, in _open_socket
    raise err
  File "C:\Users\qwert\AppData\Local\Programs\Python\Python311\Lib\site-packages\websocket\_http.py", line 184, in _open_socket
    sock.connect(address)
ConnectionRefusedError: [WinError 10061] 由于目标计算机积极拒绝，无法连接。

2024-02-28 22:35:24 - anonbot.adapter.satori.adapter - ERROR - Error while connecting to WebSocket ws://127.0.0.1:8192/v1/events
Traceback (most recent call last):
  File "f:\VS Code File\anonbot\anonbot\adapter\satori\adapter.py", line 140, in ws
    with self.websocket(request) as ws:
  File "C:\Users\qwert\AppData\Local\Programs\Python\Python311\Lib\contextlib.py", line 137, in __enter__
    return next(self.gen)
           ^^^^^^^^^^^^^^
  File "f:\VS Code File\anonbot\anonbot\internal\adapter\adapter.py", line 82, in websocket
    with self.driver.websocket(setup) as websocket:
  File "C:\Users\qwert\AppData\Local\Programs\Python\Python311\Lib\contextlib.py", line 137, in __enter__
    return next(self.gen)
           ^^^^^^^^^^^^^^
  File "f:\VS Code File\anonbot\anonbot\driver\websocket.py", line 47, in websocket
    ws = create_connection(
         ^^^^^^^^^^^^^^^^^^
  File "C:\Users\qwert\AppData\Local\Programs\Python\Python311\Lib\site-packages\websocket\_core.py", line 610, in create_connection
    websock.connect(url, **options)
  File "C:\Users\qwert\AppData\Local\Programs\Python\Python311\Lib\site-packages\websocket\_core.py", line 251, in connect
    self.sock, addrs = connect(url, self.sock_opt, proxy_info(**options),
                       ^^^^^^^^^^^^^^^^^^^^^^^^^^^^^^^^^^^^^^^^^^^^^^^^^^
  File "C:\Users\qwert\AppData\Local\Programs\Python\Python311\Lib\site-packages\websocket\_http.py", line 129, in connect
    sock = _open_socket(addrinfo_list, options.sockopt, options.timeout)
           ^^^^^^^^^^^^^^^^^^^^^^^^^^^^^^^^^^^^^^^^^^^^^^^^^^^^^^^^^^^^^
  File "C:\Users\qwert\AppData\Local\Programs\Python\Python311\Lib\site-packages\websocket\_http.py", line 204, in _open_socket
    raise err
  File "C:\Users\qwert\AppData\Local\Programs\Python\Python311\Lib\site-packages\websocket\_http.py", line 184, in _open_socket
    sock.connect(address)
ConnectionRefusedError: [WinError 10061] 由于目标计算机积极拒绝，无法连接。

2024-02-28 22:35:30 - anonbot.adapter.satori.adapter - ERROR - Error while connecting to WebSocket ws://127.0.0.1:8192/v1/events
Traceback (most recent call last):
  File "f:\VS Code File\anonbot\anonbot\adapter\satori\adapter.py", line 140, in ws
    with self.websocket(request) as ws:
  File "C:\Users\qwert\AppData\Local\Programs\Python\Python311\Lib\contextlib.py", line 137, in __enter__
    return next(self.gen)
           ^^^^^^^^^^^^^^
  File "f:\VS Code File\anonbot\anonbot\internal\adapter\adapter.py", line 82, in websocket
    with self.driver.websocket(setup) as websocket:
  File "C:\Users\qwert\AppData\Local\Programs\Python\Python311\Lib\contextlib.py", line 137, in __enter__
    return next(self.gen)
           ^^^^^^^^^^^^^^
  File "f:\VS Code File\anonbot\anonbot\driver\websocket.py", line 47, in websocket
    ws = create_connection(
         ^^^^^^^^^^^^^^^^^^
  File "C:\Users\qwert\AppData\Local\Programs\Python\Python311\Lib\site-packages\websocket\_core.py", line 610, in create_connection
    websock.connect(url, **options)
  File "C:\Users\qwert\AppData\Local\Programs\Python\Python311\Lib\site-packages\websocket\_core.py", line 251, in connect
    self.sock, addrs = connect(url, self.sock_opt, proxy_info(**options),
                       ^^^^^^^^^^^^^^^^^^^^^^^^^^^^^^^^^^^^^^^^^^^^^^^^^^
  File "C:\Users\qwert\AppData\Local\Programs\Python\Python311\Lib\site-packages\websocket\_http.py", line 129, in connect
    sock = _open_socket(addrinfo_list, options.sockopt, options.timeout)
           ^^^^^^^^^^^^^^^^^^^^^^^^^^^^^^^^^^^^^^^^^^^^^^^^^^^^^^^^^^^^^
  File "C:\Users\qwert\AppData\Local\Programs\Python\Python311\Lib\site-packages\websocket\_http.py", line 204, in _open_socket
    raise err
  File "C:\Users\qwert\AppData\Local\Programs\Python\Python311\Lib\site-packages\websocket\_http.py", line 184, in _open_socket
    sock.connect(address)
ConnectionRefusedError: [WinError 10061] 由于目标计算机积极拒绝，无法连接。

2024-02-28 22:35:35 - anonbot.adapter.satori.adapter - ERROR - Error while connecting to WebSocket ws://127.0.0.1:8192/v1/events
Traceback (most recent call last):
  File "f:\VS Code File\anonbot\anonbot\adapter\satori\adapter.py", line 140, in ws
    with self.websocket(request) as ws:
  File "C:\Users\qwert\AppData\Local\Programs\Python\Python311\Lib\contextlib.py", line 137, in __enter__
    return next(self.gen)
           ^^^^^^^^^^^^^^
  File "f:\VS Code File\anonbot\anonbot\internal\adapter\adapter.py", line 82, in websocket
    with self.driver.websocket(setup) as websocket:
  File "C:\Users\qwert\AppData\Local\Programs\Python\Python311\Lib\contextlib.py", line 137, in __enter__
    return next(self.gen)
           ^^^^^^^^^^^^^^
  File "f:\VS Code File\anonbot\anonbot\driver\websocket.py", line 47, in websocket
    ws = create_connection(
         ^^^^^^^^^^^^^^^^^^
  File "C:\Users\qwert\AppData\Local\Programs\Python\Python311\Lib\site-packages\websocket\_core.py", line 610, in create_connection
    websock.connect(url, **options)
  File "C:\Users\qwert\AppData\Local\Programs\Python\Python311\Lib\site-packages\websocket\_core.py", line 251, in connect
    self.sock, addrs = connect(url, self.sock_opt, proxy_info(**options),
                       ^^^^^^^^^^^^^^^^^^^^^^^^^^^^^^^^^^^^^^^^^^^^^^^^^^
  File "C:\Users\qwert\AppData\Local\Programs\Python\Python311\Lib\site-packages\websocket\_http.py", line 129, in connect
    sock = _open_socket(addrinfo_list, options.sockopt, options.timeout)
           ^^^^^^^^^^^^^^^^^^^^^^^^^^^^^^^^^^^^^^^^^^^^^^^^^^^^^^^^^^^^^
  File "C:\Users\qwert\AppData\Local\Programs\Python\Python311\Lib\site-packages\websocket\_http.py", line 204, in _open_socket
    raise err
  File "C:\Users\qwert\AppData\Local\Programs\Python\Python311\Lib\site-packages\websocket\_http.py", line 184, in _open_socket
    sock.connect(address)
ConnectionRefusedError: [WinError 10061] 由于目标计算机积极拒绝，无法连接。

2024-02-28 22:35:40 - anonbot.adapter.satori.adapter - ERROR - Error while connecting to WebSocket ws://127.0.0.1:8192/v1/events
Traceback (most recent call last):
  File "f:\VS Code File\anonbot\anonbot\adapter\satori\adapter.py", line 140, in ws
    with self.websocket(request) as ws:
  File "C:\Users\qwert\AppData\Local\Programs\Python\Python311\Lib\contextlib.py", line 137, in __enter__
    return next(self.gen)
           ^^^^^^^^^^^^^^
  File "f:\VS Code File\anonbot\anonbot\internal\adapter\adapter.py", line 82, in websocket
    with self.driver.websocket(setup) as websocket:
  File "C:\Users\qwert\AppData\Local\Programs\Python\Python311\Lib\contextlib.py", line 137, in __enter__
    return next(self.gen)
           ^^^^^^^^^^^^^^
  File "f:\VS Code File\anonbot\anonbot\driver\websocket.py", line 47, in websocket
    ws = create_connection(
         ^^^^^^^^^^^^^^^^^^
  File "C:\Users\qwert\AppData\Local\Programs\Python\Python311\Lib\site-packages\websocket\_core.py", line 610, in create_connection
    websock.connect(url, **options)
  File "C:\Users\qwert\AppData\Local\Programs\Python\Python311\Lib\site-packages\websocket\_core.py", line 251, in connect
    self.sock, addrs = connect(url, self.sock_opt, proxy_info(**options),
                       ^^^^^^^^^^^^^^^^^^^^^^^^^^^^^^^^^^^^^^^^^^^^^^^^^^
  File "C:\Users\qwert\AppData\Local\Programs\Python\Python311\Lib\site-packages\websocket\_http.py", line 129, in connect
    sock = _open_socket(addrinfo_list, options.sockopt, options.timeout)
           ^^^^^^^^^^^^^^^^^^^^^^^^^^^^^^^^^^^^^^^^^^^^^^^^^^^^^^^^^^^^^
  File "C:\Users\qwert\AppData\Local\Programs\Python\Python311\Lib\site-packages\websocket\_http.py", line 204, in _open_socket
    raise err
  File "C:\Users\qwert\AppData\Local\Programs\Python\Python311\Lib\site-packages\websocket\_http.py", line 184, in _open_socket
    sock.connect(address)
ConnectionRefusedError: [WinError 10061] 由于目标计算机积极拒绝，无法连接。

2024-02-28 22:35:45 - anonbot.adapter.satori.adapter - ERROR - Error while connecting to WebSocket ws://127.0.0.1:8192/v1/events
Traceback (most recent call last):
  File "f:\VS Code File\anonbot\anonbot\adapter\satori\adapter.py", line 140, in ws
    with self.websocket(request) as ws:
  File "C:\Users\qwert\AppData\Local\Programs\Python\Python311\Lib\contextlib.py", line 137, in __enter__
    return next(self.gen)
           ^^^^^^^^^^^^^^
  File "f:\VS Code File\anonbot\anonbot\internal\adapter\adapter.py", line 82, in websocket
    with self.driver.websocket(setup) as websocket:
  File "C:\Users\qwert\AppData\Local\Programs\Python\Python311\Lib\contextlib.py", line 137, in __enter__
    return next(self.gen)
           ^^^^^^^^^^^^^^
  File "f:\VS Code File\anonbot\anonbot\driver\websocket.py", line 47, in websocket
    ws = create_connection(
         ^^^^^^^^^^^^^^^^^^
  File "C:\Users\qwert\AppData\Local\Programs\Python\Python311\Lib\site-packages\websocket\_core.py", line 610, in create_connection
    websock.connect(url, **options)
  File "C:\Users\qwert\AppData\Local\Programs\Python\Python311\Lib\site-packages\websocket\_core.py", line 251, in connect
    self.sock, addrs = connect(url, self.sock_opt, proxy_info(**options),
                       ^^^^^^^^^^^^^^^^^^^^^^^^^^^^^^^^^^^^^^^^^^^^^^^^^^
  File "C:\Users\qwert\AppData\Local\Programs\Python\Python311\Lib\site-packages\websocket\_http.py", line 129, in connect
    sock = _open_socket(addrinfo_list, options.sockopt, options.timeout)
           ^^^^^^^^^^^^^^^^^^^^^^^^^^^^^^^^^^^^^^^^^^^^^^^^^^^^^^^^^^^^^
  File "C:\Users\qwert\AppData\Local\Programs\Python\Python311\Lib\site-packages\websocket\_http.py", line 204, in _open_socket
    raise err
  File "C:\Users\qwert\AppData\Local\Programs\Python\Python311\Lib\site-packages\websocket\_http.py", line 184, in _open_socket
    sock.connect(address)
ConnectionRefusedError: [WinError 10061] 由于目标计算机积极拒绝，无法连接。

2024-02-28 23:07:59 - anonbot - INFO - Initializing AnonBot
2024-02-28 23:08:00 - anonbot.internal.driver.abstract - DEBUG - Driver(type='general+websocket+flask+httpx', adapters=1, bots=0) 成功注册 adapter Satori
2024-02-28 23:08:00 - anonbot.internal.driver.abstract - DEBUG - Adapters Loaded: Satori
2024-02-28 23:08:00 - anonbot.driver.general - INFO - 应用启动成功
2024-02-28 23:08:21 - anonbot.adapter.satori.adapter - ERROR - Error while connecting to WebSocket ws://bot.kasumibot.cn:39404/v1/events
Traceback (most recent call last):
  File "f:\VS Code File\anonbot\anonbot\adapter\satori\adapter.py", line 137, in ws
    with self.websocket(request) as ws:
  File "C:\Users\qwert\AppData\Local\Programs\Python\Python311\Lib\contextlib.py", line 137, in __enter__
    return next(self.gen)
           ^^^^^^^^^^^^^^
  File "f:\VS Code File\anonbot\anonbot\internal\adapter\adapter.py", line 82, in websocket
    with self.driver.websocket(setup) as websocket:
  File "C:\Users\qwert\AppData\Local\Programs\Python\Python311\Lib\contextlib.py", line 137, in __enter__
    return next(self.gen)
           ^^^^^^^^^^^^^^
  File "f:\VS Code File\anonbot\anonbot\driver\websocket.py", line 47, in websocket
    ws = create_connection(
         ^^^^^^^^^^^^^^^^^^
  File "C:\Users\qwert\AppData\Local\Programs\Python\Python311\Lib\site-packages\websocket\_core.py", line 610, in create_connection
    websock.connect(url, **options)
  File "C:\Users\qwert\AppData\Local\Programs\Python\Python311\Lib\site-packages\websocket\_core.py", line 251, in connect
    self.sock, addrs = connect(url, self.sock_opt, proxy_info(**options),
                       ^^^^^^^^^^^^^^^^^^^^^^^^^^^^^^^^^^^^^^^^^^^^^^^^^^
  File "C:\Users\qwert\AppData\Local\Programs\Python\Python311\Lib\site-packages\websocket\_http.py", line 129, in connect
    sock = _open_socket(addrinfo_list, options.sockopt, options.timeout)
           ^^^^^^^^^^^^^^^^^^^^^^^^^^^^^^^^^^^^^^^^^^^^^^^^^^^^^^^^^^^^^
  File "C:\Users\qwert\AppData\Local\Programs\Python\Python311\Lib\site-packages\websocket\_http.py", line 196, in _open_socket
    raise error
  File "C:\Users\qwert\AppData\Local\Programs\Python\Python311\Lib\site-packages\websocket\_http.py", line 184, in _open_socket
    sock.connect(address)
TimeoutError: [WinError 10060] 由于连接方在一段时间后没有正确答复或连接的主机没有反应，连接尝试失败。

2024-02-28 23:10:18 - anonbot - INFO - Initializing AnonBot
2024-02-28 23:10:19 - anonbot.internal.driver.abstract - DEBUG - Driver(type='general+websocket+flask+httpx', adapters=1, bots=0) 成功注册 adapter Satori
2024-02-28 23:10:19 - anonbot.internal.driver.abstract - DEBUG - Adapters Loaded: Satori
2024-02-28 23:10:19 - anonbot.driver.general - INFO - 应用启动成功
2024-02-28 23:10:40 - anonbot.adapter.satori.adapter - ERROR - Error while connecting to WebSocket ws://bot.kasumibot.cn:39306/v1/events
Traceback (most recent call last):
  File "f:\VS Code File\anonbot\anonbot\adapter\satori\adapter.py", line 137, in ws
    with self.websocket(request) as ws:
  File "C:\Users\qwert\AppData\Local\Programs\Python\Python311\Lib\contextlib.py", line 137, in __enter__
    return next(self.gen)
           ^^^^^^^^^^^^^^
  File "f:\VS Code File\anonbot\anonbot\internal\adapter\adapter.py", line 82, in websocket
    with self.driver.websocket(setup) as websocket:
  File "C:\Users\qwert\AppData\Local\Programs\Python\Python311\Lib\contextlib.py", line 137, in __enter__
    return next(self.gen)
           ^^^^^^^^^^^^^^
  File "f:\VS Code File\anonbot\anonbot\driver\websocket.py", line 47, in websocket
    ws = create_connection(
         ^^^^^^^^^^^^^^^^^^
  File "C:\Users\qwert\AppData\Local\Programs\Python\Python311\Lib\site-packages\websocket\_core.py", line 610, in create_connection
    websock.connect(url, **options)
  File "C:\Users\qwert\AppData\Local\Programs\Python\Python311\Lib\site-packages\websocket\_core.py", line 251, in connect
    self.sock, addrs = connect(url, self.sock_opt, proxy_info(**options),
                       ^^^^^^^^^^^^^^^^^^^^^^^^^^^^^^^^^^^^^^^^^^^^^^^^^^
  File "C:\Users\qwert\AppData\Local\Programs\Python\Python311\Lib\site-packages\websocket\_http.py", line 129, in connect
    sock = _open_socket(addrinfo_list, options.sockopt, options.timeout)
           ^^^^^^^^^^^^^^^^^^^^^^^^^^^^^^^^^^^^^^^^^^^^^^^^^^^^^^^^^^^^^
  File "C:\Users\qwert\AppData\Local\Programs\Python\Python311\Lib\site-packages\websocket\_http.py", line 196, in _open_socket
    raise error
  File "C:\Users\qwert\AppData\Local\Programs\Python\Python311\Lib\site-packages\websocket\_http.py", line 184, in _open_socket
    sock.connect(address)
TimeoutError: [WinError 10060] 由于连接方在一段时间后没有正确答复或连接的主机没有反应，连接尝试失败。

2024-02-28 23:11:04 - anonbot.adapter.satori.adapter - ERROR - Error while connecting to WebSocket ws://bot.kasumibot.cn:39306/v1/events
Traceback (most recent call last):
  File "f:\VS Code File\anonbot\anonbot\adapter\satori\adapter.py", line 137, in ws
    with self.websocket(request) as ws:
  File "C:\Users\qwert\AppData\Local\Programs\Python\Python311\Lib\contextlib.py", line 137, in __enter__
    return next(self.gen)
           ^^^^^^^^^^^^^^
  File "f:\VS Code File\anonbot\anonbot\internal\adapter\adapter.py", line 82, in websocket
    with self.driver.websocket(setup) as websocket:
  File "C:\Users\qwert\AppData\Local\Programs\Python\Python311\Lib\contextlib.py", line 137, in __enter__
    return next(self.gen)
           ^^^^^^^^^^^^^^
  File "f:\VS Code File\anonbot\anonbot\driver\websocket.py", line 47, in websocket
    ws = create_connection(
         ^^^^^^^^^^^^^^^^^^
  File "C:\Users\qwert\AppData\Local\Programs\Python\Python311\Lib\site-packages\websocket\_core.py", line 610, in create_connection
    websock.connect(url, **options)
  File "C:\Users\qwert\AppData\Local\Programs\Python\Python311\Lib\site-packages\websocket\_core.py", line 251, in connect
    self.sock, addrs = connect(url, self.sock_opt, proxy_info(**options),
                       ^^^^^^^^^^^^^^^^^^^^^^^^^^^^^^^^^^^^^^^^^^^^^^^^^^
  File "C:\Users\qwert\AppData\Local\Programs\Python\Python311\Lib\site-packages\websocket\_http.py", line 129, in connect
    sock = _open_socket(addrinfo_list, options.sockopt, options.timeout)
           ^^^^^^^^^^^^^^^^^^^^^^^^^^^^^^^^^^^^^^^^^^^^^^^^^^^^^^^^^^^^^
  File "C:\Users\qwert\AppData\Local\Programs\Python\Python311\Lib\site-packages\websocket\_http.py", line 196, in _open_socket
    raise error
  File "C:\Users\qwert\AppData\Local\Programs\Python\Python311\Lib\site-packages\websocket\_http.py", line 184, in _open_socket
    sock.connect(address)
TimeoutError: [WinError 10060] 由于连接方在一段时间后没有正确答复或连接的主机没有反应，连接尝试失败。

2024-02-28 23:13:11 - anonbot - INFO - Initializing AnonBot
2024-02-28 23:13:12 - anonbot.internal.driver.abstract - DEBUG - Driver(type='general+websocket+flask+httpx', adapters=1, bots=0) 成功注册 adapter Satori
2024-02-28 23:13:12 - anonbot.internal.driver.abstract - DEBUG - Adapters Loaded: Satori
2024-02-28 23:13:12 - anonbot.driver.general - INFO - 应用启动成功
2024-02-28 23:13:33 - anonbot.adapter.satori.adapter - ERROR - Error while connecting to WebSocket ws://bot.kasumibot.cn:39306/v1/events
Traceback (most recent call last):
  File "f:\VS Code File\anonbot\anonbot\adapter\satori\adapter.py", line 137, in ws
    with self.websocket(request) as ws:
  File "C:\Users\qwert\AppData\Local\Programs\Python\Python311\Lib\contextlib.py", line 137, in __enter__
    return next(self.gen)
           ^^^^^^^^^^^^^^
  File "f:\VS Code File\anonbot\anonbot\internal\adapter\adapter.py", line 82, in websocket
    with self.driver.websocket(setup) as websocket:
  File "C:\Users\qwert\AppData\Local\Programs\Python\Python311\Lib\contextlib.py", line 137, in __enter__
    return next(self.gen)
           ^^^^^^^^^^^^^^
  File "f:\VS Code File\anonbot\anonbot\driver\websocket.py", line 47, in websocket
    ws = create_connection(
         ^^^^^^^^^^^^^^^^^^
  File "C:\Users\qwert\AppData\Local\Programs\Python\Python311\Lib\site-packages\websocket\_core.py", line 610, in create_connection
    websock.connect(url, **options)
  File "C:\Users\qwert\AppData\Local\Programs\Python\Python311\Lib\site-packages\websocket\_core.py", line 251, in connect
    self.sock, addrs = connect(url, self.sock_opt, proxy_info(**options),
                       ^^^^^^^^^^^^^^^^^^^^^^^^^^^^^^^^^^^^^^^^^^^^^^^^^^
  File "C:\Users\qwert\AppData\Local\Programs\Python\Python311\Lib\site-packages\websocket\_http.py", line 129, in connect
    sock = _open_socket(addrinfo_list, options.sockopt, options.timeout)
           ^^^^^^^^^^^^^^^^^^^^^^^^^^^^^^^^^^^^^^^^^^^^^^^^^^^^^^^^^^^^^
  File "C:\Users\qwert\AppData\Local\Programs\Python\Python311\Lib\site-packages\websocket\_http.py", line 196, in _open_socket
    raise error
  File "C:\Users\qwert\AppData\Local\Programs\Python\Python311\Lib\site-packages\websocket\_http.py", line 184, in _open_socket
    sock.connect(address)
TimeoutError: [WinError 10060] 由于连接方在一段时间后没有正确答复或连接的主机没有反应，连接尝试失败。

2024-02-28 23:13:57 - anonbot.adapter.satori.adapter - ERROR - Error while connecting to WebSocket ws://bot.kasumibot.cn:39306/v1/events
Traceback (most recent call last):
  File "f:\VS Code File\anonbot\anonbot\adapter\satori\adapter.py", line 137, in ws
    with self.websocket(request) as ws:
  File "C:\Users\qwert\AppData\Local\Programs\Python\Python311\Lib\contextlib.py", line 137, in __enter__
    return next(self.gen)
           ^^^^^^^^^^^^^^
  File "f:\VS Code File\anonbot\anonbot\internal\adapter\adapter.py", line 82, in websocket
    with self.driver.websocket(setup) as websocket:
  File "C:\Users\qwert\AppData\Local\Programs\Python\Python311\Lib\contextlib.py", line 137, in __enter__
    return next(self.gen)
           ^^^^^^^^^^^^^^
  File "f:\VS Code File\anonbot\anonbot\driver\websocket.py", line 47, in websocket
    ws = create_connection(
         ^^^^^^^^^^^^^^^^^^
  File "C:\Users\qwert\AppData\Local\Programs\Python\Python311\Lib\site-packages\websocket\_core.py", line 610, in create_connection
    websock.connect(url, **options)
  File "C:\Users\qwert\AppData\Local\Programs\Python\Python311\Lib\site-packages\websocket\_core.py", line 251, in connect
    self.sock, addrs = connect(url, self.sock_opt, proxy_info(**options),
                       ^^^^^^^^^^^^^^^^^^^^^^^^^^^^^^^^^^^^^^^^^^^^^^^^^^
  File "C:\Users\qwert\AppData\Local\Programs\Python\Python311\Lib\site-packages\websocket\_http.py", line 129, in connect
    sock = _open_socket(addrinfo_list, options.sockopt, options.timeout)
           ^^^^^^^^^^^^^^^^^^^^^^^^^^^^^^^^^^^^^^^^^^^^^^^^^^^^^^^^^^^^^
  File "C:\Users\qwert\AppData\Local\Programs\Python\Python311\Lib\site-packages\websocket\_http.py", line 196, in _open_socket
    raise error
  File "C:\Users\qwert\AppData\Local\Programs\Python\Python311\Lib\site-packages\websocket\_http.py", line 184, in _open_socket
    sock.connect(address)
TimeoutError: [WinError 10060] 由于连接方在一段时间后没有正确答复或连接的主机没有反应，连接尝试失败。

2024-02-28 23:17:16 - anonbot - INFO - Initializing AnonBot
2024-02-28 23:17:16 - anonbot.internal.driver.abstract - DEBUG - Driver(type='general+websocket+flask+httpx', adapters=1, bots=0) 成功注册 adapter Satori
2024-02-28 23:17:16 - anonbot.internal.driver.abstract - DEBUG - Adapters Loaded: Satori
2024-02-28 23:17:16 - anonbot.driver.general - INFO - 应用启动成功
2024-02-28 23:17:17 - anonbot.adapter.satori.adapter - DEBUG - WebSocket connected to ws://bot.kasumibot.cn:39306/v1/events
2024-02-28 23:17:17 - anonbot.adapter.satori.adapter - ERROR - Received unexpected payload: op=<Opcode.IDENTIFY: 3> body=Identify(token='TanebiChihaya', sequence=None)
2024-02-28 23:17:20 - anonbot.adapter.satori.adapter - DEBUG - WebSocket connected to ws://bot.kasumibot.cn:39306/v1/events
2024-02-28 23:17:20 - anonbot.adapter.satori.adapter - ERROR - Received unexpected payload: op=<Opcode.IDENTIFY: 3> body=Identify(token='TanebiChihaya', sequence=None)
2024-02-28 23:17:24 - anonbot.adapter.satori.adapter - DEBUG - WebSocket connected to ws://bot.kasumibot.cn:39306/v1/events
2024-02-28 23:17:24 - anonbot.adapter.satori.adapter - ERROR - Received unexpected payload: op=<Opcode.IDENTIFY: 3> body=Identify(token='TanebiChihaya', sequence=None)
2024-02-28 23:17:27 - anonbot.adapter.satori.adapter - DEBUG - WebSocket connected to ws://bot.kasumibot.cn:39306/v1/events
2024-02-28 23:17:27 - anonbot.adapter.satori.adapter - ERROR - Received unexpected payload: op=<Opcode.IDENTIFY: 3> body=Identify(token='TanebiChihaya', sequence=None)
2024-02-28 23:17:31 - anonbot.adapter.satori.adapter - DEBUG - WebSocket connected to ws://bot.kasumibot.cn:39306/v1/events
2024-02-28 23:17:31 - anonbot.adapter.satori.adapter - ERROR - Received unexpected payload: op=<Opcode.IDENTIFY: 3> body=Identify(token='TanebiChihaya', sequence=None)
2024-02-28 23:17:34 - anonbot.adapter.satori.adapter - DEBUG - WebSocket connected to ws://bot.kasumibot.cn:39306/v1/events
2024-02-28 23:17:35 - anonbot.adapter.satori.adapter - ERROR - Received unexpected payload: op=<Opcode.IDENTIFY: 3> body=Identify(token='TanebiChihaya', sequence=None)
2024-02-28 23:17:38 - anonbot.adapter.satori.adapter - DEBUG - WebSocket connected to ws://bot.kasumibot.cn:39306/v1/events
2024-02-28 23:17:38 - anonbot.adapter.satori.adapter - ERROR - Received unexpected payload: op=<Opcode.IDENTIFY: 3> body=Identify(token='TanebiChihaya', sequence=None)
2024-02-28 23:17:42 - anonbot.adapter.satori.adapter - DEBUG - WebSocket connected to ws://bot.kasumibot.cn:39306/v1/events
2024-02-28 23:17:42 - anonbot.adapter.satori.adapter - ERROR - Received unexpected payload: op=<Opcode.IDENTIFY: 3> body=Identify(token='TanebiChihaya', sequence=None)
2024-02-28 23:18:31 - anonbot - INFO - Initializing AnonBot
2024-02-28 23:18:32 - anonbot.internal.driver.abstract - DEBUG - Driver(type='general+websocket+flask+httpx', adapters=1, bots=0) 成功注册 adapter Satori
2024-02-28 23:18:32 - anonbot.internal.driver.abstract - DEBUG - Adapters Loaded: Satori
2024-02-28 23:18:32 - anonbot.driver.general - INFO - 应用启动成功
2024-02-28 23:18:32 - anonbot.adapter.satori.adapter - DEBUG - WebSocket connected to ws://bot.kasumibot.cn:39306/v1/events
2024-02-28 23:18:32 - anonbot.adapter.satori.adapter - ERROR - Received unexpected payload: op=<Opcode.IDENTIFY: 3> body=Identify(token='TanebiChihaya', sequence=None)
2024-02-28 23:18:36 - anonbot.adapter.satori.adapter - DEBUG - WebSocket connected to ws://bot.kasumibot.cn:39306/v1/events
2024-02-28 23:18:36 - anonbot.adapter.satori.adapter - ERROR - Received unexpected payload: op=<Opcode.IDENTIFY: 3> body=Identify(token='TanebiChihaya', sequence=None)
2024-02-28 23:18:39 - anonbot.adapter.satori.adapter - DEBUG - WebSocket connected to ws://bot.kasumibot.cn:39306/v1/events
2024-02-28 23:18:39 - anonbot.adapter.satori.adapter - ERROR - Received unexpected payload: op=<Opcode.IDENTIFY: 3> body=Identify(token='TanebiChihaya', sequence=None)
2024-02-28 23:18:43 - anonbot.adapter.satori.adapter - DEBUG - WebSocket connected to ws://bot.kasumibot.cn:39306/v1/events
2024-02-28 23:18:43 - anonbot.adapter.satori.adapter - ERROR - Received unexpected payload: op=<Opcode.IDENTIFY: 3> body=Identify(token='TanebiChihaya', sequence=None)
2024-02-28 23:18:46 - anonbot.adapter.satori.adapter - DEBUG - WebSocket connected to ws://bot.kasumibot.cn:39306/v1/events
2024-02-28 23:18:47 - anonbot.adapter.satori.adapter - ERROR - Received unexpected payload: op=<Opcode.IDENTIFY: 3> body=Identify(token='TanebiChihaya', sequence=None)
2024-02-28 23:18:50 - anonbot.adapter.satori.adapter - DEBUG - WebSocket connected to ws://bot.kasumibot.cn:39306/v1/events
2024-02-28 23:18:50 - anonbot.adapter.satori.adapter - ERROR - Received unexpected payload: op=<Opcode.IDENTIFY: 3> body=Identify(token='TanebiChihaya', sequence=None)
2024-02-28 23:18:53 - anonbot.adapter.satori.adapter - DEBUG - WebSocket connected to ws://bot.kasumibot.cn:39306/v1/events
2024-02-28 23:18:54 - anonbot.adapter.satori.adapter - ERROR - Received unexpected payload: op=<Opcode.IDENTIFY: 3> body=Identify(token='TanebiChihaya', sequence=None)
2024-02-28 23:18:57 - anonbot.adapter.satori.adapter - DEBUG - WebSocket connected to ws://bot.kasumibot.cn:39306/v1/events
2024-02-28 23:18:57 - anonbot.adapter.satori.adapter - ERROR - Received unexpected payload: op=<Opcode.IDENTIFY: 3> body=Identify(token='TanebiChihaya', sequence=None)
2024-02-28 23:19:01 - anonbot.adapter.satori.adapter - DEBUG - WebSocket connected to ws://bot.kasumibot.cn:39306/v1/events
2024-02-28 23:19:01 - anonbot.adapter.satori.adapter - ERROR - Received unexpected payload: op=<Opcode.IDENTIFY: 3> body=Identify(token='TanebiChihaya', sequence=None)
2024-02-28 23:19:04 - anonbot.adapter.satori.adapter - DEBUG - WebSocket connected to ws://bot.kasumibot.cn:39306/v1/events
2024-02-28 23:19:04 - anonbot.adapter.satori.adapter - ERROR - Received unexpected payload: op=<Opcode.IDENTIFY: 3> body=Identify(token='TanebiChihaya', sequence=None)
2024-02-28 23:19:08 - anonbot.adapter.satori.adapter - DEBUG - WebSocket connected to ws://bot.kasumibot.cn:39306/v1/events
2024-02-28 23:19:08 - anonbot.adapter.satori.adapter - ERROR - Received unexpected payload: op=<Opcode.IDENTIFY: 3> body=Identify(token='TanebiChihaya', sequence=None)
2024-02-28 23:20:01 - anonbot - INFO - Initializing AnonBot
2024-02-28 23:20:01 - anonbot.internal.driver.abstract - DEBUG - Driver(type='general+websocket+flask+httpx', adapters=1, bots=0) 成功注册 adapter Satori
2024-02-28 23:20:01 - anonbot.internal.driver.abstract - DEBUG - Adapters Loaded: Satori
2024-02-28 23:20:01 - anonbot.driver.general - INFO - 应用启动成功
2024-02-28 23:20:02 - anonbot.adapter.satori.adapter - DEBUG - WebSocket connected to ws://bot.kasumibot.cn:39306/v1/events
2024-02-28 23:20:02 - anonbot.adapter.satori.adapter - ERROR - Received unexpected payload: op=<Opcode.READY: 4> body={'logins': [{'user': {'id': '3662854527', 'name': 'Tane Chihaya', 'is_bot': True}, 'self_id': '3662854527', 'platform': 'chronocat', 'status': 1}]}
2024-02-28 23:20:05 - anonbot.adapter.satori.adapter - DEBUG - WebSocket connected to ws://bot.kasumibot.cn:39306/v1/events
2024-02-28 23:20:05 - anonbot.adapter.satori.adapter - ERROR - Received unexpected payload: op=<Opcode.READY: 4> body={'logins': [{'user': {'id': '3662854527', 'name': 'Tane Chihaya', 'is_bot': True}, 'self_id': '3662854527', 'platform': 'chronocat', 'status': 1}]}
2024-02-28 23:25:14 - anonbot - INFO - Initializing AnonBot
2024-02-28 23:25:14 - anonbot.internal.driver.abstract - DEBUG - Driver(type='general+websocket+flask+httpx', adapters=1, bots=0) 成功注册 adapter Satori
2024-02-28 23:25:14 - anonbot.internal.driver.abstract - DEBUG - Adapters Loaded: Satori
2024-02-28 23:25:14 - anonbot.driver.general - INFO - 应用启动成功
2024-02-28 23:25:15 - anonbot.adapter.satori.adapter - DEBUG - WebSocket connected to ws://bot.kasumibot.cn:39306/v1/events
2024-02-28 23:25:15 - anonbot.adapter.satori.adapter - ERROR - Error while process data from WebSocket ws://bot.kasumibot.cn:39306/v1/events
Traceback (most recent call last):
  File "f:\VS Code File\anonbot\anonbot\adapter\satori\adapter.py", line 142, in ws
    if not self._authenticate(info, ws):
           ^^^^^^^^^^^^^^^^^^^^^^^^^^^^
  File "f:\VS Code File\anonbot\anonbot\adapter\satori\adapter.py", line 101, in _authenticate
    response = self.receive_payload(info, ws)
               ^^^^^^^^^^^^^^^^^^^^^^^^^^^^^^
  File "f:\VS Code File\anonbot\anonbot\adapter\satori\adapter.py", line 79, in receive_payload
    payload = TypeAdapter(PayloadType).validate_python(json.loads(ws.receive()))
              ^^^^^^^^^^^^^^^^^^^^^^^^^^^^^^^^^^^^^^^^^^^^^^^^^^^^^^^^^^^^^^^^^^
  File "C:\Users\qwert\AppData\Local\Programs\Python\Python311\Lib\site-packages\pydantic\type_adapter.py", line 256, in validate_python
    return self.validator.validate_python(__object, strict=strict, from_attributes=from_attributes, context=context)
           ^^^^^^^^^^^^^^^^^^^^^^^^^^^^^^^^^^^^^^^^^^^^^^^^^^^^^^^^^^^^^^^^^^^^^^^^^^^^^^^^^^^^^^^^^^^^^^^^^^^^^^^^^
  File "<string>", line 3, in __init__
  File "C:\Users\qwert\AppData\Local\Programs\Python\Python311\Lib\site-packages\pydantic\main.py", line 810, in __setattr__
    self.__pydantic_fields_set__.add(name)
    ^^^^^^^^^^^^^^^^^^^^^^^^^^^^
  File "C:\Users\qwert\AppData\Local\Programs\Python\Python311\Lib\site-packages\pydantic\main.py", line 764, in __getattr__
    return super().__getattribute__(item)  # Raises AttributeError if appropriate
           ^^^^^^^^^^^^^^^^^^^^^^^^^^^^^^
AttributeError: 'OuterLogin' object has no attribute '__pydantic_fields_set__'

2024-02-28 23:25:15 - anonbot.adapter.satori.adapter - DEBUG - WebSocket connected to ws://bot.kasumibot.cn:39306/v1/events
2024-02-28 23:25:15 - anonbot.adapter.satori.adapter - ERROR - Error while process data from WebSocket ws://bot.kasumibot.cn:39306/v1/events
Traceback (most recent call last):
  File "f:\VS Code File\anonbot\anonbot\adapter\satori\adapter.py", line 142, in ws
    if not self._authenticate(info, ws):
           ^^^^^^^^^^^^^^^^^^^^^^^^^^^^
  File "f:\VS Code File\anonbot\anonbot\adapter\satori\adapter.py", line 101, in _authenticate
    response = self.receive_payload(info, ws)
               ^^^^^^^^^^^^^^^^^^^^^^^^^^^^^^
  File "f:\VS Code File\anonbot\anonbot\adapter\satori\adapter.py", line 79, in receive_payload
    payload = TypeAdapter(PayloadType).validate_python(json.loads(ws.receive()))
              ^^^^^^^^^^^^^^^^^^^^^^^^^^^^^^^^^^^^^^^^^^^^^^^^^^^^^^^^^^^^^^^^^^
  File "C:\Users\qwert\AppData\Local\Programs\Python\Python311\Lib\site-packages\pydantic\type_adapter.py", line 256, in validate_python
    return self.validator.validate_python(__object, strict=strict, from_attributes=from_attributes, context=context)
           ^^^^^^^^^^^^^^^^^^^^^^^^^^^^^^^^^^^^^^^^^^^^^^^^^^^^^^^^^^^^^^^^^^^^^^^^^^^^^^^^^^^^^^^^^^^^^^^^^^^^^^^^^
  File "<string>", line 3, in __init__
  File "C:\Users\qwert\AppData\Local\Programs\Python\Python311\Lib\site-packages\pydantic\main.py", line 810, in __setattr__
    self.__pydantic_fields_set__.add(name)
    ^^^^^^^^^^^^^^^^^^^^^^^^^^^^
  File "C:\Users\qwert\AppData\Local\Programs\Python\Python311\Lib\site-packages\pydantic\main.py", line 764, in __getattr__
    return super().__getattribute__(item)  # Raises AttributeError if appropriate
           ^^^^^^^^^^^^^^^^^^^^^^^^^^^^^^
AttributeError: 'OuterLogin' object has no attribute '__pydantic_fields_set__'

2024-02-28 23:25:16 - anonbot.adapter.satori.adapter - DEBUG - WebSocket connected to ws://bot.kasumibot.cn:39306/v1/events
2024-02-28 23:25:16 - anonbot.adapter.satori.adapter - ERROR - Error while process data from WebSocket ws://bot.kasumibot.cn:39306/v1/events
Traceback (most recent call last):
  File "f:\VS Code File\anonbot\anonbot\adapter\satori\adapter.py", line 142, in ws
    if not self._authenticate(info, ws):
           ^^^^^^^^^^^^^^^^^^^^^^^^^^^^
  File "f:\VS Code File\anonbot\anonbot\adapter\satori\adapter.py", line 101, in _authenticate
    response = self.receive_payload(info, ws)
               ^^^^^^^^^^^^^^^^^^^^^^^^^^^^^^
  File "f:\VS Code File\anonbot\anonbot\adapter\satori\adapter.py", line 79, in receive_payload
    payload = TypeAdapter(PayloadType).validate_python(json.loads(ws.receive()))
              ^^^^^^^^^^^^^^^^^^^^^^^^^^^^^^^^^^^^^^^^^^^^^^^^^^^^^^^^^^^^^^^^^^
  File "C:\Users\qwert\AppData\Local\Programs\Python\Python311\Lib\site-packages\pydantic\type_adapter.py", line 256, in validate_python
    return self.validator.validate_python(__object, strict=strict, from_attributes=from_attributes, context=context)
           ^^^^^^^^^^^^^^^^^^^^^^^^^^^^^^^^^^^^^^^^^^^^^^^^^^^^^^^^^^^^^^^^^^^^^^^^^^^^^^^^^^^^^^^^^^^^^^^^^^^^^^^^^
  File "<string>", line 3, in __init__
  File "C:\Users\qwert\AppData\Local\Programs\Python\Python311\Lib\site-packages\pydantic\main.py", line 810, in __setattr__
    self.__pydantic_fields_set__.add(name)
    ^^^^^^^^^^^^^^^^^^^^^^^^^^^^
  File "C:\Users\qwert\AppData\Local\Programs\Python\Python311\Lib\site-packages\pydantic\main.py", line 764, in __getattr__
    return super().__getattribute__(item)  # Raises AttributeError if appropriate
           ^^^^^^^^^^^^^^^^^^^^^^^^^^^^^^
AttributeError: 'OuterLogin' object has no attribute '__pydantic_fields_set__'

2024-02-28 23:25:16 - anonbot.adapter.satori.adapter - DEBUG - WebSocket connected to ws://bot.kasumibot.cn:39306/v1/events
2024-02-28 23:25:17 - anonbot.adapter.satori.adapter - ERROR - Error while process data from WebSocket ws://bot.kasumibot.cn:39306/v1/events
Traceback (most recent call last):
  File "f:\VS Code File\anonbot\anonbot\adapter\satori\adapter.py", line 142, in ws
    if not self._authenticate(info, ws):
           ^^^^^^^^^^^^^^^^^^^^^^^^^^^^
  File "f:\VS Code File\anonbot\anonbot\adapter\satori\adapter.py", line 101, in _authenticate
    response = self.receive_payload(info, ws)
               ^^^^^^^^^^^^^^^^^^^^^^^^^^^^^^
  File "f:\VS Code File\anonbot\anonbot\adapter\satori\adapter.py", line 79, in receive_payload
    payload = TypeAdapter(PayloadType).validate_python(json.loads(ws.receive()))
              ^^^^^^^^^^^^^^^^^^^^^^^^^^^^^^^^^^^^^^^^^^^^^^^^^^^^^^^^^^^^^^^^^^
  File "C:\Users\qwert\AppData\Local\Programs\Python\Python311\Lib\site-packages\pydantic\type_adapter.py", line 256, in validate_python
    return self.validator.validate_python(__object, strict=strict, from_attributes=from_attributes, context=context)
           ^^^^^^^^^^^^^^^^^^^^^^^^^^^^^^^^^^^^^^^^^^^^^^^^^^^^^^^^^^^^^^^^^^^^^^^^^^^^^^^^^^^^^^^^^^^^^^^^^^^^^^^^^
  File "<string>", line 3, in __init__
  File "C:\Users\qwert\AppData\Local\Programs\Python\Python311\Lib\site-packages\pydantic\main.py", line 810, in __setattr__
    self.__pydantic_fields_set__.add(name)
    ^^^^^^^^^^^^^^^^^^^^^^^^^^^^
  File "C:\Users\qwert\AppData\Local\Programs\Python\Python311\Lib\site-packages\pydantic\main.py", line 764, in __getattr__
    return super().__getattribute__(item)  # Raises AttributeError if appropriate
           ^^^^^^^^^^^^^^^^^^^^^^^^^^^^^^
AttributeError: 'OuterLogin' object has no attribute '__pydantic_fields_set__'

2024-02-28 23:25:17 - anonbot.adapter.satori.adapter - DEBUG - WebSocket connected to ws://bot.kasumibot.cn:39306/v1/events
2024-02-28 23:25:17 - anonbot.adapter.satori.adapter - ERROR - Error while process data from WebSocket ws://bot.kasumibot.cn:39306/v1/events
Traceback (most recent call last):
  File "f:\VS Code File\anonbot\anonbot\adapter\satori\adapter.py", line 142, in ws
    if not self._authenticate(info, ws):
           ^^^^^^^^^^^^^^^^^^^^^^^^^^^^
  File "f:\VS Code File\anonbot\anonbot\adapter\satori\adapter.py", line 101, in _authenticate
    response = self.receive_payload(info, ws)
               ^^^^^^^^^^^^^^^^^^^^^^^^^^^^^^
  File "f:\VS Code File\anonbot\anonbot\adapter\satori\adapter.py", line 79, in receive_payload
    payload = TypeAdapter(PayloadType).validate_python(json.loads(ws.receive()))
              ^^^^^^^^^^^^^^^^^^^^^^^^^^^^^^^^^^^^^^^^^^^^^^^^^^^^^^^^^^^^^^^^^^
  File "C:\Users\qwert\AppData\Local\Programs\Python\Python311\Lib\site-packages\pydantic\type_adapter.py", line 256, in validate_python
    return self.validator.validate_python(__object, strict=strict, from_attributes=from_attributes, context=context)
           ^^^^^^^^^^^^^^^^^^^^^^^^^^^^^^^^^^^^^^^^^^^^^^^^^^^^^^^^^^^^^^^^^^^^^^^^^^^^^^^^^^^^^^^^^^^^^^^^^^^^^^^^^
  File "<string>", line 3, in __init__
  File "C:\Users\qwert\AppData\Local\Programs\Python\Python311\Lib\site-packages\pydantic\main.py", line 810, in __setattr__
    self.__pydantic_fields_set__.add(name)
    ^^^^^^^^^^^^^^^^^^^^^^^^^^^^
  File "C:\Users\qwert\AppData\Local\Programs\Python\Python311\Lib\site-packages\pydantic\main.py", line 764, in __getattr__
    return super().__getattribute__(item)  # Raises AttributeError if appropriate
           ^^^^^^^^^^^^^^^^^^^^^^^^^^^^^^
AttributeError: 'OuterLogin' object has no attribute '__pydantic_fields_set__'

2024-02-28 23:25:17 - anonbot.adapter.satori.adapter - DEBUG - WebSocket connected to ws://bot.kasumibot.cn:39306/v1/events
2024-02-28 23:25:18 - anonbot.adapter.satori.adapter - ERROR - Error while process data from WebSocket ws://bot.kasumibot.cn:39306/v1/events
Traceback (most recent call last):
  File "f:\VS Code File\anonbot\anonbot\adapter\satori\adapter.py", line 142, in ws
    if not self._authenticate(info, ws):
           ^^^^^^^^^^^^^^^^^^^^^^^^^^^^
  File "f:\VS Code File\anonbot\anonbot\adapter\satori\adapter.py", line 101, in _authenticate
    response = self.receive_payload(info, ws)
               ^^^^^^^^^^^^^^^^^^^^^^^^^^^^^^
  File "f:\VS Code File\anonbot\anonbot\adapter\satori\adapter.py", line 79, in receive_payload
    payload = TypeAdapter(PayloadType).validate_python(json.loads(ws.receive()))
              ^^^^^^^^^^^^^^^^^^^^^^^^^^^^^^^^^^^^^^^^^^^^^^^^^^^^^^^^^^^^^^^^^^
  File "C:\Users\qwert\AppData\Local\Programs\Python\Python311\Lib\site-packages\pydantic\type_adapter.py", line 256, in validate_python
    return self.validator.validate_python(__object, strict=strict, from_attributes=from_attributes, context=context)
           ^^^^^^^^^^^^^^^^^^^^^^^^^^^^^^^^^^^^^^^^^^^^^^^^^^^^^^^^^^^^^^^^^^^^^^^^^^^^^^^^^^^^^^^^^^^^^^^^^^^^^^^^^
  File "<string>", line 3, in __init__
  File "C:\Users\qwert\AppData\Local\Programs\Python\Python311\Lib\site-packages\pydantic\main.py", line 810, in __setattr__
    self.__pydantic_fields_set__.add(name)
    ^^^^^^^^^^^^^^^^^^^^^^^^^^^^
  File "C:\Users\qwert\AppData\Local\Programs\Python\Python311\Lib\site-packages\pydantic\main.py", line 764, in __getattr__
    return super().__getattribute__(item)  # Raises AttributeError if appropriate
           ^^^^^^^^^^^^^^^^^^^^^^^^^^^^^^
AttributeError: 'OuterLogin' object has no attribute '__pydantic_fields_set__'

2024-02-28 23:25:18 - anonbot.adapter.satori.adapter - DEBUG - WebSocket connected to ws://bot.kasumibot.cn:39306/v1/events
2024-02-28 23:25:18 - anonbot.adapter.satori.adapter - ERROR - Error while process data from WebSocket ws://bot.kasumibot.cn:39306/v1/events
Traceback (most recent call last):
  File "f:\VS Code File\anonbot\anonbot\adapter\satori\adapter.py", line 142, in ws
    if not self._authenticate(info, ws):
           ^^^^^^^^^^^^^^^^^^^^^^^^^^^^
  File "f:\VS Code File\anonbot\anonbot\adapter\satori\adapter.py", line 101, in _authenticate
    response = self.receive_payload(info, ws)
               ^^^^^^^^^^^^^^^^^^^^^^^^^^^^^^
  File "f:\VS Code File\anonbot\anonbot\adapter\satori\adapter.py", line 79, in receive_payload
    payload = TypeAdapter(PayloadType).validate_python(json.loads(ws.receive()))
              ^^^^^^^^^^^^^^^^^^^^^^^^^^^^^^^^^^^^^^^^^^^^^^^^^^^^^^^^^^^^^^^^^^
  File "C:\Users\qwert\AppData\Local\Programs\Python\Python311\Lib\site-packages\pydantic\type_adapter.py", line 256, in validate_python
    return self.validator.validate_python(__object, strict=strict, from_attributes=from_attributes, context=context)
           ^^^^^^^^^^^^^^^^^^^^^^^^^^^^^^^^^^^^^^^^^^^^^^^^^^^^^^^^^^^^^^^^^^^^^^^^^^^^^^^^^^^^^^^^^^^^^^^^^^^^^^^^^
  File "<string>", line 3, in __init__
  File "C:\Users\qwert\AppData\Local\Programs\Python\Python311\Lib\site-packages\pydantic\main.py", line 810, in __setattr__
    self.__pydantic_fields_set__.add(name)
    ^^^^^^^^^^^^^^^^^^^^^^^^^^^^
  File "C:\Users\qwert\AppData\Local\Programs\Python\Python311\Lib\site-packages\pydantic\main.py", line 764, in __getattr__
    return super().__getattribute__(item)  # Raises AttributeError if appropriate
           ^^^^^^^^^^^^^^^^^^^^^^^^^^^^^^
AttributeError: 'OuterLogin' object has no attribute '__pydantic_fields_set__'

2024-02-28 23:25:19 - anonbot.adapter.satori.adapter - DEBUG - WebSocket connected to ws://bot.kasumibot.cn:39306/v1/events
2024-02-28 23:25:19 - anonbot.adapter.satori.adapter - ERROR - Error while process data from WebSocket ws://bot.kasumibot.cn:39306/v1/events
Traceback (most recent call last):
  File "f:\VS Code File\anonbot\anonbot\adapter\satori\adapter.py", line 142, in ws
    if not self._authenticate(info, ws):
           ^^^^^^^^^^^^^^^^^^^^^^^^^^^^
  File "f:\VS Code File\anonbot\anonbot\adapter\satori\adapter.py", line 101, in _authenticate
    response = self.receive_payload(info, ws)
               ^^^^^^^^^^^^^^^^^^^^^^^^^^^^^^
  File "f:\VS Code File\anonbot\anonbot\adapter\satori\adapter.py", line 79, in receive_payload
    payload = TypeAdapter(PayloadType).validate_python(json.loads(ws.receive()))
              ^^^^^^^^^^^^^^^^^^^^^^^^^^^^^^^^^^^^^^^^^^^^^^^^^^^^^^^^^^^^^^^^^^
  File "C:\Users\qwert\AppData\Local\Programs\Python\Python311\Lib\site-packages\pydantic\type_adapter.py", line 256, in validate_python
    return self.validator.validate_python(__object, strict=strict, from_attributes=from_attributes, context=context)
           ^^^^^^^^^^^^^^^^^^^^^^^^^^^^^^^^^^^^^^^^^^^^^^^^^^^^^^^^^^^^^^^^^^^^^^^^^^^^^^^^^^^^^^^^^^^^^^^^^^^^^^^^^
  File "<string>", line 3, in __init__
  File "C:\Users\qwert\AppData\Local\Programs\Python\Python311\Lib\site-packages\pydantic\main.py", line 810, in __setattr__
    self.__pydantic_fields_set__.add(name)
    ^^^^^^^^^^^^^^^^^^^^^^^^^^^^
  File "C:\Users\qwert\AppData\Local\Programs\Python\Python311\Lib\site-packages\pydantic\main.py", line 764, in __getattr__
    return super().__getattribute__(item)  # Raises AttributeError if appropriate
           ^^^^^^^^^^^^^^^^^^^^^^^^^^^^^^
AttributeError: 'OuterLogin' object has no attribute '__pydantic_fields_set__'

2024-02-28 23:25:19 - anonbot.adapter.satori.adapter - DEBUG - WebSocket connected to ws://bot.kasumibot.cn:39306/v1/events
2024-02-28 23:25:19 - anonbot.adapter.satori.adapter - ERROR - Error while process data from WebSocket ws://bot.kasumibot.cn:39306/v1/events
Traceback (most recent call last):
  File "f:\VS Code File\anonbot\anonbot\adapter\satori\adapter.py", line 142, in ws
    if not self._authenticate(info, ws):
           ^^^^^^^^^^^^^^^^^^^^^^^^^^^^
  File "f:\VS Code File\anonbot\anonbot\adapter\satori\adapter.py", line 101, in _authenticate
    response = self.receive_payload(info, ws)
               ^^^^^^^^^^^^^^^^^^^^^^^^^^^^^^
  File "f:\VS Code File\anonbot\anonbot\adapter\satori\adapter.py", line 79, in receive_payload
    payload = TypeAdapter(PayloadType).validate_python(json.loads(ws.receive()))
              ^^^^^^^^^^^^^^^^^^^^^^^^^^^^^^^^^^^^^^^^^^^^^^^^^^^^^^^^^^^^^^^^^^
  File "C:\Users\qwert\AppData\Local\Programs\Python\Python311\Lib\site-packages\pydantic\type_adapter.py", line 256, in validate_python
    return self.validator.validate_python(__object, strict=strict, from_attributes=from_attributes, context=context)
           ^^^^^^^^^^^^^^^^^^^^^^^^^^^^^^^^^^^^^^^^^^^^^^^^^^^^^^^^^^^^^^^^^^^^^^^^^^^^^^^^^^^^^^^^^^^^^^^^^^^^^^^^^
  File "<string>", line 3, in __init__
  File "C:\Users\qwert\AppData\Local\Programs\Python\Python311\Lib\site-packages\pydantic\main.py", line 810, in __setattr__
    self.__pydantic_fields_set__.add(name)
    ^^^^^^^^^^^^^^^^^^^^^^^^^^^^
  File "C:\Users\qwert\AppData\Local\Programs\Python\Python311\Lib\site-packages\pydantic\main.py", line 764, in __getattr__
    return super().__getattribute__(item)  # Raises AttributeError if appropriate
           ^^^^^^^^^^^^^^^^^^^^^^^^^^^^^^
AttributeError: 'OuterLogin' object has no attribute '__pydantic_fields_set__'

2024-02-28 23:25:20 - anonbot.adapter.satori.adapter - DEBUG - WebSocket connected to ws://bot.kasumibot.cn:39306/v1/events
2024-02-28 23:25:20 - anonbot.adapter.satori.adapter - ERROR - Error while process data from WebSocket ws://bot.kasumibot.cn:39306/v1/events
Traceback (most recent call last):
  File "f:\VS Code File\anonbot\anonbot\adapter\satori\adapter.py", line 142, in ws
    if not self._authenticate(info, ws):
           ^^^^^^^^^^^^^^^^^^^^^^^^^^^^
  File "f:\VS Code File\anonbot\anonbot\adapter\satori\adapter.py", line 101, in _authenticate
    response = self.receive_payload(info, ws)
               ^^^^^^^^^^^^^^^^^^^^^^^^^^^^^^
  File "f:\VS Code File\anonbot\anonbot\adapter\satori\adapter.py", line 79, in receive_payload
    payload = TypeAdapter(PayloadType).validate_python(json.loads(ws.receive()))
              ^^^^^^^^^^^^^^^^^^^^^^^^^^^^^^^^^^^^^^^^^^^^^^^^^^^^^^^^^^^^^^^^^^
  File "C:\Users\qwert\AppData\Local\Programs\Python\Python311\Lib\site-packages\pydantic\type_adapter.py", line 256, in validate_python
    return self.validator.validate_python(__object, strict=strict, from_attributes=from_attributes, context=context)
           ^^^^^^^^^^^^^^^^^^^^^^^^^^^^^^^^^^^^^^^^^^^^^^^^^^^^^^^^^^^^^^^^^^^^^^^^^^^^^^^^^^^^^^^^^^^^^^^^^^^^^^^^^
  File "<string>", line 3, in __init__
  File "C:\Users\qwert\AppData\Local\Programs\Python\Python311\Lib\site-packages\pydantic\main.py", line 810, in __setattr__
    self.__pydantic_fields_set__.add(name)
    ^^^^^^^^^^^^^^^^^^^^^^^^^^^^
  File "C:\Users\qwert\AppData\Local\Programs\Python\Python311\Lib\site-packages\pydantic\main.py", line 764, in __getattr__
    return super().__getattribute__(item)  # Raises AttributeError if appropriate
           ^^^^^^^^^^^^^^^^^^^^^^^^^^^^^^
AttributeError: 'OuterLogin' object has no attribute '__pydantic_fields_set__'

2024-02-28 23:25:20 - anonbot.adapter.satori.adapter - DEBUG - WebSocket connected to ws://bot.kasumibot.cn:39306/v1/events
2024-02-28 23:25:21 - anonbot.adapter.satori.adapter - ERROR - Error while process data from WebSocket ws://bot.kasumibot.cn:39306/v1/events
Traceback (most recent call last):
  File "f:\VS Code File\anonbot\anonbot\adapter\satori\adapter.py", line 142, in ws
    if not self._authenticate(info, ws):
           ^^^^^^^^^^^^^^^^^^^^^^^^^^^^
  File "f:\VS Code File\anonbot\anonbot\adapter\satori\adapter.py", line 101, in _authenticate
    response = self.receive_payload(info, ws)
               ^^^^^^^^^^^^^^^^^^^^^^^^^^^^^^
  File "f:\VS Code File\anonbot\anonbot\adapter\satori\adapter.py", line 79, in receive_payload
    payload = TypeAdapter(PayloadType).validate_python(json.loads(ws.receive()))
              ^^^^^^^^^^^^^^^^^^^^^^^^^^^^^^^^^^^^^^^^^^^^^^^^^^^^^^^^^^^^^^^^^^
  File "C:\Users\qwert\AppData\Local\Programs\Python\Python311\Lib\site-packages\pydantic\type_adapter.py", line 256, in validate_python
    return self.validator.validate_python(__object, strict=strict, from_attributes=from_attributes, context=context)
           ^^^^^^^^^^^^^^^^^^^^^^^^^^^^^^^^^^^^^^^^^^^^^^^^^^^^^^^^^^^^^^^^^^^^^^^^^^^^^^^^^^^^^^^^^^^^^^^^^^^^^^^^^
  File "<string>", line 3, in __init__
  File "C:\Users\qwert\AppData\Local\Programs\Python\Python311\Lib\site-packages\pydantic\main.py", line 810, in __setattr__
    self.__pydantic_fields_set__.add(name)
    ^^^^^^^^^^^^^^^^^^^^^^^^^^^^
  File "C:\Users\qwert\AppData\Local\Programs\Python\Python311\Lib\site-packages\pydantic\main.py", line 764, in __getattr__
    return super().__getattribute__(item)  # Raises AttributeError if appropriate
           ^^^^^^^^^^^^^^^^^^^^^^^^^^^^^^
AttributeError: 'OuterLogin' object has no attribute '__pydantic_fields_set__'

2024-02-28 23:25:21 - anonbot.adapter.satori.adapter - DEBUG - WebSocket connected to ws://bot.kasumibot.cn:39306/v1/events
2024-02-28 23:25:21 - anonbot.adapter.satori.adapter - ERROR - Error while process data from WebSocket ws://bot.kasumibot.cn:39306/v1/events
Traceback (most recent call last):
  File "f:\VS Code File\anonbot\anonbot\adapter\satori\adapter.py", line 142, in ws
    if not self._authenticate(info, ws):
           ^^^^^^^^^^^^^^^^^^^^^^^^^^^^
  File "f:\VS Code File\anonbot\anonbot\adapter\satori\adapter.py", line 101, in _authenticate
    response = self.receive_payload(info, ws)
               ^^^^^^^^^^^^^^^^^^^^^^^^^^^^^^
  File "f:\VS Code File\anonbot\anonbot\adapter\satori\adapter.py", line 79, in receive_payload
    payload = TypeAdapter(PayloadType).validate_python(json.loads(ws.receive()))
              ^^^^^^^^^^^^^^^^^^^^^^^^^^^^^^^^^^^^^^^^^^^^^^^^^^^^^^^^^^^^^^^^^^
  File "C:\Users\qwert\AppData\Local\Programs\Python\Python311\Lib\site-packages\pydantic\type_adapter.py", line 256, in validate_python
    return self.validator.validate_python(__object, strict=strict, from_attributes=from_attributes, context=context)
           ^^^^^^^^^^^^^^^^^^^^^^^^^^^^^^^^^^^^^^^^^^^^^^^^^^^^^^^^^^^^^^^^^^^^^^^^^^^^^^^^^^^^^^^^^^^^^^^^^^^^^^^^^
  File "<string>", line 3, in __init__
  File "C:\Users\qwert\AppData\Local\Programs\Python\Python311\Lib\site-packages\pydantic\main.py", line 810, in __setattr__
    self.__pydantic_fields_set__.add(name)
    ^^^^^^^^^^^^^^^^^^^^^^^^^^^^
  File "C:\Users\qwert\AppData\Local\Programs\Python\Python311\Lib\site-packages\pydantic\main.py", line 764, in __getattr__
    return super().__getattribute__(item)  # Raises AttributeError if appropriate
           ^^^^^^^^^^^^^^^^^^^^^^^^^^^^^^
AttributeError: 'OuterLogin' object has no attribute '__pydantic_fields_set__'

2024-02-28 23:25:21 - anonbot.adapter.satori.adapter - DEBUG - WebSocket connected to ws://bot.kasumibot.cn:39306/v1/events
2024-02-28 23:25:21 - anonbot.adapter.satori.adapter - ERROR - Error while process data from WebSocket ws://bot.kasumibot.cn:39306/v1/events
Traceback (most recent call last):
  File "f:\VS Code File\anonbot\anonbot\adapter\satori\adapter.py", line 142, in ws
    if not self._authenticate(info, ws):
           ^^^^^^^^^^^^^^^^^^^^^^^^^^^^
  File "f:\VS Code File\anonbot\anonbot\adapter\satori\adapter.py", line 101, in _authenticate
    response = self.receive_payload(info, ws)
               ^^^^^^^^^^^^^^^^^^^^^^^^^^^^^^
  File "f:\VS Code File\anonbot\anonbot\adapter\satori\adapter.py", line 79, in receive_payload
    payload = TypeAdapter(PayloadType).validate_python(json.loads(ws.receive()))
              ^^^^^^^^^^^^^^^^^^^^^^^^^^^^^^^^^^^^^^^^^^^^^^^^^^^^^^^^^^^^^^^^^^
  File "C:\Users\qwert\AppData\Local\Programs\Python\Python311\Lib\site-packages\pydantic\type_adapter.py", line 256, in validate_python
    return self.validator.validate_python(__object, strict=strict, from_attributes=from_attributes, context=context)
           ^^^^^^^^^^^^^^^^^^^^^^^^^^^^^^^^^^^^^^^^^^^^^^^^^^^^^^^^^^^^^^^^^^^^^^^^^^^^^^^^^^^^^^^^^^^^^^^^^^^^^^^^^
  File "<string>", line 3, in __init__
  File "C:\Users\qwert\AppData\Local\Programs\Python\Python311\Lib\site-packages\pydantic\main.py", line 810, in __setattr__
    self.__pydantic_fields_set__.add(name)
    ^^^^^^^^^^^^^^^^^^^^^^^^^^^^
  File "C:\Users\qwert\AppData\Local\Programs\Python\Python311\Lib\site-packages\pydantic\main.py", line 764, in __getattr__
    return super().__getattribute__(item)  # Raises AttributeError if appropriate
           ^^^^^^^^^^^^^^^^^^^^^^^^^^^^^^
AttributeError: 'OuterLogin' object has no attribute '__pydantic_fields_set__'

2024-02-28 23:25:22 - anonbot.adapter.satori.adapter - DEBUG - WebSocket connected to ws://bot.kasumibot.cn:39306/v1/events
2024-02-28 23:25:22 - anonbot.adapter.satori.adapter - ERROR - Error while process data from WebSocket ws://bot.kasumibot.cn:39306/v1/events
Traceback (most recent call last):
  File "f:\VS Code File\anonbot\anonbot\adapter\satori\adapter.py", line 142, in ws
    if not self._authenticate(info, ws):
           ^^^^^^^^^^^^^^^^^^^^^^^^^^^^
  File "f:\VS Code File\anonbot\anonbot\adapter\satori\adapter.py", line 101, in _authenticate
    response = self.receive_payload(info, ws)
               ^^^^^^^^^^^^^^^^^^^^^^^^^^^^^^
  File "f:\VS Code File\anonbot\anonbot\adapter\satori\adapter.py", line 79, in receive_payload
    payload = TypeAdapter(PayloadType).validate_python(json.loads(ws.receive()))
              ^^^^^^^^^^^^^^^^^^^^^^^^^^^^^^^^^^^^^^^^^^^^^^^^^^^^^^^^^^^^^^^^^^
  File "C:\Users\qwert\AppData\Local\Programs\Python\Python311\Lib\site-packages\pydantic\type_adapter.py", line 256, in validate_python
    return self.validator.validate_python(__object, strict=strict, from_attributes=from_attributes, context=context)
           ^^^^^^^^^^^^^^^^^^^^^^^^^^^^^^^^^^^^^^^^^^^^^^^^^^^^^^^^^^^^^^^^^^^^^^^^^^^^^^^^^^^^^^^^^^^^^^^^^^^^^^^^^
  File "<string>", line 3, in __init__
  File "C:\Users\qwert\AppData\Local\Programs\Python\Python311\Lib\site-packages\pydantic\main.py", line 810, in __setattr__
    self.__pydantic_fields_set__.add(name)
    ^^^^^^^^^^^^^^^^^^^^^^^^^^^^
  File "C:\Users\qwert\AppData\Local\Programs\Python\Python311\Lib\site-packages\pydantic\main.py", line 764, in __getattr__
    return super().__getattribute__(item)  # Raises AttributeError if appropriate
           ^^^^^^^^^^^^^^^^^^^^^^^^^^^^^^
AttributeError: 'OuterLogin' object has no attribute '__pydantic_fields_set__'

2024-02-28 23:25:22 - anonbot.adapter.satori.adapter - DEBUG - WebSocket connected to ws://bot.kasumibot.cn:39306/v1/events
2024-02-28 23:25:23 - anonbot.adapter.satori.adapter - ERROR - Error while process data from WebSocket ws://bot.kasumibot.cn:39306/v1/events
Traceback (most recent call last):
  File "f:\VS Code File\anonbot\anonbot\adapter\satori\adapter.py", line 142, in ws
    if not self._authenticate(info, ws):
           ^^^^^^^^^^^^^^^^^^^^^^^^^^^^
  File "f:\VS Code File\anonbot\anonbot\adapter\satori\adapter.py", line 101, in _authenticate
    response = self.receive_payload(info, ws)
               ^^^^^^^^^^^^^^^^^^^^^^^^^^^^^^
  File "f:\VS Code File\anonbot\anonbot\adapter\satori\adapter.py", line 79, in receive_payload
    payload = TypeAdapter(PayloadType).validate_python(json.loads(ws.receive()))
              ^^^^^^^^^^^^^^^^^^^^^^^^^^^^^^^^^^^^^^^^^^^^^^^^^^^^^^^^^^^^^^^^^^
  File "C:\Users\qwert\AppData\Local\Programs\Python\Python311\Lib\site-packages\pydantic\type_adapter.py", line 256, in validate_python
    return self.validator.validate_python(__object, strict=strict, from_attributes=from_attributes, context=context)
           ^^^^^^^^^^^^^^^^^^^^^^^^^^^^^^^^^^^^^^^^^^^^^^^^^^^^^^^^^^^^^^^^^^^^^^^^^^^^^^^^^^^^^^^^^^^^^^^^^^^^^^^^^
  File "<string>", line 3, in __init__
  File "C:\Users\qwert\AppData\Local\Programs\Python\Python311\Lib\site-packages\pydantic\main.py", line 810, in __setattr__
    self.__pydantic_fields_set__.add(name)
    ^^^^^^^^^^^^^^^^^^^^^^^^^^^^
  File "C:\Users\qwert\AppData\Local\Programs\Python\Python311\Lib\site-packages\pydantic\main.py", line 764, in __getattr__
    return super().__getattribute__(item)  # Raises AttributeError if appropriate
           ^^^^^^^^^^^^^^^^^^^^^^^^^^^^^^
AttributeError: 'OuterLogin' object has no attribute '__pydantic_fields_set__'

2024-02-28 23:25:23 - anonbot.adapter.satori.adapter - DEBUG - WebSocket connected to ws://bot.kasumibot.cn:39306/v1/events
2024-02-28 23:25:23 - anonbot.adapter.satori.adapter - ERROR - Error while process data from WebSocket ws://bot.kasumibot.cn:39306/v1/events
Traceback (most recent call last):
  File "f:\VS Code File\anonbot\anonbot\adapter\satori\adapter.py", line 142, in ws
    if not self._authenticate(info, ws):
           ^^^^^^^^^^^^^^^^^^^^^^^^^^^^
  File "f:\VS Code File\anonbot\anonbot\adapter\satori\adapter.py", line 101, in _authenticate
    response = self.receive_payload(info, ws)
               ^^^^^^^^^^^^^^^^^^^^^^^^^^^^^^
  File "f:\VS Code File\anonbot\anonbot\adapter\satori\adapter.py", line 79, in receive_payload
    payload = TypeAdapter(PayloadType).validate_python(json.loads(ws.receive()))
              ^^^^^^^^^^^^^^^^^^^^^^^^^^^^^^^^^^^^^^^^^^^^^^^^^^^^^^^^^^^^^^^^^^
  File "C:\Users\qwert\AppData\Local\Programs\Python\Python311\Lib\site-packages\pydantic\type_adapter.py", line 256, in validate_python
    return self.validator.validate_python(__object, strict=strict, from_attributes=from_attributes, context=context)
           ^^^^^^^^^^^^^^^^^^^^^^^^^^^^^^^^^^^^^^^^^^^^^^^^^^^^^^^^^^^^^^^^^^^^^^^^^^^^^^^^^^^^^^^^^^^^^^^^^^^^^^^^^
  File "<string>", line 3, in __init__
  File "C:\Users\qwert\AppData\Local\Programs\Python\Python311\Lib\site-packages\pydantic\main.py", line 810, in __setattr__
    self.__pydantic_fields_set__.add(name)
    ^^^^^^^^^^^^^^^^^^^^^^^^^^^^
  File "C:\Users\qwert\AppData\Local\Programs\Python\Python311\Lib\site-packages\pydantic\main.py", line 764, in __getattr__
    return super().__getattribute__(item)  # Raises AttributeError if appropriate
           ^^^^^^^^^^^^^^^^^^^^^^^^^^^^^^
AttributeError: 'OuterLogin' object has no attribute '__pydantic_fields_set__'

2024-02-28 23:25:24 - anonbot.adapter.satori.adapter - DEBUG - WebSocket connected to ws://bot.kasumibot.cn:39306/v1/events
2024-02-28 23:25:24 - anonbot.adapter.satori.adapter - ERROR - Error while process data from WebSocket ws://bot.kasumibot.cn:39306/v1/events
Traceback (most recent call last):
  File "f:\VS Code File\anonbot\anonbot\adapter\satori\adapter.py", line 142, in ws
    if not self._authenticate(info, ws):
           ^^^^^^^^^^^^^^^^^^^^^^^^^^^^
  File "f:\VS Code File\anonbot\anonbot\adapter\satori\adapter.py", line 101, in _authenticate
    response = self.receive_payload(info, ws)
               ^^^^^^^^^^^^^^^^^^^^^^^^^^^^^^
  File "f:\VS Code File\anonbot\anonbot\adapter\satori\adapter.py", line 79, in receive_payload
    payload = TypeAdapter(PayloadType).validate_python(json.loads(ws.receive()))
              ^^^^^^^^^^^^^^^^^^^^^^^^^^^^^^^^^^^^^^^^^^^^^^^^^^^^^^^^^^^^^^^^^^
  File "C:\Users\qwert\AppData\Local\Programs\Python\Python311\Lib\site-packages\pydantic\type_adapter.py", line 256, in validate_python
    return self.validator.validate_python(__object, strict=strict, from_attributes=from_attributes, context=context)
           ^^^^^^^^^^^^^^^^^^^^^^^^^^^^^^^^^^^^^^^^^^^^^^^^^^^^^^^^^^^^^^^^^^^^^^^^^^^^^^^^^^^^^^^^^^^^^^^^^^^^^^^^^
  File "<string>", line 3, in __init__
  File "C:\Users\qwert\AppData\Local\Programs\Python\Python311\Lib\site-packages\pydantic\main.py", line 810, in __setattr__
    self.__pydantic_fields_set__.add(name)
    ^^^^^^^^^^^^^^^^^^^^^^^^^^^^
  File "C:\Users\qwert\AppData\Local\Programs\Python\Python311\Lib\site-packages\pydantic\main.py", line 764, in __getattr__
    return super().__getattribute__(item)  # Raises AttributeError if appropriate
           ^^^^^^^^^^^^^^^^^^^^^^^^^^^^^^
AttributeError: 'OuterLogin' object has no attribute '__pydantic_fields_set__'

2024-02-28 23:25:24 - anonbot.adapter.satori.adapter - DEBUG - WebSocket connected to ws://bot.kasumibot.cn:39306/v1/events
2024-02-28 23:25:24 - anonbot.adapter.satori.adapter - ERROR - Error while process data from WebSocket ws://bot.kasumibot.cn:39306/v1/events
Traceback (most recent call last):
  File "f:\VS Code File\anonbot\anonbot\adapter\satori\adapter.py", line 142, in ws
    if not self._authenticate(info, ws):
           ^^^^^^^^^^^^^^^^^^^^^^^^^^^^
  File "f:\VS Code File\anonbot\anonbot\adapter\satori\adapter.py", line 101, in _authenticate
    response = self.receive_payload(info, ws)
               ^^^^^^^^^^^^^^^^^^^^^^^^^^^^^^
  File "f:\VS Code File\anonbot\anonbot\adapter\satori\adapter.py", line 79, in receive_payload
    payload = TypeAdapter(PayloadType).validate_python(json.loads(ws.receive()))
              ^^^^^^^^^^^^^^^^^^^^^^^^^^^^^^^^^^^^^^^^^^^^^^^^^^^^^^^^^^^^^^^^^^
  File "C:\Users\qwert\AppData\Local\Programs\Python\Python311\Lib\site-packages\pydantic\type_adapter.py", line 256, in validate_python
    return self.validator.validate_python(__object, strict=strict, from_attributes=from_attributes, context=context)
           ^^^^^^^^^^^^^^^^^^^^^^^^^^^^^^^^^^^^^^^^^^^^^^^^^^^^^^^^^^^^^^^^^^^^^^^^^^^^^^^^^^^^^^^^^^^^^^^^^^^^^^^^^
  File "<string>", line 3, in __init__
  File "C:\Users\qwert\AppData\Local\Programs\Python\Python311\Lib\site-packages\pydantic\main.py", line 810, in __setattr__
    self.__pydantic_fields_set__.add(name)
    ^^^^^^^^^^^^^^^^^^^^^^^^^^^^
  File "C:\Users\qwert\AppData\Local\Programs\Python\Python311\Lib\site-packages\pydantic\main.py", line 764, in __getattr__
    return super().__getattribute__(item)  # Raises AttributeError if appropriate
           ^^^^^^^^^^^^^^^^^^^^^^^^^^^^^^
AttributeError: 'OuterLogin' object has no attribute '__pydantic_fields_set__'

2024-02-28 23:25:25 - anonbot.adapter.satori.adapter - DEBUG - WebSocket connected to ws://bot.kasumibot.cn:39306/v1/events
2024-02-28 23:25:25 - anonbot.adapter.satori.adapter - ERROR - Error while process data from WebSocket ws://bot.kasumibot.cn:39306/v1/events
Traceback (most recent call last):
  File "f:\VS Code File\anonbot\anonbot\adapter\satori\adapter.py", line 142, in ws
    if not self._authenticate(info, ws):
           ^^^^^^^^^^^^^^^^^^^^^^^^^^^^
  File "f:\VS Code File\anonbot\anonbot\adapter\satori\adapter.py", line 101, in _authenticate
    response = self.receive_payload(info, ws)
               ^^^^^^^^^^^^^^^^^^^^^^^^^^^^^^
  File "f:\VS Code File\anonbot\anonbot\adapter\satori\adapter.py", line 79, in receive_payload
    payload = TypeAdapter(PayloadType).validate_python(json.loads(ws.receive()))
              ^^^^^^^^^^^^^^^^^^^^^^^^^^^^^^^^^^^^^^^^^^^^^^^^^^^^^^^^^^^^^^^^^^
  File "C:\Users\qwert\AppData\Local\Programs\Python\Python311\Lib\site-packages\pydantic\type_adapter.py", line 256, in validate_python
    return self.validator.validate_python(__object, strict=strict, from_attributes=from_attributes, context=context)
           ^^^^^^^^^^^^^^^^^^^^^^^^^^^^^^^^^^^^^^^^^^^^^^^^^^^^^^^^^^^^^^^^^^^^^^^^^^^^^^^^^^^^^^^^^^^^^^^^^^^^^^^^^
  File "<string>", line 3, in __init__
  File "C:\Users\qwert\AppData\Local\Programs\Python\Python311\Lib\site-packages\pydantic\main.py", line 810, in __setattr__
    self.__pydantic_fields_set__.add(name)
    ^^^^^^^^^^^^^^^^^^^^^^^^^^^^
  File "C:\Users\qwert\AppData\Local\Programs\Python\Python311\Lib\site-packages\pydantic\main.py", line 764, in __getattr__
    return super().__getattribute__(item)  # Raises AttributeError if appropriate
           ^^^^^^^^^^^^^^^^^^^^^^^^^^^^^^
AttributeError: 'OuterLogin' object has no attribute '__pydantic_fields_set__'

2024-02-28 23:25:25 - anonbot.adapter.satori.adapter - DEBUG - WebSocket connected to ws://bot.kasumibot.cn:39306/v1/events
2024-02-28 23:25:25 - anonbot.adapter.satori.adapter - ERROR - Error while process data from WebSocket ws://bot.kasumibot.cn:39306/v1/events
Traceback (most recent call last):
  File "f:\VS Code File\anonbot\anonbot\adapter\satori\adapter.py", line 142, in ws
    if not self._authenticate(info, ws):
           ^^^^^^^^^^^^^^^^^^^^^^^^^^^^
  File "f:\VS Code File\anonbot\anonbot\adapter\satori\adapter.py", line 101, in _authenticate
    response = self.receive_payload(info, ws)
               ^^^^^^^^^^^^^^^^^^^^^^^^^^^^^^
  File "f:\VS Code File\anonbot\anonbot\adapter\satori\adapter.py", line 79, in receive_payload
    payload = TypeAdapter(PayloadType).validate_python(json.loads(ws.receive()))
              ^^^^^^^^^^^^^^^^^^^^^^^^^^^^^^^^^^^^^^^^^^^^^^^^^^^^^^^^^^^^^^^^^^
  File "C:\Users\qwert\AppData\Local\Programs\Python\Python311\Lib\site-packages\pydantic\type_adapter.py", line 256, in validate_python
    return self.validator.validate_python(__object, strict=strict, from_attributes=from_attributes, context=context)
           ^^^^^^^^^^^^^^^^^^^^^^^^^^^^^^^^^^^^^^^^^^^^^^^^^^^^^^^^^^^^^^^^^^^^^^^^^^^^^^^^^^^^^^^^^^^^^^^^^^^^^^^^^
  File "<string>", line 3, in __init__
  File "C:\Users\qwert\AppData\Local\Programs\Python\Python311\Lib\site-packages\pydantic\main.py", line 810, in __setattr__
    self.__pydantic_fields_set__.add(name)
    ^^^^^^^^^^^^^^^^^^^^^^^^^^^^
  File "C:\Users\qwert\AppData\Local\Programs\Python\Python311\Lib\site-packages\pydantic\main.py", line 764, in __getattr__
    return super().__getattribute__(item)  # Raises AttributeError if appropriate
           ^^^^^^^^^^^^^^^^^^^^^^^^^^^^^^
AttributeError: 'OuterLogin' object has no attribute '__pydantic_fields_set__'

2024-02-28 23:25:26 - anonbot.adapter.satori.adapter - DEBUG - WebSocket connected to ws://bot.kasumibot.cn:39306/v1/events
2024-02-28 23:25:26 - anonbot.adapter.satori.adapter - ERROR - Error while process data from WebSocket ws://bot.kasumibot.cn:39306/v1/events
Traceback (most recent call last):
  File "f:\VS Code File\anonbot\anonbot\adapter\satori\adapter.py", line 142, in ws
    if not self._authenticate(info, ws):
           ^^^^^^^^^^^^^^^^^^^^^^^^^^^^
  File "f:\VS Code File\anonbot\anonbot\adapter\satori\adapter.py", line 101, in _authenticate
    response = self.receive_payload(info, ws)
               ^^^^^^^^^^^^^^^^^^^^^^^^^^^^^^
  File "f:\VS Code File\anonbot\anonbot\adapter\satori\adapter.py", line 79, in receive_payload
    payload = TypeAdapter(PayloadType).validate_python(json.loads(ws.receive()))
              ^^^^^^^^^^^^^^^^^^^^^^^^^^^^^^^^^^^^^^^^^^^^^^^^^^^^^^^^^^^^^^^^^^
  File "C:\Users\qwert\AppData\Local\Programs\Python\Python311\Lib\site-packages\pydantic\type_adapter.py", line 256, in validate_python
    return self.validator.validate_python(__object, strict=strict, from_attributes=from_attributes, context=context)
           ^^^^^^^^^^^^^^^^^^^^^^^^^^^^^^^^^^^^^^^^^^^^^^^^^^^^^^^^^^^^^^^^^^^^^^^^^^^^^^^^^^^^^^^^^^^^^^^^^^^^^^^^^
  File "<string>", line 3, in __init__
  File "C:\Users\qwert\AppData\Local\Programs\Python\Python311\Lib\site-packages\pydantic\main.py", line 810, in __setattr__
    self.__pydantic_fields_set__.add(name)
    ^^^^^^^^^^^^^^^^^^^^^^^^^^^^
  File "C:\Users\qwert\AppData\Local\Programs\Python\Python311\Lib\site-packages\pydantic\main.py", line 764, in __getattr__
    return super().__getattribute__(item)  # Raises AttributeError if appropriate
           ^^^^^^^^^^^^^^^^^^^^^^^^^^^^^^
AttributeError: 'OuterLogin' object has no attribute '__pydantic_fields_set__'

2024-02-28 23:25:26 - anonbot.adapter.satori.adapter - DEBUG - WebSocket connected to ws://bot.kasumibot.cn:39306/v1/events
2024-02-28 23:25:26 - anonbot.adapter.satori.adapter - ERROR - Error while process data from WebSocket ws://bot.kasumibot.cn:39306/v1/events
Traceback (most recent call last):
  File "f:\VS Code File\anonbot\anonbot\adapter\satori\adapter.py", line 142, in ws
    if not self._authenticate(info, ws):
           ^^^^^^^^^^^^^^^^^^^^^^^^^^^^
  File "f:\VS Code File\anonbot\anonbot\adapter\satori\adapter.py", line 101, in _authenticate
    response = self.receive_payload(info, ws)
               ^^^^^^^^^^^^^^^^^^^^^^^^^^^^^^
  File "f:\VS Code File\anonbot\anonbot\adapter\satori\adapter.py", line 79, in receive_payload
    payload = TypeAdapter(PayloadType).validate_python(json.loads(ws.receive()))
              ^^^^^^^^^^^^^^^^^^^^^^^^^^^^^^^^^^^^^^^^^^^^^^^^^^^^^^^^^^^^^^^^^^
  File "C:\Users\qwert\AppData\Local\Programs\Python\Python311\Lib\site-packages\pydantic\type_adapter.py", line 256, in validate_python
    return self.validator.validate_python(__object, strict=strict, from_attributes=from_attributes, context=context)
           ^^^^^^^^^^^^^^^^^^^^^^^^^^^^^^^^^^^^^^^^^^^^^^^^^^^^^^^^^^^^^^^^^^^^^^^^^^^^^^^^^^^^^^^^^^^^^^^^^^^^^^^^^
  File "<string>", line 3, in __init__
  File "C:\Users\qwert\AppData\Local\Programs\Python\Python311\Lib\site-packages\pydantic\main.py", line 810, in __setattr__
    self.__pydantic_fields_set__.add(name)
    ^^^^^^^^^^^^^^^^^^^^^^^^^^^^
  File "C:\Users\qwert\AppData\Local\Programs\Python\Python311\Lib\site-packages\pydantic\main.py", line 764, in __getattr__
    return super().__getattribute__(item)  # Raises AttributeError if appropriate
           ^^^^^^^^^^^^^^^^^^^^^^^^^^^^^^
AttributeError: 'OuterLogin' object has no attribute '__pydantic_fields_set__'

2024-02-28 23:25:27 - anonbot.adapter.satori.adapter - DEBUG - WebSocket connected to ws://bot.kasumibot.cn:39306/v1/events
2024-02-28 23:25:27 - anonbot.adapter.satori.adapter - ERROR - Error while process data from WebSocket ws://bot.kasumibot.cn:39306/v1/events
Traceback (most recent call last):
  File "f:\VS Code File\anonbot\anonbot\adapter\satori\adapter.py", line 142, in ws
    if not self._authenticate(info, ws):
           ^^^^^^^^^^^^^^^^^^^^^^^^^^^^
  File "f:\VS Code File\anonbot\anonbot\adapter\satori\adapter.py", line 101, in _authenticate
    response = self.receive_payload(info, ws)
               ^^^^^^^^^^^^^^^^^^^^^^^^^^^^^^
  File "f:\VS Code File\anonbot\anonbot\adapter\satori\adapter.py", line 79, in receive_payload
    payload = TypeAdapter(PayloadType).validate_python(json.loads(ws.receive()))
              ^^^^^^^^^^^^^^^^^^^^^^^^^^^^^^^^^^^^^^^^^^^^^^^^^^^^^^^^^^^^^^^^^^
  File "C:\Users\qwert\AppData\Local\Programs\Python\Python311\Lib\site-packages\pydantic\type_adapter.py", line 256, in validate_python
    return self.validator.validate_python(__object, strict=strict, from_attributes=from_attributes, context=context)
           ^^^^^^^^^^^^^^^^^^^^^^^^^^^^^^^^^^^^^^^^^^^^^^^^^^^^^^^^^^^^^^^^^^^^^^^^^^^^^^^^^^^^^^^^^^^^^^^^^^^^^^^^^
  File "<string>", line 3, in __init__
  File "C:\Users\qwert\AppData\Local\Programs\Python\Python311\Lib\site-packages\pydantic\main.py", line 810, in __setattr__
    self.__pydantic_fields_set__.add(name)
    ^^^^^^^^^^^^^^^^^^^^^^^^^^^^
  File "C:\Users\qwert\AppData\Local\Programs\Python\Python311\Lib\site-packages\pydantic\main.py", line 764, in __getattr__
    return super().__getattribute__(item)  # Raises AttributeError if appropriate
           ^^^^^^^^^^^^^^^^^^^^^^^^^^^^^^
AttributeError: 'OuterLogin' object has no attribute '__pydantic_fields_set__'

2024-02-28 23:25:27 - anonbot.adapter.satori.adapter - DEBUG - WebSocket connected to ws://bot.kasumibot.cn:39306/v1/events
2024-02-28 23:25:28 - anonbot.adapter.satori.adapter - ERROR - Error while process data from WebSocket ws://bot.kasumibot.cn:39306/v1/events
Traceback (most recent call last):
  File "f:\VS Code File\anonbot\anonbot\adapter\satori\adapter.py", line 142, in ws
    if not self._authenticate(info, ws):
           ^^^^^^^^^^^^^^^^^^^^^^^^^^^^
  File "f:\VS Code File\anonbot\anonbot\adapter\satori\adapter.py", line 101, in _authenticate
    response = self.receive_payload(info, ws)
               ^^^^^^^^^^^^^^^^^^^^^^^^^^^^^^
  File "f:\VS Code File\anonbot\anonbot\adapter\satori\adapter.py", line 79, in receive_payload
    payload = TypeAdapter(PayloadType).validate_python(json.loads(ws.receive()))
              ^^^^^^^^^^^^^^^^^^^^^^^^^^^^^^^^^^^^^^^^^^^^^^^^^^^^^^^^^^^^^^^^^^
  File "C:\Users\qwert\AppData\Local\Programs\Python\Python311\Lib\site-packages\pydantic\type_adapter.py", line 256, in validate_python
    return self.validator.validate_python(__object, strict=strict, from_attributes=from_attributes, context=context)
           ^^^^^^^^^^^^^^^^^^^^^^^^^^^^^^^^^^^^^^^^^^^^^^^^^^^^^^^^^^^^^^^^^^^^^^^^^^^^^^^^^^^^^^^^^^^^^^^^^^^^^^^^^
  File "<string>", line 3, in __init__
  File "C:\Users\qwert\AppData\Local\Programs\Python\Python311\Lib\site-packages\pydantic\main.py", line 810, in __setattr__
    self.__pydantic_fields_set__.add(name)
    ^^^^^^^^^^^^^^^^^^^^^^^^^^^^
  File "C:\Users\qwert\AppData\Local\Programs\Python\Python311\Lib\site-packages\pydantic\main.py", line 764, in __getattr__
    return super().__getattribute__(item)  # Raises AttributeError if appropriate
           ^^^^^^^^^^^^^^^^^^^^^^^^^^^^^^
AttributeError: 'OuterLogin' object has no attribute '__pydantic_fields_set__'

2024-02-28 23:25:28 - anonbot.adapter.satori.adapter - DEBUG - WebSocket connected to ws://bot.kasumibot.cn:39306/v1/events
2024-02-28 23:25:28 - anonbot.adapter.satori.adapter - ERROR - Error while process data from WebSocket ws://bot.kasumibot.cn:39306/v1/events
Traceback (most recent call last):
  File "f:\VS Code File\anonbot\anonbot\adapter\satori\adapter.py", line 142, in ws
    if not self._authenticate(info, ws):
           ^^^^^^^^^^^^^^^^^^^^^^^^^^^^
  File "f:\VS Code File\anonbot\anonbot\adapter\satori\adapter.py", line 101, in _authenticate
    response = self.receive_payload(info, ws)
               ^^^^^^^^^^^^^^^^^^^^^^^^^^^^^^
  File "f:\VS Code File\anonbot\anonbot\adapter\satori\adapter.py", line 79, in receive_payload
    payload = TypeAdapter(PayloadType).validate_python(json.loads(ws.receive()))
              ^^^^^^^^^^^^^^^^^^^^^^^^^^^^^^^^^^^^^^^^^^^^^^^^^^^^^^^^^^^^^^^^^^
  File "C:\Users\qwert\AppData\Local\Programs\Python\Python311\Lib\site-packages\pydantic\type_adapter.py", line 256, in validate_python
    return self.validator.validate_python(__object, strict=strict, from_attributes=from_attributes, context=context)
           ^^^^^^^^^^^^^^^^^^^^^^^^^^^^^^^^^^^^^^^^^^^^^^^^^^^^^^^^^^^^^^^^^^^^^^^^^^^^^^^^^^^^^^^^^^^^^^^^^^^^^^^^^
  File "<string>", line 3, in __init__
  File "C:\Users\qwert\AppData\Local\Programs\Python\Python311\Lib\site-packages\pydantic\main.py", line 810, in __setattr__
    self.__pydantic_fields_set__.add(name)
    ^^^^^^^^^^^^^^^^^^^^^^^^^^^^
  File "C:\Users\qwert\AppData\Local\Programs\Python\Python311\Lib\site-packages\pydantic\main.py", line 764, in __getattr__
    return super().__getattribute__(item)  # Raises AttributeError if appropriate
           ^^^^^^^^^^^^^^^^^^^^^^^^^^^^^^
AttributeError: 'OuterLogin' object has no attribute '__pydantic_fields_set__'

2024-02-28 23:25:29 - anonbot.adapter.satori.adapter - DEBUG - WebSocket connected to ws://bot.kasumibot.cn:39306/v1/events
2024-02-28 23:25:29 - anonbot.adapter.satori.adapter - ERROR - Error while process data from WebSocket ws://bot.kasumibot.cn:39306/v1/events
Traceback (most recent call last):
  File "f:\VS Code File\anonbot\anonbot\adapter\satori\adapter.py", line 142, in ws
    if not self._authenticate(info, ws):
           ^^^^^^^^^^^^^^^^^^^^^^^^^^^^
  File "f:\VS Code File\anonbot\anonbot\adapter\satori\adapter.py", line 101, in _authenticate
    response = self.receive_payload(info, ws)
               ^^^^^^^^^^^^^^^^^^^^^^^^^^^^^^
  File "f:\VS Code File\anonbot\anonbot\adapter\satori\adapter.py", line 79, in receive_payload
    payload = TypeAdapter(PayloadType).validate_python(json.loads(ws.receive()))
              ^^^^^^^^^^^^^^^^^^^^^^^^^^^^^^^^^^^^^^^^^^^^^^^^^^^^^^^^^^^^^^^^^^
  File "C:\Users\qwert\AppData\Local\Programs\Python\Python311\Lib\site-packages\pydantic\type_adapter.py", line 256, in validate_python
    return self.validator.validate_python(__object, strict=strict, from_attributes=from_attributes, context=context)
           ^^^^^^^^^^^^^^^^^^^^^^^^^^^^^^^^^^^^^^^^^^^^^^^^^^^^^^^^^^^^^^^^^^^^^^^^^^^^^^^^^^^^^^^^^^^^^^^^^^^^^^^^^
  File "<string>", line 3, in __init__
  File "C:\Users\qwert\AppData\Local\Programs\Python\Python311\Lib\site-packages\pydantic\main.py", line 810, in __setattr__
    self.__pydantic_fields_set__.add(name)
    ^^^^^^^^^^^^^^^^^^^^^^^^^^^^
  File "C:\Users\qwert\AppData\Local\Programs\Python\Python311\Lib\site-packages\pydantic\main.py", line 764, in __getattr__
    return super().__getattribute__(item)  # Raises AttributeError if appropriate
           ^^^^^^^^^^^^^^^^^^^^^^^^^^^^^^
AttributeError: 'OuterLogin' object has no attribute '__pydantic_fields_set__'

2024-02-28 23:25:29 - anonbot.adapter.satori.adapter - DEBUG - WebSocket connected to ws://bot.kasumibot.cn:39306/v1/events
2024-02-28 23:25:29 - anonbot.adapter.satori.adapter - ERROR - Error while process data from WebSocket ws://bot.kasumibot.cn:39306/v1/events
Traceback (most recent call last):
  File "f:\VS Code File\anonbot\anonbot\adapter\satori\adapter.py", line 142, in ws
    if not self._authenticate(info, ws):
           ^^^^^^^^^^^^^^^^^^^^^^^^^^^^
  File "f:\VS Code File\anonbot\anonbot\adapter\satori\adapter.py", line 101, in _authenticate
    response = self.receive_payload(info, ws)
               ^^^^^^^^^^^^^^^^^^^^^^^^^^^^^^
  File "f:\VS Code File\anonbot\anonbot\adapter\satori\adapter.py", line 79, in receive_payload
    payload = TypeAdapter(PayloadType).validate_python(json.loads(ws.receive()))
              ^^^^^^^^^^^^^^^^^^^^^^^^^^^^^^^^^^^^^^^^^^^^^^^^^^^^^^^^^^^^^^^^^^
  File "C:\Users\qwert\AppData\Local\Programs\Python\Python311\Lib\site-packages\pydantic\type_adapter.py", line 256, in validate_python
    return self.validator.validate_python(__object, strict=strict, from_attributes=from_attributes, context=context)
           ^^^^^^^^^^^^^^^^^^^^^^^^^^^^^^^^^^^^^^^^^^^^^^^^^^^^^^^^^^^^^^^^^^^^^^^^^^^^^^^^^^^^^^^^^^^^^^^^^^^^^^^^^
  File "<string>", line 3, in __init__
  File "C:\Users\qwert\AppData\Local\Programs\Python\Python311\Lib\site-packages\pydantic\main.py", line 810, in __setattr__
    self.__pydantic_fields_set__.add(name)
    ^^^^^^^^^^^^^^^^^^^^^^^^^^^^
  File "C:\Users\qwert\AppData\Local\Programs\Python\Python311\Lib\site-packages\pydantic\main.py", line 764, in __getattr__
    return super().__getattribute__(item)  # Raises AttributeError if appropriate
           ^^^^^^^^^^^^^^^^^^^^^^^^^^^^^^
AttributeError: 'OuterLogin' object has no attribute '__pydantic_fields_set__'

2024-02-28 23:25:30 - anonbot.adapter.satori.adapter - DEBUG - WebSocket connected to ws://bot.kasumibot.cn:39306/v1/events
2024-02-28 23:25:30 - anonbot.adapter.satori.adapter - ERROR - Error while process data from WebSocket ws://bot.kasumibot.cn:39306/v1/events
Traceback (most recent call last):
  File "f:\VS Code File\anonbot\anonbot\adapter\satori\adapter.py", line 142, in ws
    if not self._authenticate(info, ws):
           ^^^^^^^^^^^^^^^^^^^^^^^^^^^^
  File "f:\VS Code File\anonbot\anonbot\adapter\satori\adapter.py", line 101, in _authenticate
    response = self.receive_payload(info, ws)
               ^^^^^^^^^^^^^^^^^^^^^^^^^^^^^^
  File "f:\VS Code File\anonbot\anonbot\adapter\satori\adapter.py", line 79, in receive_payload
    payload = TypeAdapter(PayloadType).validate_python(json.loads(ws.receive()))
              ^^^^^^^^^^^^^^^^^^^^^^^^^^^^^^^^^^^^^^^^^^^^^^^^^^^^^^^^^^^^^^^^^^
  File "C:\Users\qwert\AppData\Local\Programs\Python\Python311\Lib\site-packages\pydantic\type_adapter.py", line 256, in validate_python
    return self.validator.validate_python(__object, strict=strict, from_attributes=from_attributes, context=context)
           ^^^^^^^^^^^^^^^^^^^^^^^^^^^^^^^^^^^^^^^^^^^^^^^^^^^^^^^^^^^^^^^^^^^^^^^^^^^^^^^^^^^^^^^^^^^^^^^^^^^^^^^^^
  File "<string>", line 3, in __init__
  File "C:\Users\qwert\AppData\Local\Programs\Python\Python311\Lib\site-packages\pydantic\main.py", line 810, in __setattr__
    self.__pydantic_fields_set__.add(name)
    ^^^^^^^^^^^^^^^^^^^^^^^^^^^^
  File "C:\Users\qwert\AppData\Local\Programs\Python\Python311\Lib\site-packages\pydantic\main.py", line 764, in __getattr__
    return super().__getattribute__(item)  # Raises AttributeError if appropriate
           ^^^^^^^^^^^^^^^^^^^^^^^^^^^^^^
AttributeError: 'OuterLogin' object has no attribute '__pydantic_fields_set__'

2024-02-28 23:25:30 - anonbot.adapter.satori.adapter - DEBUG - WebSocket connected to ws://bot.kasumibot.cn:39306/v1/events
2024-02-28 23:25:31 - anonbot.adapter.satori.adapter - ERROR - Error while process data from WebSocket ws://bot.kasumibot.cn:39306/v1/events
Traceback (most recent call last):
  File "f:\VS Code File\anonbot\anonbot\adapter\satori\adapter.py", line 142, in ws
    if not self._authenticate(info, ws):
           ^^^^^^^^^^^^^^^^^^^^^^^^^^^^
  File "f:\VS Code File\anonbot\anonbot\adapter\satori\adapter.py", line 101, in _authenticate
    response = self.receive_payload(info, ws)
               ^^^^^^^^^^^^^^^^^^^^^^^^^^^^^^
  File "f:\VS Code File\anonbot\anonbot\adapter\satori\adapter.py", line 79, in receive_payload
    payload = TypeAdapter(PayloadType).validate_python(json.loads(ws.receive()))
              ^^^^^^^^^^^^^^^^^^^^^^^^^^^^^^^^^^^^^^^^^^^^^^^^^^^^^^^^^^^^^^^^^^
  File "C:\Users\qwert\AppData\Local\Programs\Python\Python311\Lib\site-packages\pydantic\type_adapter.py", line 256, in validate_python
    return self.validator.validate_python(__object, strict=strict, from_attributes=from_attributes, context=context)
           ^^^^^^^^^^^^^^^^^^^^^^^^^^^^^^^^^^^^^^^^^^^^^^^^^^^^^^^^^^^^^^^^^^^^^^^^^^^^^^^^^^^^^^^^^^^^^^^^^^^^^^^^^
  File "<string>", line 3, in __init__
  File "C:\Users\qwert\AppData\Local\Programs\Python\Python311\Lib\site-packages\pydantic\main.py", line 810, in __setattr__
    self.__pydantic_fields_set__.add(name)
    ^^^^^^^^^^^^^^^^^^^^^^^^^^^^
  File "C:\Users\qwert\AppData\Local\Programs\Python\Python311\Lib\site-packages\pydantic\main.py", line 764, in __getattr__
    return super().__getattribute__(item)  # Raises AttributeError if appropriate
           ^^^^^^^^^^^^^^^^^^^^^^^^^^^^^^
AttributeError: 'OuterLogin' object has no attribute '__pydantic_fields_set__'

2024-02-28 23:25:31 - anonbot.adapter.satori.adapter - DEBUG - WebSocket connected to ws://bot.kasumibot.cn:39306/v1/events
2024-02-28 23:25:31 - anonbot.adapter.satori.adapter - ERROR - Error while process data from WebSocket ws://bot.kasumibot.cn:39306/v1/events
Traceback (most recent call last):
  File "f:\VS Code File\anonbot\anonbot\adapter\satori\adapter.py", line 142, in ws
    if not self._authenticate(info, ws):
           ^^^^^^^^^^^^^^^^^^^^^^^^^^^^
  File "f:\VS Code File\anonbot\anonbot\adapter\satori\adapter.py", line 101, in _authenticate
    response = self.receive_payload(info, ws)
               ^^^^^^^^^^^^^^^^^^^^^^^^^^^^^^
  File "f:\VS Code File\anonbot\anonbot\adapter\satori\adapter.py", line 79, in receive_payload
    payload = TypeAdapter(PayloadType).validate_python(json.loads(ws.receive()))
              ^^^^^^^^^^^^^^^^^^^^^^^^^^^^^^^^^^^^^^^^^^^^^^^^^^^^^^^^^^^^^^^^^^
  File "C:\Users\qwert\AppData\Local\Programs\Python\Python311\Lib\site-packages\pydantic\type_adapter.py", line 256, in validate_python
    return self.validator.validate_python(__object, strict=strict, from_attributes=from_attributes, context=context)
           ^^^^^^^^^^^^^^^^^^^^^^^^^^^^^^^^^^^^^^^^^^^^^^^^^^^^^^^^^^^^^^^^^^^^^^^^^^^^^^^^^^^^^^^^^^^^^^^^^^^^^^^^^
  File "<string>", line 3, in __init__
  File "C:\Users\qwert\AppData\Local\Programs\Python\Python311\Lib\site-packages\pydantic\main.py", line 810, in __setattr__
    self.__pydantic_fields_set__.add(name)
    ^^^^^^^^^^^^^^^^^^^^^^^^^^^^
  File "C:\Users\qwert\AppData\Local\Programs\Python\Python311\Lib\site-packages\pydantic\main.py", line 764, in __getattr__
    return super().__getattribute__(item)  # Raises AttributeError if appropriate
           ^^^^^^^^^^^^^^^^^^^^^^^^^^^^^^
AttributeError: 'OuterLogin' object has no attribute '__pydantic_fields_set__'

2024-02-28 23:25:32 - anonbot.adapter.satori.adapter - DEBUG - WebSocket connected to ws://bot.kasumibot.cn:39306/v1/events
2024-02-28 23:25:32 - anonbot.adapter.satori.adapter - ERROR - Error while process data from WebSocket ws://bot.kasumibot.cn:39306/v1/events
Traceback (most recent call last):
  File "f:\VS Code File\anonbot\anonbot\adapter\satori\adapter.py", line 142, in ws
    if not self._authenticate(info, ws):
           ^^^^^^^^^^^^^^^^^^^^^^^^^^^^
  File "f:\VS Code File\anonbot\anonbot\adapter\satori\adapter.py", line 101, in _authenticate
    response = self.receive_payload(info, ws)
               ^^^^^^^^^^^^^^^^^^^^^^^^^^^^^^
  File "f:\VS Code File\anonbot\anonbot\adapter\satori\adapter.py", line 79, in receive_payload
    payload = TypeAdapter(PayloadType).validate_python(json.loads(ws.receive()))
              ^^^^^^^^^^^^^^^^^^^^^^^^^^^^^^^^^^^^^^^^^^^^^^^^^^^^^^^^^^^^^^^^^^
  File "C:\Users\qwert\AppData\Local\Programs\Python\Python311\Lib\site-packages\pydantic\type_adapter.py", line 256, in validate_python
    return self.validator.validate_python(__object, strict=strict, from_attributes=from_attributes, context=context)
           ^^^^^^^^^^^^^^^^^^^^^^^^^^^^^^^^^^^^^^^^^^^^^^^^^^^^^^^^^^^^^^^^^^^^^^^^^^^^^^^^^^^^^^^^^^^^^^^^^^^^^^^^^
  File "<string>", line 3, in __init__
  File "C:\Users\qwert\AppData\Local\Programs\Python\Python311\Lib\site-packages\pydantic\main.py", line 810, in __setattr__
    self.__pydantic_fields_set__.add(name)
    ^^^^^^^^^^^^^^^^^^^^^^^^^^^^
  File "C:\Users\qwert\AppData\Local\Programs\Python\Python311\Lib\site-packages\pydantic\main.py", line 764, in __getattr__
    return super().__getattribute__(item)  # Raises AttributeError if appropriate
           ^^^^^^^^^^^^^^^^^^^^^^^^^^^^^^
AttributeError: 'OuterLogin' object has no attribute '__pydantic_fields_set__'

2024-02-28 23:25:32 - anonbot.adapter.satori.adapter - DEBUG - WebSocket connected to ws://bot.kasumibot.cn:39306/v1/events
2024-02-28 23:25:32 - anonbot.adapter.satori.adapter - ERROR - Error while process data from WebSocket ws://bot.kasumibot.cn:39306/v1/events
Traceback (most recent call last):
  File "f:\VS Code File\anonbot\anonbot\adapter\satori\adapter.py", line 142, in ws
    if not self._authenticate(info, ws):
           ^^^^^^^^^^^^^^^^^^^^^^^^^^^^
  File "f:\VS Code File\anonbot\anonbot\adapter\satori\adapter.py", line 101, in _authenticate
    response = self.receive_payload(info, ws)
               ^^^^^^^^^^^^^^^^^^^^^^^^^^^^^^
  File "f:\VS Code File\anonbot\anonbot\adapter\satori\adapter.py", line 79, in receive_payload
    payload = TypeAdapter(PayloadType).validate_python(json.loads(ws.receive()))
              ^^^^^^^^^^^^^^^^^^^^^^^^^^^^^^^^^^^^^^^^^^^^^^^^^^^^^^^^^^^^^^^^^^
  File "C:\Users\qwert\AppData\Local\Programs\Python\Python311\Lib\site-packages\pydantic\type_adapter.py", line 256, in validate_python
    return self.validator.validate_python(__object, strict=strict, from_attributes=from_attributes, context=context)
           ^^^^^^^^^^^^^^^^^^^^^^^^^^^^^^^^^^^^^^^^^^^^^^^^^^^^^^^^^^^^^^^^^^^^^^^^^^^^^^^^^^^^^^^^^^^^^^^^^^^^^^^^^
  File "<string>", line 3, in __init__
  File "C:\Users\qwert\AppData\Local\Programs\Python\Python311\Lib\site-packages\pydantic\main.py", line 810, in __setattr__
    self.__pydantic_fields_set__.add(name)
    ^^^^^^^^^^^^^^^^^^^^^^^^^^^^
  File "C:\Users\qwert\AppData\Local\Programs\Python\Python311\Lib\site-packages\pydantic\main.py", line 764, in __getattr__
    return super().__getattribute__(item)  # Raises AttributeError if appropriate
           ^^^^^^^^^^^^^^^^^^^^^^^^^^^^^^
AttributeError: 'OuterLogin' object has no attribute '__pydantic_fields_set__'

2024-02-28 23:25:33 - anonbot.adapter.satori.adapter - DEBUG - WebSocket connected to ws://bot.kasumibot.cn:39306/v1/events
2024-02-28 23:25:33 - anonbot.adapter.satori.adapter - ERROR - Error while process data from WebSocket ws://bot.kasumibot.cn:39306/v1/events
Traceback (most recent call last):
  File "f:\VS Code File\anonbot\anonbot\adapter\satori\adapter.py", line 142, in ws
    if not self._authenticate(info, ws):
           ^^^^^^^^^^^^^^^^^^^^^^^^^^^^
  File "f:\VS Code File\anonbot\anonbot\adapter\satori\adapter.py", line 101, in _authenticate
    response = self.receive_payload(info, ws)
               ^^^^^^^^^^^^^^^^^^^^^^^^^^^^^^
  File "f:\VS Code File\anonbot\anonbot\adapter\satori\adapter.py", line 79, in receive_payload
    payload = TypeAdapter(PayloadType).validate_python(json.loads(ws.receive()))
              ^^^^^^^^^^^^^^^^^^^^^^^^^^^^^^^^^^^^^^^^^^^^^^^^^^^^^^^^^^^^^^^^^^
  File "C:\Users\qwert\AppData\Local\Programs\Python\Python311\Lib\site-packages\pydantic\type_adapter.py", line 256, in validate_python
    return self.validator.validate_python(__object, strict=strict, from_attributes=from_attributes, context=context)
           ^^^^^^^^^^^^^^^^^^^^^^^^^^^^^^^^^^^^^^^^^^^^^^^^^^^^^^^^^^^^^^^^^^^^^^^^^^^^^^^^^^^^^^^^^^^^^^^^^^^^^^^^^
  File "<string>", line 3, in __init__
  File "C:\Users\qwert\AppData\Local\Programs\Python\Python311\Lib\site-packages\pydantic\main.py", line 810, in __setattr__
    self.__pydantic_fields_set__.add(name)
    ^^^^^^^^^^^^^^^^^^^^^^^^^^^^
  File "C:\Users\qwert\AppData\Local\Programs\Python\Python311\Lib\site-packages\pydantic\main.py", line 764, in __getattr__
    return super().__getattribute__(item)  # Raises AttributeError if appropriate
           ^^^^^^^^^^^^^^^^^^^^^^^^^^^^^^
AttributeError: 'OuterLogin' object has no attribute '__pydantic_fields_set__'

2024-02-28 23:25:33 - anonbot.adapter.satori.adapter - DEBUG - WebSocket connected to ws://bot.kasumibot.cn:39306/v1/events
2024-02-28 23:25:33 - anonbot.adapter.satori.adapter - ERROR - Error while process data from WebSocket ws://bot.kasumibot.cn:39306/v1/events
Traceback (most recent call last):
  File "f:\VS Code File\anonbot\anonbot\adapter\satori\adapter.py", line 142, in ws
    if not self._authenticate(info, ws):
           ^^^^^^^^^^^^^^^^^^^^^^^^^^^^
  File "f:\VS Code File\anonbot\anonbot\adapter\satori\adapter.py", line 101, in _authenticate
    response = self.receive_payload(info, ws)
               ^^^^^^^^^^^^^^^^^^^^^^^^^^^^^^
  File "f:\VS Code File\anonbot\anonbot\adapter\satori\adapter.py", line 79, in receive_payload
    payload = TypeAdapter(PayloadType).validate_python(json.loads(ws.receive()))
              ^^^^^^^^^^^^^^^^^^^^^^^^^^^^^^^^^^^^^^^^^^^^^^^^^^^^^^^^^^^^^^^^^^
  File "C:\Users\qwert\AppData\Local\Programs\Python\Python311\Lib\site-packages\pydantic\type_adapter.py", line 256, in validate_python
    return self.validator.validate_python(__object, strict=strict, from_attributes=from_attributes, context=context)
           ^^^^^^^^^^^^^^^^^^^^^^^^^^^^^^^^^^^^^^^^^^^^^^^^^^^^^^^^^^^^^^^^^^^^^^^^^^^^^^^^^^^^^^^^^^^^^^^^^^^^^^^^^
  File "<string>", line 3, in __init__
  File "C:\Users\qwert\AppData\Local\Programs\Python\Python311\Lib\site-packages\pydantic\main.py", line 810, in __setattr__
    self.__pydantic_fields_set__.add(name)
    ^^^^^^^^^^^^^^^^^^^^^^^^^^^^
  File "C:\Users\qwert\AppData\Local\Programs\Python\Python311\Lib\site-packages\pydantic\main.py", line 764, in __getattr__
    return super().__getattribute__(item)  # Raises AttributeError if appropriate
           ^^^^^^^^^^^^^^^^^^^^^^^^^^^^^^
AttributeError: 'OuterLogin' object has no attribute '__pydantic_fields_set__'

2024-02-28 23:25:34 - anonbot.adapter.satori.adapter - DEBUG - WebSocket connected to ws://bot.kasumibot.cn:39306/v1/events
2024-02-28 23:25:34 - anonbot.adapter.satori.adapter - ERROR - Error while process data from WebSocket ws://bot.kasumibot.cn:39306/v1/events
Traceback (most recent call last):
  File "f:\VS Code File\anonbot\anonbot\adapter\satori\adapter.py", line 142, in ws
    if not self._authenticate(info, ws):
           ^^^^^^^^^^^^^^^^^^^^^^^^^^^^
  File "f:\VS Code File\anonbot\anonbot\adapter\satori\adapter.py", line 101, in _authenticate
    response = self.receive_payload(info, ws)
               ^^^^^^^^^^^^^^^^^^^^^^^^^^^^^^
  File "f:\VS Code File\anonbot\anonbot\adapter\satori\adapter.py", line 79, in receive_payload
    payload = TypeAdapter(PayloadType).validate_python(json.loads(ws.receive()))
              ^^^^^^^^^^^^^^^^^^^^^^^^^^^^^^^^^^^^^^^^^^^^^^^^^^^^^^^^^^^^^^^^^^
  File "C:\Users\qwert\AppData\Local\Programs\Python\Python311\Lib\site-packages\pydantic\type_adapter.py", line 256, in validate_python
    return self.validator.validate_python(__object, strict=strict, from_attributes=from_attributes, context=context)
           ^^^^^^^^^^^^^^^^^^^^^^^^^^^^^^^^^^^^^^^^^^^^^^^^^^^^^^^^^^^^^^^^^^^^^^^^^^^^^^^^^^^^^^^^^^^^^^^^^^^^^^^^^
  File "<string>", line 3, in __init__
  File "C:\Users\qwert\AppData\Local\Programs\Python\Python311\Lib\site-packages\pydantic\main.py", line 810, in __setattr__
    self.__pydantic_fields_set__.add(name)
    ^^^^^^^^^^^^^^^^^^^^^^^^^^^^
  File "C:\Users\qwert\AppData\Local\Programs\Python\Python311\Lib\site-packages\pydantic\main.py", line 764, in __getattr__
    return super().__getattribute__(item)  # Raises AttributeError if appropriate
           ^^^^^^^^^^^^^^^^^^^^^^^^^^^^^^
AttributeError: 'OuterLogin' object has no attribute '__pydantic_fields_set__'

2024-02-28 23:25:35 - anonbot.adapter.satori.adapter - DEBUG - WebSocket connected to ws://bot.kasumibot.cn:39306/v1/events
2024-02-28 23:25:35 - anonbot.adapter.satori.adapter - ERROR - Error while process data from WebSocket ws://bot.kasumibot.cn:39306/v1/events
Traceback (most recent call last):
  File "f:\VS Code File\anonbot\anonbot\adapter\satori\adapter.py", line 142, in ws
    if not self._authenticate(info, ws):
           ^^^^^^^^^^^^^^^^^^^^^^^^^^^^
  File "f:\VS Code File\anonbot\anonbot\adapter\satori\adapter.py", line 101, in _authenticate
    response = self.receive_payload(info, ws)
               ^^^^^^^^^^^^^^^^^^^^^^^^^^^^^^
  File "f:\VS Code File\anonbot\anonbot\adapter\satori\adapter.py", line 79, in receive_payload
    payload = TypeAdapter(PayloadType).validate_python(json.loads(ws.receive()))
              ^^^^^^^^^^^^^^^^^^^^^^^^^^^^^^^^^^^^^^^^^^^^^^^^^^^^^^^^^^^^^^^^^^
  File "C:\Users\qwert\AppData\Local\Programs\Python\Python311\Lib\site-packages\pydantic\type_adapter.py", line 256, in validate_python
    return self.validator.validate_python(__object, strict=strict, from_attributes=from_attributes, context=context)
           ^^^^^^^^^^^^^^^^^^^^^^^^^^^^^^^^^^^^^^^^^^^^^^^^^^^^^^^^^^^^^^^^^^^^^^^^^^^^^^^^^^^^^^^^^^^^^^^^^^^^^^^^^
  File "<string>", line 3, in __init__
  File "C:\Users\qwert\AppData\Local\Programs\Python\Python311\Lib\site-packages\pydantic\main.py", line 810, in __setattr__
    self.__pydantic_fields_set__.add(name)
    ^^^^^^^^^^^^^^^^^^^^^^^^^^^^
  File "C:\Users\qwert\AppData\Local\Programs\Python\Python311\Lib\site-packages\pydantic\main.py", line 764, in __getattr__
    return super().__getattribute__(item)  # Raises AttributeError if appropriate
           ^^^^^^^^^^^^^^^^^^^^^^^^^^^^^^
AttributeError: 'OuterLogin' object has no attribute '__pydantic_fields_set__'

2024-02-28 23:25:35 - anonbot.adapter.satori.adapter - DEBUG - WebSocket connected to ws://bot.kasumibot.cn:39306/v1/events
2024-02-28 23:25:35 - anonbot.adapter.satori.adapter - ERROR - Error while process data from WebSocket ws://bot.kasumibot.cn:39306/v1/events
Traceback (most recent call last):
  File "f:\VS Code File\anonbot\anonbot\adapter\satori\adapter.py", line 142, in ws
    if not self._authenticate(info, ws):
           ^^^^^^^^^^^^^^^^^^^^^^^^^^^^
  File "f:\VS Code File\anonbot\anonbot\adapter\satori\adapter.py", line 101, in _authenticate
    response = self.receive_payload(info, ws)
               ^^^^^^^^^^^^^^^^^^^^^^^^^^^^^^
  File "f:\VS Code File\anonbot\anonbot\adapter\satori\adapter.py", line 79, in receive_payload
    payload = TypeAdapter(PayloadType).validate_python(json.loads(ws.receive()))
              ^^^^^^^^^^^^^^^^^^^^^^^^^^^^^^^^^^^^^^^^^^^^^^^^^^^^^^^^^^^^^^^^^^
  File "C:\Users\qwert\AppData\Local\Programs\Python\Python311\Lib\site-packages\pydantic\type_adapter.py", line 256, in validate_python
    return self.validator.validate_python(__object, strict=strict, from_attributes=from_attributes, context=context)
           ^^^^^^^^^^^^^^^^^^^^^^^^^^^^^^^^^^^^^^^^^^^^^^^^^^^^^^^^^^^^^^^^^^^^^^^^^^^^^^^^^^^^^^^^^^^^^^^^^^^^^^^^^
  File "<string>", line 3, in __init__
  File "C:\Users\qwert\AppData\Local\Programs\Python\Python311\Lib\site-packages\pydantic\main.py", line 810, in __setattr__
    self.__pydantic_fields_set__.add(name)
    ^^^^^^^^^^^^^^^^^^^^^^^^^^^^
  File "C:\Users\qwert\AppData\Local\Programs\Python\Python311\Lib\site-packages\pydantic\main.py", line 764, in __getattr__
    return super().__getattribute__(item)  # Raises AttributeError if appropriate
           ^^^^^^^^^^^^^^^^^^^^^^^^^^^^^^
AttributeError: 'OuterLogin' object has no attribute '__pydantic_fields_set__'

2024-02-28 23:25:36 - anonbot.adapter.satori.adapter - DEBUG - WebSocket connected to ws://bot.kasumibot.cn:39306/v1/events
2024-02-28 23:25:36 - anonbot.adapter.satori.adapter - ERROR - Error while process data from WebSocket ws://bot.kasumibot.cn:39306/v1/events
Traceback (most recent call last):
  File "f:\VS Code File\anonbot\anonbot\adapter\satori\adapter.py", line 142, in ws
    if not self._authenticate(info, ws):
           ^^^^^^^^^^^^^^^^^^^^^^^^^^^^
  File "f:\VS Code File\anonbot\anonbot\adapter\satori\adapter.py", line 101, in _authenticate
    response = self.receive_payload(info, ws)
               ^^^^^^^^^^^^^^^^^^^^^^^^^^^^^^
  File "f:\VS Code File\anonbot\anonbot\adapter\satori\adapter.py", line 79, in receive_payload
    payload = TypeAdapter(PayloadType).validate_python(json.loads(ws.receive()))
              ^^^^^^^^^^^^^^^^^^^^^^^^^^^^^^^^^^^^^^^^^^^^^^^^^^^^^^^^^^^^^^^^^^
  File "C:\Users\qwert\AppData\Local\Programs\Python\Python311\Lib\site-packages\pydantic\type_adapter.py", line 256, in validate_python
    return self.validator.validate_python(__object, strict=strict, from_attributes=from_attributes, context=context)
           ^^^^^^^^^^^^^^^^^^^^^^^^^^^^^^^^^^^^^^^^^^^^^^^^^^^^^^^^^^^^^^^^^^^^^^^^^^^^^^^^^^^^^^^^^^^^^^^^^^^^^^^^^
  File "<string>", line 3, in __init__
  File "C:\Users\qwert\AppData\Local\Programs\Python\Python311\Lib\site-packages\pydantic\main.py", line 810, in __setattr__
    self.__pydantic_fields_set__.add(name)
    ^^^^^^^^^^^^^^^^^^^^^^^^^^^^
  File "C:\Users\qwert\AppData\Local\Programs\Python\Python311\Lib\site-packages\pydantic\main.py", line 764, in __getattr__
    return super().__getattribute__(item)  # Raises AttributeError if appropriate
           ^^^^^^^^^^^^^^^^^^^^^^^^^^^^^^
AttributeError: 'OuterLogin' object has no attribute '__pydantic_fields_set__'

2024-02-28 23:25:36 - anonbot.adapter.satori.adapter - DEBUG - WebSocket connected to ws://bot.kasumibot.cn:39306/v1/events
2024-02-28 23:25:36 - anonbot.adapter.satori.adapter - ERROR - Error while process data from WebSocket ws://bot.kasumibot.cn:39306/v1/events
Traceback (most recent call last):
  File "f:\VS Code File\anonbot\anonbot\adapter\satori\adapter.py", line 142, in ws
    if not self._authenticate(info, ws):
           ^^^^^^^^^^^^^^^^^^^^^^^^^^^^
  File "f:\VS Code File\anonbot\anonbot\adapter\satori\adapter.py", line 101, in _authenticate
    response = self.receive_payload(info, ws)
               ^^^^^^^^^^^^^^^^^^^^^^^^^^^^^^
  File "f:\VS Code File\anonbot\anonbot\adapter\satori\adapter.py", line 79, in receive_payload
    payload = TypeAdapter(PayloadType).validate_python(json.loads(ws.receive()))
              ^^^^^^^^^^^^^^^^^^^^^^^^^^^^^^^^^^^^^^^^^^^^^^^^^^^^^^^^^^^^^^^^^^
  File "C:\Users\qwert\AppData\Local\Programs\Python\Python311\Lib\site-packages\pydantic\type_adapter.py", line 256, in validate_python
    return self.validator.validate_python(__object, strict=strict, from_attributes=from_attributes, context=context)
           ^^^^^^^^^^^^^^^^^^^^^^^^^^^^^^^^^^^^^^^^^^^^^^^^^^^^^^^^^^^^^^^^^^^^^^^^^^^^^^^^^^^^^^^^^^^^^^^^^^^^^^^^^
  File "<string>", line 3, in __init__
  File "C:\Users\qwert\AppData\Local\Programs\Python\Python311\Lib\site-packages\pydantic\main.py", line 810, in __setattr__
    self.__pydantic_fields_set__.add(name)
    ^^^^^^^^^^^^^^^^^^^^^^^^^^^^
  File "C:\Users\qwert\AppData\Local\Programs\Python\Python311\Lib\site-packages\pydantic\main.py", line 764, in __getattr__
    return super().__getattribute__(item)  # Raises AttributeError if appropriate
           ^^^^^^^^^^^^^^^^^^^^^^^^^^^^^^
AttributeError: 'OuterLogin' object has no attribute '__pydantic_fields_set__'

2024-02-28 23:25:37 - anonbot.adapter.satori.adapter - DEBUG - WebSocket connected to ws://bot.kasumibot.cn:39306/v1/events
2024-02-28 23:25:37 - anonbot.adapter.satori.adapter - ERROR - Error while process data from WebSocket ws://bot.kasumibot.cn:39306/v1/events
Traceback (most recent call last):
  File "f:\VS Code File\anonbot\anonbot\adapter\satori\adapter.py", line 142, in ws
    if not self._authenticate(info, ws):
           ^^^^^^^^^^^^^^^^^^^^^^^^^^^^
  File "f:\VS Code File\anonbot\anonbot\adapter\satori\adapter.py", line 101, in _authenticate
    response = self.receive_payload(info, ws)
               ^^^^^^^^^^^^^^^^^^^^^^^^^^^^^^
  File "f:\VS Code File\anonbot\anonbot\adapter\satori\adapter.py", line 79, in receive_payload
    payload = TypeAdapter(PayloadType).validate_python(json.loads(ws.receive()))
              ^^^^^^^^^^^^^^^^^^^^^^^^^^^^^^^^^^^^^^^^^^^^^^^^^^^^^^^^^^^^^^^^^^
  File "C:\Users\qwert\AppData\Local\Programs\Python\Python311\Lib\site-packages\pydantic\type_adapter.py", line 256, in validate_python
    return self.validator.validate_python(__object, strict=strict, from_attributes=from_attributes, context=context)
           ^^^^^^^^^^^^^^^^^^^^^^^^^^^^^^^^^^^^^^^^^^^^^^^^^^^^^^^^^^^^^^^^^^^^^^^^^^^^^^^^^^^^^^^^^^^^^^^^^^^^^^^^^
  File "<string>", line 3, in __init__
  File "C:\Users\qwert\AppData\Local\Programs\Python\Python311\Lib\site-packages\pydantic\main.py", line 810, in __setattr__
    self.__pydantic_fields_set__.add(name)
    ^^^^^^^^^^^^^^^^^^^^^^^^^^^^
  File "C:\Users\qwert\AppData\Local\Programs\Python\Python311\Lib\site-packages\pydantic\main.py", line 764, in __getattr__
    return super().__getattribute__(item)  # Raises AttributeError if appropriate
           ^^^^^^^^^^^^^^^^^^^^^^^^^^^^^^
AttributeError: 'OuterLogin' object has no attribute '__pydantic_fields_set__'

2024-02-28 23:25:37 - anonbot.adapter.satori.adapter - DEBUG - WebSocket connected to ws://bot.kasumibot.cn:39306/v1/events
2024-02-28 23:25:37 - anonbot.adapter.satori.adapter - ERROR - Error while process data from WebSocket ws://bot.kasumibot.cn:39306/v1/events
Traceback (most recent call last):
  File "f:\VS Code File\anonbot\anonbot\adapter\satori\adapter.py", line 142, in ws
    if not self._authenticate(info, ws):
           ^^^^^^^^^^^^^^^^^^^^^^^^^^^^
  File "f:\VS Code File\anonbot\anonbot\adapter\satori\adapter.py", line 101, in _authenticate
    response = self.receive_payload(info, ws)
               ^^^^^^^^^^^^^^^^^^^^^^^^^^^^^^
  File "f:\VS Code File\anonbot\anonbot\adapter\satori\adapter.py", line 79, in receive_payload
    payload = TypeAdapter(PayloadType).validate_python(json.loads(ws.receive()))
              ^^^^^^^^^^^^^^^^^^^^^^^^^^^^^^^^^^^^^^^^^^^^^^^^^^^^^^^^^^^^^^^^^^
  File "C:\Users\qwert\AppData\Local\Programs\Python\Python311\Lib\site-packages\pydantic\type_adapter.py", line 256, in validate_python
    return self.validator.validate_python(__object, strict=strict, from_attributes=from_attributes, context=context)
           ^^^^^^^^^^^^^^^^^^^^^^^^^^^^^^^^^^^^^^^^^^^^^^^^^^^^^^^^^^^^^^^^^^^^^^^^^^^^^^^^^^^^^^^^^^^^^^^^^^^^^^^^^
  File "<string>", line 3, in __init__
  File "C:\Users\qwert\AppData\Local\Programs\Python\Python311\Lib\site-packages\pydantic\main.py", line 810, in __setattr__
    self.__pydantic_fields_set__.add(name)
    ^^^^^^^^^^^^^^^^^^^^^^^^^^^^
  File "C:\Users\qwert\AppData\Local\Programs\Python\Python311\Lib\site-packages\pydantic\main.py", line 764, in __getattr__
    return super().__getattribute__(item)  # Raises AttributeError if appropriate
           ^^^^^^^^^^^^^^^^^^^^^^^^^^^^^^
AttributeError: 'OuterLogin' object has no attribute '__pydantic_fields_set__'

2024-02-28 23:25:38 - anonbot.adapter.satori.adapter - DEBUG - WebSocket connected to ws://bot.kasumibot.cn:39306/v1/events
2024-02-28 23:25:38 - anonbot.adapter.satori.adapter - ERROR - Error while process data from WebSocket ws://bot.kasumibot.cn:39306/v1/events
Traceback (most recent call last):
  File "f:\VS Code File\anonbot\anonbot\adapter\satori\adapter.py", line 142, in ws
    if not self._authenticate(info, ws):
           ^^^^^^^^^^^^^^^^^^^^^^^^^^^^
  File "f:\VS Code File\anonbot\anonbot\adapter\satori\adapter.py", line 101, in _authenticate
    response = self.receive_payload(info, ws)
               ^^^^^^^^^^^^^^^^^^^^^^^^^^^^^^
  File "f:\VS Code File\anonbot\anonbot\adapter\satori\adapter.py", line 79, in receive_payload
    payload = TypeAdapter(PayloadType).validate_python(json.loads(ws.receive()))
              ^^^^^^^^^^^^^^^^^^^^^^^^^^^^^^^^^^^^^^^^^^^^^^^^^^^^^^^^^^^^^^^^^^
  File "C:\Users\qwert\AppData\Local\Programs\Python\Python311\Lib\site-packages\pydantic\type_adapter.py", line 256, in validate_python
    return self.validator.validate_python(__object, strict=strict, from_attributes=from_attributes, context=context)
           ^^^^^^^^^^^^^^^^^^^^^^^^^^^^^^^^^^^^^^^^^^^^^^^^^^^^^^^^^^^^^^^^^^^^^^^^^^^^^^^^^^^^^^^^^^^^^^^^^^^^^^^^^
  File "<string>", line 3, in __init__
  File "C:\Users\qwert\AppData\Local\Programs\Python\Python311\Lib\site-packages\pydantic\main.py", line 810, in __setattr__
    self.__pydantic_fields_set__.add(name)
    ^^^^^^^^^^^^^^^^^^^^^^^^^^^^
  File "C:\Users\qwert\AppData\Local\Programs\Python\Python311\Lib\site-packages\pydantic\main.py", line 764, in __getattr__
    return super().__getattribute__(item)  # Raises AttributeError if appropriate
           ^^^^^^^^^^^^^^^^^^^^^^^^^^^^^^
AttributeError: 'OuterLogin' object has no attribute '__pydantic_fields_set__'

2024-02-28 23:27:36 - anonbot - INFO - Initializing AnonBot
2024-02-28 23:27:36 - anonbot.internal.driver.abstract - DEBUG - Driver(type='general+websocket+flask+httpx', adapters=1, bots=0) 成功注册 adapter Satori
2024-02-28 23:27:36 - anonbot.internal.driver.abstract - DEBUG - Adapters Loaded: Satori
2024-02-28 23:27:36 - anonbot.driver.general - INFO - 应用启动成功
2024-02-28 23:27:36 - anonbot.adapter.satori.adapter - DEBUG - WebSocket connected to ws://bot.kasumibot.cn:39306/v1/events
2024-02-28 23:27:37 - anonbot.adapter.satori.adapter - INFO - Bot 3662854527 connected to chronocat
2024-02-28 23:28:37 - anonbot.adapter.satori.adapter - ERROR - Error while process data from WebSocket ws://bot.kasumibot.cn:39306/v1/events
Traceback (most recent call last):
  File "C:\Users\qwert\AppData\Local\Programs\Python\Python311\Lib\site-packages\websocket\_socket.py", line 110, in recv
    bytes_ = _recv()
             ^^^^^^^
  File "C:\Users\qwert\AppData\Local\Programs\Python\Python311\Lib\site-packages\websocket\_socket.py", line 89, in _recv
    return sock.recv(bufsize)
           ^^^^^^^^^^^^^^^^^^
TimeoutError: timed out

During handling of the above exception, another exception occurred:

Traceback (most recent call last):
  File "f:\VS Code File\anonbot\anonbot\adapter\satori\adapter.py", line 147, in ws
    self._loop(info, ws)
  File "f:\VS Code File\anonbot\anonbot\adapter\satori\adapter.py", line 166, in _loop
    payload = self.receive_payload(info, ws)
              ^^^^^^^^^^^^^^^^^^^^^^^^^^^^^^
  File "f:\VS Code File\anonbot\anonbot\adapter\satori\adapter.py", line 79, in receive_payload
    payload = TypeAdapter(PayloadType).validate_python(json.loads(ws.receive()))
                                                                  ^^^^^^^^^^^^
  File "f:\VS Code File\anonbot\anonbot\driver\websocket.py", line 32, in decorator
    raise exception
  File "f:\VS Code File\anonbot\anonbot\driver\websocket.py", line 28, in decorator
    return func(*args, **kwargs)
           ^^^^^^^^^^^^^^^^^^^^^
  File "f:\VS Code File\anonbot\anonbot\driver\websocket.py", line 82, in receive
    opcode, data = self.websocket.recv_data()
                   ^^^^^^^^^^^^^^^^^^^^^^^^^^
  File "C:\Users\qwert\AppData\Local\Programs\Python\Python311\Lib\site-packages\websocket\_core.py", line 387, in recv_data
    opcode, frame = self.recv_data_frame(control_frame)
                    ^^^^^^^^^^^^^^^^^^^^^^^^^^^^^^^^^^^
  File "C:\Users\qwert\AppData\Local\Programs\Python\Python311\Lib\site-packages\websocket\_core.py", line 408, in recv_data_frame
    frame = self.recv_frame()
            ^^^^^^^^^^^^^^^^^
  File "C:\Users\qwert\AppData\Local\Programs\Python\Python311\Lib\site-packages\websocket\_core.py", line 447, in recv_frame
    return self.frame_buffer.recv_frame()
           ^^^^^^^^^^^^^^^^^^^^^^^^^^^^^^
  File "C:\Users\qwert\AppData\Local\Programs\Python\Python311\Lib\site-packages\websocket\_abnf.py", line 340, in recv_frame
    self.recv_header()
  File "C:\Users\qwert\AppData\Local\Programs\Python\Python311\Lib\site-packages\websocket\_abnf.py", line 296, in recv_header
    header = self.recv_strict(2)
             ^^^^^^^^^^^^^^^^^^^
  File "C:\Users\qwert\AppData\Local\Programs\Python\Python311\Lib\site-packages\websocket\_abnf.py", line 375, in recv_strict
    bytes_ = self.recv(min(16384, shortage))
             ^^^^^^^^^^^^^^^^^^^^^^^^^^^^^^^
  File "C:\Users\qwert\AppData\Local\Programs\Python\Python311\Lib\site-packages\websocket\_core.py", line 531, in _recv
    return recv(self.sock, bufsize)
           ^^^^^^^^^^^^^^^^^^^^^^^^
  File "C:\Users\qwert\AppData\Local\Programs\Python\Python311\Lib\site-packages\websocket\_socket.py", line 112, in recv
    raise WebSocketTimeoutException("Connection timed out")
websocket._exceptions.WebSocketTimeoutException: Connection timed out

2024-02-28 23:28:37 - anonbot.adapter.satori.adapter - DEBUG - WebSocket connected to ws://bot.kasumibot.cn:39306/v1/events
2024-02-28 23:28:37 - anonbot.adapter.satori.adapter - INFO - Bot 3662854527 connected to chronocat
2024-02-28 23:29:35 - anonbot - INFO - Initializing AnonBot
2024-02-28 23:29:36 - anonbot.internal.driver.abstract - DEBUG - Driver(type='general+websocket+flask+httpx', adapters=1, bots=0) 成功注册 adapter Satori
2024-02-28 23:29:36 - anonbot.internal.driver.abstract - DEBUG - Adapters Loaded: Satori
2024-02-28 23:29:36 - anonbot.driver.general - INFO - 应用启动成功
2024-02-28 23:29:36 - anonbot.adapter.satori.adapter - DEBUG - WebSocket connected to ws://bot.kasumibot.cn:39306/v1/events
2024-02-28 23:29:36 - anonbot.adapter.satori.adapter - INFO - Bot 3662854527 connected to chronocat
2024-02-28 23:29:36 - anonbot.adapter.satori.adapter - TRACE - Heartbeat at None
2024-02-28 23:29:36 - anonbot.adapter.satori.adapter - TRACE - Received payload: PongPayload(op=<Opcode.PONG: 2>, body=None)
2024-02-28 23:29:36 - anonbot.adapter.satori.adapter - TRACE - Pong
2024-02-28 23:29:45 - anonbot.adapter.satori.adapter - TRACE - Heartbeat at None
2024-02-28 23:29:45 - anonbot.adapter.satori.adapter - TRACE - Received payload: PongPayload(op=<Opcode.PONG: 2>, body=None)
2024-02-28 23:29:45 - anonbot.adapter.satori.adapter - TRACE - Pong
2024-02-28 23:29:54 - anonbot.adapter.satori.adapter - TRACE - Heartbeat at None
2024-02-28 23:29:54 - anonbot.adapter.satori.adapter - TRACE - Received payload: PongPayload(op=<Opcode.PONG: 2>, body=None)
2024-02-28 23:29:54 - anonbot.adapter.satori.adapter - TRACE - Pong
2024-02-28 23:30:03 - anonbot.adapter.satori.adapter - TRACE - Heartbeat at None
2024-02-28 23:30:03 - anonbot.adapter.satori.adapter - TRACE - Received payload: PongPayload(op=<Opcode.PONG: 2>, body=None)
2024-02-28 23:30:03 - anonbot.adapter.satori.adapter - TRACE - Pong
2024-02-28 23:30:12 - anonbot.adapter.satori.adapter - TRACE - Heartbeat at None
2024-02-28 23:30:12 - anonbot.adapter.satori.adapter - TRACE - Received payload: PongPayload(op=<Opcode.PONG: 2>, body=None)
2024-02-28 23:30:12 - anonbot.adapter.satori.adapter - TRACE - Pong
2024-02-28 23:30:21 - anonbot.adapter.satori.adapter - TRACE - Heartbeat at None
2024-02-28 23:30:21 - anonbot.adapter.satori.adapter - TRACE - Received payload: PongPayload(op=<Opcode.PONG: 2>, body=None)
2024-02-28 23:30:22 - anonbot.adapter.satori.adapter - TRACE - Pong
2024-02-28 23:30:30 - anonbot.adapter.satori.adapter - TRACE - Heartbeat at None
2024-02-28 23:30:31 - anonbot.adapter.satori.adapter - TRACE - Received payload: PongPayload(op=<Opcode.PONG: 2>, body=None)
2024-02-28 23:30:31 - anonbot.adapter.satori.adapter - TRACE - Pong
2024-02-28 23:30:39 - anonbot.adapter.satori.adapter - TRACE - Heartbeat at None
2024-02-28 23:30:40 - anonbot.adapter.satori.adapter - TRACE - Received payload: PongPayload(op=<Opcode.PONG: 2>, body=None)
2024-02-28 23:30:40 - anonbot.adapter.satori.adapter - TRACE - Pong
2024-02-28 23:30:46 - anonbot.adapter.satori.adapter - TRACE - Received payload: Payload(op=<Opcode.EVENT: 0>, body={'id': 1, 'type': 'message-created', 'platform': 'chronocat', 'self_id': '3662854527', 'timestamp': 1709134246000, 'user': {'id': '1242954863', 'avatar': 'http://q.qlogo.cn/headimg_dl?dst_uin=1242954863&spec=640'}, 'channel': {'type': 0, 'id': '227179118', 'name': '你好'}, 'guild': {'id': '227179118', 'name': '你好', 'avatar': 'https://p.qlogo.cn/gh/227179118/227179118/640'}, 'member': {'name': 'WindowsSov8'}, 'message': {'id': '7340675688548448807', 'content': '你好'}})
2024-02-28 23:30:46 - anonbot.adapter.satori.adapter - WARN - Unknown payload: Payload(op=<Opcode.EVENT: 0>, body={'id': 1, 'type': 'message-created', 'platform': 'chronocat', 'self_id': '3662854527', 'timestamp': 1709134246000, 'user': {'id': '1242954863', 'avatar': 'http://q.qlogo.cn/headimg_dl?dst_uin=1242954863&spec=640'}, 'channel': {'type': 0, 'id': '227179118', 'name': '你好'}, 'guild': {'id': '227179118', 'name': '你好', 'avatar': 'https://p.qlogo.cn/gh/227179118/227179118/640'}, 'member': {'name': 'WindowsSov8'}, 'message': {'id': '7340675688548448807', 'content': '你好'}})
2024-02-28 23:30:48 - anonbot.adapter.satori.adapter - TRACE - Heartbeat at None
2024-02-28 23:30:49 - anonbot.adapter.satori.adapter - TRACE - Received payload: PongPayload(op=<Opcode.PONG: 2>, body=None)
2024-02-28 23:30:49 - anonbot.adapter.satori.adapter - TRACE - Pong
2024-02-28 23:30:57 - anonbot.adapter.satori.adapter - TRACE - Heartbeat at None
2024-02-28 23:30:58 - anonbot.adapter.satori.adapter - TRACE - Received payload: PongPayload(op=<Opcode.PONG: 2>, body=None)
2024-02-28 23:30:58 - anonbot.adapter.satori.adapter - TRACE - Pong
2024-02-28 23:31:06 - anonbot.adapter.satori.adapter - TRACE - Heartbeat at None
2024-02-28 23:31:07 - anonbot.adapter.satori.adapter - TRACE - Received payload: PongPayload(op=<Opcode.PONG: 2>, body=None)
2024-02-28 23:31:07 - anonbot.adapter.satori.adapter - TRACE - Pong
2024-02-28 23:31:15 - anonbot.adapter.satori.adapter - TRACE - Heartbeat at None
2024-02-28 23:31:16 - anonbot.adapter.satori.adapter - TRACE - Received payload: PongPayload(op=<Opcode.PONG: 2>, body=None)
2024-02-28 23:31:16 - anonbot.adapter.satori.adapter - TRACE - Pong
2024-02-28 23:31:24 - anonbot.adapter.satori.adapter - TRACE - Heartbeat at None
2024-02-28 23:31:25 - anonbot.adapter.satori.adapter - TRACE - Received payload: PongPayload(op=<Opcode.PONG: 2>, body=None)
2024-02-28 23:31:25 - anonbot.adapter.satori.adapter - TRACE - Pong
2024-02-28 23:31:34 - anonbot.adapter.satori.adapter - TRACE - Heartbeat at None
2024-02-28 23:31:34 - anonbot.adapter.satori.adapter - TRACE - Received payload: PongPayload(op=<Opcode.PONG: 2>, body=None)
2024-02-28 23:31:34 - anonbot.adapter.satori.adapter - TRACE - Pong
2024-02-28 23:31:43 - anonbot.adapter.satori.adapter - TRACE - Heartbeat at None
2024-02-28 23:31:43 - anonbot.adapter.satori.adapter - TRACE - Received payload: PongPayload(op=<Opcode.PONG: 2>, body=None)
2024-02-28 23:31:43 - anonbot.adapter.satori.adapter - TRACE - Pong
2024-02-28 23:31:52 - anonbot.adapter.satori.adapter - TRACE - Heartbeat at None
2024-02-28 23:31:52 - anonbot.adapter.satori.adapter - TRACE - Received payload: PongPayload(op=<Opcode.PONG: 2>, body=None)
2024-02-28 23:31:52 - anonbot.adapter.satori.adapter - TRACE - Pong
2024-02-28 23:32:01 - anonbot.adapter.satori.adapter - TRACE - Heartbeat at None
2024-02-28 23:32:01 - anonbot.adapter.satori.adapter - TRACE - Received payload: PongPayload(op=<Opcode.PONG: 2>, body=None)
2024-02-28 23:32:01 - anonbot.adapter.satori.adapter - TRACE - Pong
2024-02-28 23:32:10 - anonbot.adapter.satori.adapter - TRACE - Heartbeat at None
2024-02-28 23:32:10 - anonbot.adapter.satori.adapter - TRACE - Received payload: PongPayload(op=<Opcode.PONG: 2>, body=None)
2024-02-28 23:32:10 - anonbot.adapter.satori.adapter - TRACE - Pong
2024-02-28 23:32:19 - anonbot.adapter.satori.adapter - TRACE - Heartbeat at None
2024-02-28 23:32:19 - anonbot.adapter.satori.adapter - TRACE - Received payload: PongPayload(op=<Opcode.PONG: 2>, body=None)
2024-02-28 23:32:19 - anonbot.adapter.satori.adapter - TRACE - Pong
2024-02-28 23:32:28 - anonbot.adapter.satori.adapter - TRACE - Heartbeat at None
2024-02-28 23:32:28 - anonbot.adapter.satori.adapter - TRACE - Received payload: PongPayload(op=<Opcode.PONG: 2>, body=None)
2024-02-28 23:32:28 - anonbot.adapter.satori.adapter - TRACE - Pong
2024-02-28 23:32:37 - anonbot.adapter.satori.adapter - TRACE - Heartbeat at None
2024-02-28 23:32:37 - anonbot.adapter.satori.adapter - TRACE - Received payload: PongPayload(op=<Opcode.PONG: 2>, body=None)
2024-02-28 23:32:37 - anonbot.adapter.satori.adapter - TRACE - Pong
2024-02-28 23:32:46 - anonbot.adapter.satori.adapter - TRACE - Heartbeat at None
2024-02-28 23:32:46 - anonbot.adapter.satori.adapter - TRACE - Received payload: PongPayload(op=<Opcode.PONG: 2>, body=None)
2024-02-28 23:32:46 - anonbot.adapter.satori.adapter - TRACE - Pong
2024-02-28 23:32:55 - anonbot.adapter.satori.adapter - TRACE - Heartbeat at None
2024-02-28 23:32:55 - anonbot.adapter.satori.adapter - TRACE - Received payload: PongPayload(op=<Opcode.PONG: 2>, body=None)
2024-02-28 23:32:55 - anonbot.adapter.satori.adapter - TRACE - Pong
2024-02-28 23:33:04 - anonbot.adapter.satori.adapter - TRACE - Heartbeat at None
2024-02-28 23:33:04 - anonbot.adapter.satori.adapter - TRACE - Received payload: PongPayload(op=<Opcode.PONG: 2>, body=None)
2024-02-28 23:33:04 - anonbot.adapter.satori.adapter - TRACE - Pong
2024-02-28 23:33:13 - anonbot.adapter.satori.adapter - TRACE - Heartbeat at None
2024-02-28 23:33:13 - anonbot.adapter.satori.adapter - TRACE - Received payload: PongPayload(op=<Opcode.PONG: 2>, body=None)
2024-02-28 23:33:13 - anonbot.adapter.satori.adapter - TRACE - Pong
2024-02-28 23:33:22 - anonbot.adapter.satori.adapter - TRACE - Heartbeat at None
2024-02-28 23:33:22 - anonbot.adapter.satori.adapter - TRACE - Received payload: PongPayload(op=<Opcode.PONG: 2>, body=None)
2024-02-28 23:33:22 - anonbot.adapter.satori.adapter - TRACE - Pong
2024-02-28 23:33:31 - anonbot.adapter.satori.adapter - TRACE - Heartbeat at None
2024-02-28 23:33:31 - anonbot.adapter.satori.adapter - TRACE - Received payload: PongPayload(op=<Opcode.PONG: 2>, body=None)
2024-02-28 23:33:31 - anonbot.adapter.satori.adapter - TRACE - Pong
2024-02-28 23:33:40 - anonbot.adapter.satori.adapter - TRACE - Heartbeat at None
2024-02-28 23:33:40 - anonbot.adapter.satori.adapter - TRACE - Received payload: PongPayload(op=<Opcode.PONG: 2>, body=None)
2024-02-28 23:33:40 - anonbot.adapter.satori.adapter - TRACE - Pong
2024-02-28 23:33:49 - anonbot.adapter.satori.adapter - TRACE - Heartbeat at None
2024-02-28 23:33:49 - anonbot.adapter.satori.adapter - TRACE - Received payload: PongPayload(op=<Opcode.PONG: 2>, body=None)
2024-02-28 23:33:49 - anonbot.adapter.satori.adapter - TRACE - Pong
2024-02-28 23:33:58 - anonbot.adapter.satori.adapter - TRACE - Heartbeat at None
2024-02-28 23:33:58 - anonbot.adapter.satori.adapter - TRACE - Received payload: PongPayload(op=<Opcode.PONG: 2>, body=None)
2024-02-28 23:33:58 - anonbot.adapter.satori.adapter - TRACE - Pong
2024-02-28 23:34:07 - anonbot.adapter.satori.adapter - TRACE - Heartbeat at None
2024-02-28 23:34:07 - anonbot.adapter.satori.adapter - TRACE - Received payload: PongPayload(op=<Opcode.PONG: 2>, body=None)
2024-02-28 23:34:07 - anonbot.adapter.satori.adapter - TRACE - Pong
2024-02-28 23:34:16 - anonbot.adapter.satori.adapter - TRACE - Heartbeat at None
2024-02-28 23:34:16 - anonbot.adapter.satori.adapter - TRACE - Received payload: PongPayload(op=<Opcode.PONG: 2>, body=None)
2024-02-28 23:34:16 - anonbot.adapter.satori.adapter - TRACE - Pong
2024-02-28 23:34:25 - anonbot.adapter.satori.adapter - TRACE - Heartbeat at None
2024-02-28 23:34:25 - anonbot.adapter.satori.adapter - TRACE - Received payload: PongPayload(op=<Opcode.PONG: 2>, body=None)
2024-02-28 23:34:25 - anonbot.adapter.satori.adapter - TRACE - Pong
2024-02-28 23:34:34 - anonbot.adapter.satori.adapter - TRACE - Heartbeat at None
2024-02-28 23:34:34 - anonbot.adapter.satori.adapter - TRACE - Received payload: PongPayload(op=<Opcode.PONG: 2>, body=None)
2024-02-28 23:34:34 - anonbot.adapter.satori.adapter - TRACE - Pong
2024-02-28 23:34:43 - anonbot.adapter.satori.adapter - TRACE - Heartbeat at None
2024-02-28 23:34:43 - anonbot.adapter.satori.adapter - TRACE - Received payload: PongPayload(op=<Opcode.PONG: 2>, body=None)
2024-02-28 23:34:43 - anonbot.adapter.satori.adapter - TRACE - Pong
2024-02-28 23:34:52 - anonbot.adapter.satori.adapter - TRACE - Heartbeat at None
2024-02-28 23:34:52 - anonbot.adapter.satori.adapter - TRACE - Received payload: PongPayload(op=<Opcode.PONG: 2>, body=None)
2024-02-28 23:34:52 - anonbot.adapter.satori.adapter - TRACE - Pong
2024-02-28 23:35:01 - anonbot.adapter.satori.adapter - TRACE - Heartbeat at None
2024-02-28 23:35:01 - anonbot.adapter.satori.adapter - TRACE - Received payload: PongPayload(op=<Opcode.PONG: 2>, body=None)
2024-02-28 23:35:01 - anonbot.adapter.satori.adapter - TRACE - Pong
2024-02-28 23:35:10 - anonbot.adapter.satori.adapter - TRACE - Heartbeat at None
2024-02-28 23:35:10 - anonbot.adapter.satori.adapter - TRACE - Received payload: PongPayload(op=<Opcode.PONG: 2>, body=None)
2024-02-28 23:35:10 - anonbot.adapter.satori.adapter - TRACE - Pong
2024-02-28 23:35:14 - anonbot - INFO - Initializing AnonBot
2024-02-28 23:35:15 - anonbot.internal.driver.abstract - DEBUG - Driver(type='general+websocket+flask+httpx', adapters=1, bots=0) 成功注册 adapter Satori
2024-02-28 23:35:15 - anonbot.internal.driver.abstract - DEBUG - Adapters Loaded: Satori
2024-02-28 23:35:15 - anonbot.driver.general - INFO - 应用启动成功
2024-02-28 23:35:15 - anonbot.adapter.satori.adapter - DEBUG - WebSocket connected to ws://bot.kasumibot.cn:39306/v1/events
2024-02-28 23:35:15 - anonbot.adapter.satori.adapter - INFO - Bot 3662854527 connected to chronocat
2024-02-28 23:35:15 - anonbot.adapter.satori.adapter - TRACE - Heartbeat at None
2024-02-28 23:35:16 - anonbot.adapter.satori.adapter - TRACE - Received payload: PongPayload(op=<Opcode.PONG: 2>, body=None)
2024-02-28 23:35:16 - anonbot.adapter.satori.adapter - TRACE - Pong
2024-02-28 23:35:24 - anonbot.adapter.satori.adapter - TRACE - Heartbeat at None
2024-02-28 23:35:25 - anonbot.adapter.satori.adapter - TRACE - Received payload: PongPayload(op=<Opcode.PONG: 2>, body=None)
2024-02-28 23:35:25 - anonbot.adapter.satori.adapter - TRACE - Pong
2024-02-28 23:35:29 - anonbot.adapter.satori.adapter - TRACE - Received payload: Payload(op=<Opcode.EVENT: 0>, body={'id': 2, 'type': 'message-created', 'platform': 'chronocat', 'self_id': '3662854527', 'timestamp': 1709134528000, 'user': {'id': '1242954863', 'avatar': 'http://q.qlogo.cn/headimg_dl?dst_uin=1242954863&spec=640'}, 'channel': {'type': 0, 'id': '227179118', 'name': '你好'}, 'guild': {'id': '227179118', 'name': '你好', 'avatar': 'https://p.qlogo.cn/gh/227179118/227179118/640'}, 'member': {'name': 'WindowsSov8'}, 'message': {'id': '7340676904038614760', 'content': '你好'}})
2024-02-28 23:35:29 - anonbot.adapter.satori.adapter - WARN - Unknown payload: Payload(op=<Opcode.EVENT: 0>, body={'id': 2, 'type': 'message-created', 'platform': 'chronocat', 'self_id': '3662854527', 'timestamp': 1709134528000, 'user': {'id': '1242954863', 'avatar': 'http://q.qlogo.cn/headimg_dl?dst_uin=1242954863&spec=640'}, 'channel': {'type': 0, 'id': '227179118', 'name': '你好'}, 'guild': {'id': '227179118', 'name': '你好', 'avatar': 'https://p.qlogo.cn/gh/227179118/227179118/640'}, 'member': {'name': 'WindowsSov8'}, 'message': {'id': '7340676904038614760', 'content': '你好'}})
2024-02-28 23:35:33 - anonbot.adapter.satori.adapter - TRACE - Heartbeat at None
2024-02-28 23:35:34 - anonbot.adapter.satori.adapter - TRACE - Received payload: PongPayload(op=<Opcode.PONG: 2>, body=None)
2024-02-28 23:35:34 - anonbot.adapter.satori.adapter - TRACE - Pong
2024-02-28 23:35:43 - anonbot.adapter.satori.adapter - TRACE - Heartbeat at None
2024-02-28 23:35:43 - anonbot.adapter.satori.adapter - TRACE - Received payload: PongPayload(op=<Opcode.PONG: 2>, body=None)
2024-02-28 23:35:43 - anonbot.adapter.satori.adapter - TRACE - Pong
2024-02-28 23:35:52 - anonbot.adapter.satori.adapter - TRACE - Heartbeat at None
2024-02-28 23:35:52 - anonbot.adapter.satori.adapter - TRACE - Received payload: PongPayload(op=<Opcode.PONG: 2>, body=None)
2024-02-28 23:36:29 - anonbot - INFO - Initializing AnonBot
2024-02-28 23:36:29 - anonbot.internal.driver.abstract - DEBUG - Driver(type='general+websocket+flask+httpx', adapters=1, bots=0) 成功注册 adapter Satori
2024-02-28 23:36:29 - anonbot.internal.driver.abstract - DEBUG - Adapters Loaded: Satori
2024-02-28 23:36:29 - anonbot.driver.general - INFO - 应用启动成功
2024-02-28 23:36:30 - anonbot.adapter.satori.adapter - DEBUG - WebSocket connected to ws://bot.kasumibot.cn:39306/v1/events
2024-02-28 23:36:30 - anonbot.adapter.satori.adapter - INFO - Bot 3662854527 connected to chronocat
2024-02-28 23:36:30 - anonbot.adapter.satori.adapter - TRACE - Heartbeat at None
2024-02-28 23:36:30 - anonbot.adapter.satori.adapter - TRACE - Received payload: PongPayload(op=<Opcode.PONG: 2>, body=None)
2024-02-28 23:36:30 - anonbot.adapter.satori.adapter - TRACE - Pong
2024-02-28 23:36:34 - anonbot.adapter.satori.adapter - TRACE - Received payload: EventPayload(op=<Opcode.EVENT: 0>, body=Event(id=3, type='message-created', platform='chronocat', self_id='3662854527', timestamp=datetime.datetime(2024, 2, 28, 23, 36, 34), argv=None, button=None, channel=Channel(id='227179118', type=<ChannelType.TEXT: 0>, name='你好', parent_id=None), guild=Guild(id='227179118', name='你好', avatar='https://p.qlogo.cn/gh/227179118/227179118/640'), login=None, member=InnerMember(user=None, nick=None, avatar=None, joined_at=None), message=InnerMessage(id='7340677181823684517', content='你好', channel=None, guild=None, member=None, created_at=None, updated_at=None), operator=None, role=None, user=User(id='1242954863', name=None, nick=None, avatar='http://q.qlogo.cn/headimg_dl?dst_uin=1242954863&spec=640', is_bot=None)))
2024-02-28 23:36:34 - anonbot.adapter.satori.adapter - WARN - Failed to parse event payload: op=<Opcode.EVENT: 0> body=Event(id=3, type='message-created', platform='chronocat', self_id='3662854527', timestamp=datetime.datetime(2024, 2, 28, 23, 36, 34), argv=None, button=None, channel=Channel(id='227179118', type=<ChannelType.TEXT: 0>, name='你好', parent_id=None), guild=Guild(id='227179118', name='你好', avatar='https://p.qlogo.cn/gh/227179118/227179118/640'), login=None, member=InnerMember(user=None, nick=None, avatar=None, joined_at=None), message=InnerMessage(id='7340677181823684517', content='你好', channel=None, guild=None, member=None, created_at=None, updated_at=None), operator=None, role=None, user=User(id='1242954863', name=None, nick=None, avatar='http://q.qlogo.cn/headimg_dl?dst_uin=1242954863&spec=640', is_bot=None))1 validation error for MessageCreatedEvent
  Input should be a valid dictionary or instance of MessageCreatedEvent [type=model_type, input_value=Event(id=3, type='message...spec=640', is_bot=None)), input_type=Event]
    For further information visit https://errors.pydantic.dev/2.6/v/model_type
2024-02-28 23:36:39 - anonbot.adapter.satori.adapter - TRACE - Heartbeat at 3
2024-02-28 23:36:39 - anonbot.adapter.satori.adapter - TRACE - Received payload: PongPayload(op=<Opcode.PONG: 2>, body=None)
2024-02-28 23:36:39 - anonbot.adapter.satori.adapter - TRACE - Pong
2024-02-28 23:36:48 - anonbot.adapter.satori.adapter - TRACE - Heartbeat at 3
2024-02-28 23:36:48 - anonbot.adapter.satori.adapter - TRACE - Received payload: PongPayload(op=<Opcode.PONG: 2>, body=None)
2024-02-28 23:36:48 - anonbot.adapter.satori.adapter - TRACE - Pong
2024-02-28 23:36:57 - anonbot.adapter.satori.adapter - TRACE - Heartbeat at 3
2024-02-28 23:36:57 - anonbot.adapter.satori.adapter - TRACE - Received payload: PongPayload(op=<Opcode.PONG: 2>, body=None)
2024-02-28 23:36:57 - anonbot.adapter.satori.adapter - TRACE - Pong
2024-02-28 23:37:06 - anonbot.adapter.satori.adapter - TRACE - Heartbeat at 3
2024-02-28 23:37:06 - anonbot.adapter.satori.adapter - TRACE - Received payload: PongPayload(op=<Opcode.PONG: 2>, body=None)
2024-02-28 23:37:06 - anonbot.adapter.satori.adapter - TRACE - Pong
2024-02-28 23:37:15 - anonbot.adapter.satori.adapter - TRACE - Heartbeat at 3
2024-02-28 23:37:15 - anonbot.adapter.satori.adapter - TRACE - Received payload: PongPayload(op=<Opcode.PONG: 2>, body=None)
2024-02-28 23:37:15 - anonbot.adapter.satori.adapter - TRACE - Pong
2024-02-28 23:37:24 - anonbot.adapter.satori.adapter - TRACE - Heartbeat at 3
2024-02-28 23:37:24 - anonbot.adapter.satori.adapter - TRACE - Received payload: PongPayload(op=<Opcode.PONG: 2>, body=None)
2024-02-28 23:37:24 - anonbot.adapter.satori.adapter - TRACE - Pong
2024-02-28 23:37:32 - anonbot - INFO - Initializing AnonBot
2024-02-28 23:37:33 - anonbot.internal.driver.abstract - DEBUG - Driver(type='general+websocket+flask+httpx', adapters=1, bots=0) 成功注册 adapter Satori
2024-02-28 23:37:33 - anonbot.internal.driver.abstract - DEBUG - Adapters Loaded: Satori
2024-02-28 23:37:33 - anonbot.driver.general - INFO - 应用启动成功
2024-02-28 23:37:33 - anonbot.adapter.satori.adapter - DEBUG - WebSocket connected to ws://bot.kasumibot.cn:39306/v1/events
2024-02-28 23:37:33 - anonbot.adapter.satori.adapter - INFO - Bot 3662854527 connected to chronocat
2024-02-28 23:37:33 - anonbot.adapter.satori.adapter - TRACE - Heartbeat at None
2024-02-28 23:37:34 - anonbot.adapter.satori.adapter - TRACE - Received payload: PongPayload(op=<Opcode.PONG: 2>, body=None)
2024-02-28 23:37:34 - anonbot.adapter.satori.adapter - TRACE - Pong
2024-02-28 23:37:36 - anonbot.adapter.satori.adapter - TRACE - Received payload: EventPayload(op=<Opcode.EVENT: 0>, body=Event(id=4, type='message-created', platform='chronocat', self_id='3662854527', timestamp=datetime.datetime(2024, 2, 28, 23, 37, 36), argv=None, button=None, channel=Channel(id='227179118', type=<ChannelType.TEXT: 0>, name='你好', parent_id=None), guild=Guild(id='227179118', name='你好', avatar='https://p.qlogo.cn/gh/227179118/227179118/640'), login=None, member=InnerMember(user=None, nick=None, avatar=None, joined_at=None), message=InnerMessage(id='7340677448032729704', content='你好', channel=None, guild=None, member=None, created_at=None, updated_at=None), operator=None, role=None, user=User(id='1242954863', name=None, nick=None, avatar='http://q.qlogo.cn/headimg_dl?dst_uin=1242954863&spec=640', is_bot=None)))
2024-02-28 23:37:36 - anonbot.adapter.satori.adapter - WARN - Bot 3662854527 at chronocat not found
2024-02-28 23:37:42 - anonbot.adapter.satori.adapter - TRACE - Heartbeat at 4
2024-02-28 23:37:43 - anonbot.adapter.satori.adapter - TRACE - Received payload: PongPayload(op=<Opcode.PONG: 2>, body=None)
2024-02-28 23:37:43 - anonbot.adapter.satori.adapter - TRACE - Pong
2024-02-28 23:37:51 - anonbot.adapter.satori.adapter - TRACE - Heartbeat at 4
2024-02-28 23:37:52 - anonbot.adapter.satori.adapter - TRACE - Received payload: PongPayload(op=<Opcode.PONG: 2>, body=None)
2024-02-28 23:37:52 - anonbot.adapter.satori.adapter - TRACE - Pong
2024-02-28 23:38:00 - anonbot.adapter.satori.adapter - TRACE - Heartbeat at 4
2024-02-28 23:38:01 - anonbot.adapter.satori.adapter - TRACE - Received payload: PongPayload(op=<Opcode.PONG: 2>, body=None)
2024-02-28 23:38:01 - anonbot.adapter.satori.adapter - TRACE - Pong
2024-02-28 23:38:09 - anonbot.adapter.satori.adapter - TRACE - Heartbeat at 4
2024-02-28 23:38:10 - anonbot.adapter.satori.adapter - TRACE - Received payload: PongPayload(op=<Opcode.PONG: 2>, body=None)
2024-02-28 23:38:10 - anonbot.adapter.satori.adapter - TRACE - Pong
2024-02-28 23:38:19 - anonbot.adapter.satori.adapter - TRACE - Heartbeat at 4
2024-02-28 23:38:19 - anonbot.adapter.satori.adapter - TRACE - Received payload: PongPayload(op=<Opcode.PONG: 2>, body=None)
2024-02-28 23:38:19 - anonbot.adapter.satori.adapter - TRACE - Pong
2024-02-28 23:38:28 - anonbot.adapter.satori.adapter - TRACE - Heartbeat at 4
2024-02-28 23:38:28 - anonbot.adapter.satori.adapter - TRACE - Received payload: PongPayload(op=<Opcode.PONG: 2>, body=None)
2024-02-28 23:38:28 - anonbot.adapter.satori.adapter - TRACE - Pong
2024-02-28 23:38:37 - anonbot.adapter.satori.adapter - TRACE - Heartbeat at 4
2024-02-28 23:38:37 - anonbot.adapter.satori.adapter - TRACE - Received payload: PongPayload(op=<Opcode.PONG: 2>, body=None)
2024-02-28 23:38:37 - anonbot.adapter.satori.adapter - TRACE - Pong
2024-02-28 23:38:46 - anonbot.adapter.satori.adapter - TRACE - Heartbeat at 4
2024-02-28 23:38:46 - anonbot.adapter.satori.adapter - TRACE - Received payload: PongPayload(op=<Opcode.PONG: 2>, body=None)
2024-02-28 23:38:46 - anonbot.adapter.satori.adapter - TRACE - Pong
2024-02-28 23:38:55 - anonbot.adapter.satori.adapter - TRACE - Heartbeat at 4
2024-02-28 23:38:55 - anonbot.adapter.satori.adapter - TRACE - Received payload: PongPayload(op=<Opcode.PONG: 2>, body=None)
2024-02-28 23:38:55 - anonbot.adapter.satori.adapter - TRACE - Pong
2024-02-28 23:39:04 - anonbot.adapter.satori.adapter - TRACE - Heartbeat at 4
2024-02-28 23:39:04 - anonbot.adapter.satori.adapter - TRACE - Received payload: PongPayload(op=<Opcode.PONG: 2>, body=None)
2024-02-28 23:39:04 - anonbot.adapter.satori.adapter - TRACE - Pong
2024-02-28 23:39:13 - anonbot.adapter.satori.adapter - TRACE - Heartbeat at 4
2024-02-28 23:39:13 - anonbot.adapter.satori.adapter - TRACE - Received payload: PongPayload(op=<Opcode.PONG: 2>, body=None)
2024-02-28 23:39:13 - anonbot.adapter.satori.adapter - TRACE - Pong
2024-02-28 23:39:22 - anonbot.adapter.satori.adapter - TRACE - Heartbeat at 4
2024-02-28 23:39:22 - anonbot.adapter.satori.adapter - TRACE - Received payload: PongPayload(op=<Opcode.PONG: 2>, body=None)
2024-02-28 23:39:22 - anonbot.adapter.satori.adapter - TRACE - Pong
2024-02-28 23:39:31 - anonbot.adapter.satori.adapter - TRACE - Heartbeat at 4
2024-02-28 23:39:31 - anonbot.adapter.satori.adapter - TRACE - Received payload: PongPayload(op=<Opcode.PONG: 2>, body=None)
2024-02-28 23:39:31 - anonbot.adapter.satori.adapter - TRACE - Pong
2024-02-28 23:39:40 - anonbot.adapter.satori.adapter - TRACE - Heartbeat at 4
2024-02-28 23:39:40 - anonbot.adapter.satori.adapter - TRACE - Received payload: PongPayload(op=<Opcode.PONG: 2>, body=None)
2024-02-28 23:39:40 - anonbot.adapter.satori.adapter - TRACE - Pong
2024-02-28 23:39:49 - anonbot.adapter.satori.adapter - TRACE - Heartbeat at 4
2024-02-28 23:39:49 - anonbot.adapter.satori.adapter - TRACE - Received payload: PongPayload(op=<Opcode.PONG: 2>, body=None)
2024-02-28 23:39:49 - anonbot.adapter.satori.adapter - TRACE - Pong
2024-02-28 23:39:58 - anonbot.adapter.satori.adapter - TRACE - Heartbeat at 4
2024-02-28 23:39:58 - anonbot.adapter.satori.adapter - TRACE - Received payload: PongPayload(op=<Opcode.PONG: 2>, body=None)
2024-02-28 23:39:58 - anonbot.adapter.satori.adapter - TRACE - Pong
2024-02-28 23:40:07 - anonbot.adapter.satori.adapter - TRACE - Heartbeat at 4
2024-02-28 23:40:07 - anonbot.adapter.satori.adapter - TRACE - Received payload: PongPayload(op=<Opcode.PONG: 2>, body=None)
2024-02-28 23:40:07 - anonbot.adapter.satori.adapter - TRACE - Pong
2024-02-28 23:40:16 - anonbot.adapter.satori.adapter - TRACE - Heartbeat at 4
2024-02-28 23:40:16 - anonbot.adapter.satori.adapter - TRACE - Received payload: PongPayload(op=<Opcode.PONG: 2>, body=None)
2024-02-28 23:40:16 - anonbot.adapter.satori.adapter - TRACE - Pong
2024-02-28 23:40:25 - anonbot.adapter.satori.adapter - TRACE - Heartbeat at 4
2024-02-28 23:40:25 - anonbot.adapter.satori.adapter - TRACE - Received payload: PongPayload(op=<Opcode.PONG: 2>, body=None)
2024-02-28 23:40:25 - anonbot.adapter.satori.adapter - TRACE - Pong
2024-02-28 23:40:34 - anonbot.adapter.satori.adapter - TRACE - Heartbeat at 4
2024-02-28 23:40:34 - anonbot.adapter.satori.adapter - TRACE - Received payload: PongPayload(op=<Opcode.PONG: 2>, body=None)
2024-02-28 23:40:34 - anonbot.adapter.satori.adapter - TRACE - Pong
